Workbook

Sheet Planilla
B3: Terminal | AC3: Terminal
B4: Servicio | AC4: Servicio
B5: Sentido | C5: IDA | AC5: Sentido | AD5: REG
B6: tipo de día | AC6: tipo de día
B7: PO | AC7: PO
B8: TURNO 1 | AC8: TURNO 1 | AD8: =IF(C8="","",C8)
B9: TURNO 2 | AC9: TURNO 2 | AD9: =IF(C9="","",C9)
B10: TURNO3 | AC10: TURNO3 | AD10: =IF(C10="","",C10)
BC11: =C4&" "&C5 -> IDA | BL11: =AD4&" "&MID(AD5,1,3) -> REG
A12: Periodo | B12: TB Programado | C12: Tipo de Salida | D12: Cumple TB | E12: Bus | F12: Media Hora despacho | G12: ="H Sale Terminal"&""&C3 -> H Sale Terminal | H12: Cumple despacho | I12: H. Sale Real | J12: KM PERIODO | K12: KM PROMEDIO | L12: IR_REAL_PROM | M12: IR_PROG_PROM | N12: IR_PROG_DESVEST | O12: IR_REAL_DESVEST | P12: TE_IDEAL | Q12: TE_OBS | R12: TE_OBS_NET | S12: IR_REAL | T12: IR_PROG | U12: ="H llegada Terminal"&""&AD3 -> H llegada Terminal | V12: Hora de Llegada Real | W12: IE | X12: Causa Perdidas | Y12: observación | AB12: Periodo | AC12: TB Programado | AD12: Tipo de Salida | AE12: Cumple TB | AF12: Bus | AG12: Media Hora despcaho | AH12: ="H Sale Terminal"&""&AD3 -> H Sale Terminal | AI12: Cumple despacho | AJ12: H. Sale Real | AK12: KM PERIODO | AL12: KM PROMEDIO | AM12: IR_REAL_PROM | AN12: IR_PROG_PROM | AO12: IR_PROG_DESVEST | AP12: IR_PROG_DESVEST | AQ12: TE_IDEAL | AR12: TE_OBS | AS12: TE_OBS_NET | AT12: IR_REAL | AU12: IR_PROG | AV12: ="H llegada Terminal"&""&C3 -> H llegada Terminal | AW12: Hora de Legada Real | AX12: IE | AY12: Causa Perdidas | AZ12: observación | BC12: Periodo | BD12: Teórico | BE12: Real | BF12: ICF-P | BG12: TE Obs | BH12: TE Ideal | BI12: IE | BL12: Periodo | BM12: Teórico | BN12: Real | BO12: ICF-P | BP12: TE Obs | BQ12: TE Ideal | BR12: IE
A13: =HOUR(G13)+1 -> 1 | D13: =IFERROR( IF(AND(OR(Planilla!B13="C",Planilla!B13="c"), VLOOKUP(E13,[1]Diccionario!B:N,13,0)="C"), "OK",IF(AND(OR(Planilla!B13="C",Planilla!B13="c"), OR(VLOOKUP(E13,[1]Diccionario!B:N,13,0)="B", VLOOKUP(E13,[1]Diccionario!B:N,13,0)="A")), "DEFICIT",IF( AND(OR(Planilla!B13="B", Planilla!B13="BPAL"), VLOOKUP(E13,[1]Diccionario!B:N,13,0)="B"), "OK",IF(AND(OR(Planilla!B13="B", Planilla!B13="BPAL"), VLOOKUP(E13,[1]Diccionario!B:N,13,0)="A"), "DEFICIT",IF(AND(OR(Planilla!B13="B", Planilla!B13="BPAL"), VLOOKUP(E13,[1]Diccionario!B:N,13,0)="C"), "SOBREOFERTA",IF(AND(Planilla!B13="A", VLOOKUP(E13,[1]Diccionario!B:N,13,0)="A"), "OK",IF( AND(Planilla!B13="A", OR(VLOOKUP(E13,[1]Diccionario!B:N,13,0)="B", VLOOKUP(E13,[1]Diccionario!B:N,13,0)="C")), "SOBREOFERTA","" ))))))),"") | F13: =+IF(G13="","",INT(G13*48+1.00001)) | H13: =IF(I13="","",IF(AND((I13-G13)>=TIME(0,0,0),(I13-G13)<TIME(0,3,0)),"OK",IF(AND((I13-G13)>=TIME(0,3,0),(I13-G13)<TIME(0,5,0)),"RETRASO DE 3-5 MIN",IF(AND((I13-G13)>=TIME(0,5,0),(I13-G13)<TIME(0,10,0)),"RETRASO DE 5-10 MIN",IF((I13-G13)>=TIME(0,10,0),"RETRASO >10 MIN", IF(AND((G13-I13)>=TIME(0,0,0),(G13-I13)<TIME(0,3,0)),"OK",IF((G13-I13)>=TIME(0,3,0),"ADELANTADO"))))))) | J13: =IF(A13<>"",HLOOKUP(VALUE(TEXT(G13,"h:mm:ss")),IF($C$6="Laboral",[1]Input!$A$4:$Y$227,IF($C$6="Sábado",[1]Input!$A$231:$Y$452,[1]Input!$A$456:$Y$656)),VLOOKUP($C$4,[1]Input!$AG$2:$AI$99,3,0)+IF(C$5="Ida",0,1),1),"") -> #N/A | K13: =IF(A14<>A13,AVERAGEIF(A$9:A13,A13,J$13:J13),"") | L13: =IFERROR(IF(A14<>A13,AVERAGEIF(A$9:A13,A13,S$13:S13),""),"") | M13: =IFERROR(IF(A14<>A13,AVERAGEIF(A$9:A13,A13,T$8:T13),""),"") | N13: {=IFERROR(IF(A14<>A13,_xlfn.STDEV.P(IF(A$9:A13=A13,T$7:T13)),""),"")} | O13: {=IFERROR(IF(A14<>A13,_xlfn.STDEV.P(IF(A$9:A13=A13,S$7:S13)),""),"")} | P13: =IFERROR(IF(A13<>A14,MAX((((M13*24*60)/2)*(1+POWER((((N13*24*60) / (M13*24*60) )),2))) + ((M13*24*60 )*-0.1 + (K13*0.015)) +1,(((M13*24*60)/2)*(1+POWER((((N13*24*60) / (M13*24*60 ))),2)))),""),"") | Q13: =IF(AND(O13<>"",L13<>""),IF(A13<>A14,((L13*24*60) / 2 ) * (1 + POWER(((O13*24*60) / (L13*24*60)),2)),""),"") | R13: =IF(Q13<>"",MAX(P13,Q13),"") | S13: =IF(I13<>"H. Sale Real",IF(AND(I14<>"",LEFT(C14,2)<>"NC"),IF(AND(I13<>"",LEFT(C13,2)<>"NC",I13<>"H. Sale Real"),IF(I14-I13<0.208333333333333,I14-I13,""),IF(AND(I12<>"",LEFT(C12,2)<>"NC",I12<>"H. Sale Real"),IF(I14-I12<0.208333333333333,I14-I12,""),IF(AND(I11<>"",LEFT(C11,2)<>"NC",I11<>"H. Sale Real"),IF(I14-I11<0.208333333333333,I14-I11,""),IF(AND(I10<>"",LEFT(C10,2)<>"NC",I10<>"H. Sale Real"),IF(I14-I10<0.208333333333333,I14-I10,""),IF(AND(I9<>"",LEFT(C9,2)<>"NC",I9<>"H. Sale Real"),IF(I14-I9<0.208333333333333,I14-I9,""),""))))),""),"") | T13: =IF(G13<>"H. Sale Real",IF(AND(G14<>"",LEFT(C14,2)<>"NC"),IF(AND(G13<>"",LEFT(C13,2)<>"NC",G13<>"H. Sale Real"),IF(G14-G13<0.208333333333333,G14-G13,""),IF(AND(G12<>"",LEFT(C12,2)<>"NC",G12<>"H. Sale Real"),IF(G14-G12<0.208333333333333,G14-G12,""),IF(AND(G11<>"",LEFT(C11,2)<>"NC",G11<>"H. Sale Real"),IF(G14-G11<0.208333333333333,G14-G11,""),IF(AND(G10<>"",LEFT(C10,2)<>"NC",G10<>"H. Sale Real"),IF(G14-G10<0.208333333333333,G14-G10,""),IF(AND(G9<>"",LEFT(C9,2)<>"NC",G9<>"H. Sale Real"),IF(G14-G9<0.208333333333333,G14-G9,""),""))))),""),"") | W13: =IF(G13<>"",IF(AND(W12<>"IE",P13<>0,R13<>""),IF(IFERROR((P13/R13),0) <=1,IFERROR(P13/R13,""),1),""),"") | AB13: =HOUR(AH13)+1 -> 1 | AE13: =IFERROR( IF(AND(OR(AC13="C",AC13="c"), VLOOKUP(AF13,[1]Diccionario!B:N,13,0)="C"), "OK",IF(AND(OR(AC13="C",AC13="c"), OR(VLOOKUP(AF13,[1]Diccionario!B:N,13,0)="B", VLOOKUP(AF13,[1]Diccionario!B:N,13,0)="A")), "DEFICIT",IF( AND(OR(AC13="B", AC13="BPAL"), VLOOKUP(AF13,[1]Diccionario!B:N,13,0)="B"), "OK",IF(AND(OR(AC13="B", AC13="BPAL"), VLOOKUP(AF13,[1]Diccionario!B:N,13,0)="A"), "DEFICIT",IF(AND(OR(AC13="B", AC13="BPAL"), VLOOKUP(AF13,[1]Diccionario!B:N,13,0)="C"), "SOBREOFERTA",IF(AND(AC13="A", VLOOKUP(AF13,[1]Diccionario!B:N,13,0)="A"), "OK",IF( AND(AC13="A", OR(VLOOKUP(AF13,[1]Diccionario!B:N,13,0)="B", VLOOKUP(AF13,[1]Diccionario!B:N,13,0)="C")), "SOBREOFERTA","" ))))))),"") | AI13: =IF(AJ13="","",IF(AND((AJ13-AH13)>=TIME(0,0,0),(AJ13-AH13)<TIME(0,3,0)),"OK",IF(AND((AJ13-AH13)>=TIME(0,3,0),(AJ13-AH13)<TIME(0,5,0)),"RETRASO DE 3-5 MIN",IF(AND((AJ13-AH13)>=TIME(0,5,0),(AJ13-AH13)<TIME(0,10,0)),"RETRASO DE 5-10 MIN",IF((AJ13-AH13)>=TIME(0,10,0),"RETRASO >10 MIN", IF(AND((AH13-AJ13)>=TIME(0,0,0),(AH13-AJ13)<TIME(0,3,0)),"OK",IF((AH13-AJ13)>=TIME(0,3,0),"ADELANTADO"))))))) | AK13: =IF(AB13<>"",HLOOKUP(VALUE(TEXT(AH13,"h:mm:ss")),IF($C$6="Laboral",[1]Input!$A$4:$Y$227,IF($C$6="Sábado",[1]Input!$A$231:$Y$452,[1]Input!$A$456:$Y$656)),VLOOKUP($C$4,[1]Input!$AG$2:$AI$99,3,0)+IF(AD$5="Ida",0,1),1),"") -> #N/A | AL13: =IF(AB14<>AB13,AVERAGEIF(AB$9:AB13,AB13,AK$9:AK13),"") | AM13: =IFERROR(IF(AB14<>AB13,AVERAGEIF(AB$9:AB13,AB13,AT$9:AT13),""),"") | AN13: =IFERROR(IF(AB14<>AB13,AVERAGEIF(AB$9:AB13,AB13,AU$9:AU13),""),"") | AO13: {=IFERROR(IF(AB14<>AB13,_xlfn.STDEV.P(IF(AB$9:AB13=AB13,AU$9:AU13)),""),"")} | AP13: {=IFERROR(IF(AB14<>AB13,_xlfn.STDEV.P(IF(AB$9:AB13=AB13,AT$9:AT13)),""),"")} | AQ13: =IFERROR(IF(AB13<>AB14,MAX((((AN13*24*60)/2)*(1+POWER((((AO13*24*60) / (AN13*24*60) )),2))) + ((AN13*24*60 )*-0.1 + (AL13*0.015)) +1,(((AN13*24*60)/2)*(1+POWER((((AO13*24*60) / (AN13*24*60 ))),2)))),""),"") | AR13: =IF(AND(AP13<>"",AM13<>""),IF(AB13<>AB14,((AM13*24*60) / 2 ) * (1 + POWER(((AP13*24*60) / (AM13*24*60)),2)),""),"") | AS13: =IF(AR13<>"",MAX(AQ13,AR13),"") | AT13: =IF(AJ13<>"H. Sale Real",IF(AND(AJ14<>"",LEFT(AD14,2)<>"NC"),IF(AND(AJ13<>"",LEFT(AD13,2)<>"NC",AJ13<>"H. Sale Real"),IF(AJ14-AJ13<0.208333333333333,AJ14-AJ13,""),IF(AND(AJ12<>"",LEFT(AD12,2)<>"NC",AJ12<>"H. Sale Real"),IF(AJ14-AJ12<0.208333333333333,AJ14-AJ12,""),IF(AND(AJ11<>"",LEFT(AD11,2)<>"NC",AJ11<>"H. Sale Real"),IF(AJ14-AJ11<0.208333333333333,AJ14-AJ11,""),IF(AND(AJ10<>"",LEFT(AD10,2)<>"NC",AJ10<>"H. Sale Real"),IF(AJ14-AJ10<0.208333333333333,AJ14-AJ10,""),IF(AND(AJ9<>"",LEFT(AD9,2)<>"NC",AJ9<>"H. Sale Real"),IF(AJ14-AJ9<0.208333333333333,AJ14-AJ9,""),""))))),""),"") | AU13: =IF(AH13<>"H. Sale Real",IF(AND(AH14<>"",LEFT(AD14,2)<>"NC"),IF(AND(AH13<>"",LEFT(AD13,2)<>"NC",AH13<>"H. Sale Real"),IF(AH14-AH13<0.208333333333333,AH14-AH13,""),IF(AND(AH12<>"",LEFT(AD12,2)<>"NC",AH12<>"H. Sale Real"),IF(AH14-AH12<0.208333333333333,AH14-AH12,""),IF(AND(AH11<>"",LEFT(AD11,2)<>"NC",AH11<>"H. Sale Real"),IF(AH14-AH11<0.208333333333333,AH14-AH11,""),IF(AND(AH10<>"",LEFT(AD10,2)<>"NC",AH10<>"H. Sale Real"),IF(AH14-AH10<0.208333333333333,AH14-AH10,""),IF(AND(AH9<>"",LEFT(AD9,2)<>"NC",AH9<>"H. Sale Real"),IF(AH14-AH9<0.208333333333333,AH14-AH9,""),""))))),""),"") | AX13: {=IF(AH13<>"",IF(AND(AX11:AX12<>"IE",AQ13<>0,AS13<>""),IF(IFERROR((AQ13/AS13),0) <=1,IFERROR(AQ13/AS13,""),1),""),"")} | BC13: 1 | BD13: =COUNTIFS($A:$A,$BC13,$C:$C,$BC$11) -> 0 | BE13: =BD13-COUNTIFS($A:$A,$BC13,$C:$C,$BC$11,$H:$H,"") -> 0 | BF13: =IFERROR((BE13/BD13),"") | BG13: =_xlfn.XLOOKUP(BC13,$A:$A,$R:$R,"0",0,-1) | BH13: =_xlfn.XLOOKUP(BC13,$A:$A,$P:$P,"0",0,-1) | BI13: =_xlfn.XLOOKUP(BC13,$A:$A,$W:$W,"",0,-1) | BL13: 1 | BM13: =COUNTIFS($AB:$AB,$BL13,$AD:$AD,$BL$11) -> 0 | BN13: =BM13-COUNTIFS($AB:$AB,$BL13,$AD:$AD,$BL$11,$AI:$AI,"") -> 0 | BO13: =IFERROR((BN13/BM13),"") | BP13: =_xlfn.XLOOKUP(BL13,$AB:$AB,$AS:$AS,"0",0,-1) | BQ13: =_xlfn.XLOOKUP(BL13,$AB:$AB,$AQ:$AQ,"0",0,-1) | BR13: =_xlfn.XLOOKUP(BL13,$AB:$AB,$AX:$AX,"",0,-1)
A14: =HOUR(G14)+1 -> 1 | D14: =IFERROR( IF(AND(OR(Planilla!B14="C",Planilla!B14="c"), VLOOKUP(E14,[1]Diccionario!B:N,13,0)="C"), "OK",IF(AND(OR(Planilla!B14="C",Planilla!B14="c"), OR(VLOOKUP(E14,[1]Diccionario!B:N,13,0)="B", VLOOKUP(E14,[1]Diccionario!B:N,13,0)="A")), "DEFICIT",IF( AND(OR(Planilla!B14="B", Planilla!B14="BPAL"), VLOOKUP(E14,[1]Diccionario!B:N,13,0)="B"), "OK",IF(AND(OR(Planilla!B14="B", Planilla!B14="BPAL"), VLOOKUP(E14,[1]Diccionario!B:N,13,0)="A"), "DEFICIT",IF(AND(OR(Planilla!B14="B", Planilla!B14="BPAL"), VLOOKUP(E14,[1]Diccionario!B:N,13,0)="C"), "SOBREOFERTA",IF(AND(Planilla!B14="A", VLOOKUP(E14,[1]Diccionario!B:N,13,0)="A"), "OK",IF( AND(Planilla!B14="A", OR(VLOOKUP(E14,[1]Diccionario!B:N,13,0)="B", VLOOKUP(E14,[1]Diccionario!B:N,13,0)="C")), "SOBREOFERTA","" ))))))),"") | F14: =+IF(G14="","",INT(G14*48+1.00001)) | H14: =IF(I14="","",IF(AND((I14-G14)>=TIME(0,0,0),(I14-G14)<TIME(0,3,0)),"OK",IF(AND((I14-G14)>=TIME(0,3,0),(I14-G14)<TIME(0,5,0)),"RETRASO DE 3-5 MIN",IF(AND((I14-G14)>=TIME(0,5,0),(I14-G14)<TIME(0,10,0)),"RETRASO DE 5-10 MIN",IF((I14-G14)>=TIME(0,10,0),"RETRASO >10 MIN", IF(AND((G14-I14)>=TIME(0,0,0),(G14-I14)<TIME(0,3,0)),"OK",IF((G14-I14)>=TIME(0,3,0),"ADELANTADO"))))))) | J14: =IF(A14<>"",HLOOKUP(VALUE(TEXT(G14,"h:mm:ss")),IF($C$6="Laboral",[1]Input!$A$4:$Y$227,IF($C$6="Sábado",[1]Input!$A$231:$Y$452,[1]Input!$A$456:$Y$656)),VLOOKUP($C$4,[1]Input!$AG$2:$AI$99,3,0)+IF(C$5="Ida",0,1),1),"") -> #N/A | K14: =IF(A15<>A14,AVERAGEIF(A$9:A14,A14,J$13:J14),"") | L14: =IFERROR(IF(A15<>A14,AVERAGEIF(A$9:A14,A14,S$13:S14),""),"") | M14: =IFERROR(IF(A15<>A14,AVERAGEIF(A$9:A14,A14,T$8:T14),""),"") | N14: {=IFERROR(IF(A15<>A14,_xlfn.STDEV.P(IF(A$9:A14=A14,T$7:T14)),""),"")} | O14: {=IFERROR(IF(A15<>A14,_xlfn.STDEV.P(IF(A$9:A14=A14,S$7:S14)),""),"")} | P14: =IFERROR(IF(A14<>A15,MAX((((M14*24*60)/2)*(1+POWER((((N14*24*60) / (M14*24*60) )),2))) + ((M14*24*60 )*-0.1 + (K14*0.015)) +1,(((M14*24*60)/2)*(1+POWER((((N14*24*60) / (M14*24*60 ))),2)))),""),"") | Q14: =IF(AND(O14<>"",L14<>""),IF(A14<>A15,((L14*24*60) / 2 ) * (1 + POWER(((O14*24*60) / (L14*24*60)),2)),""),"") | R14: =IF(Q14<>"",MAX(P14,Q14),"") | S14: =IF(I14<>"H. Sale Real",IF(AND(I15<>"",LEFT(C15,2)<>"NC"),IF(AND(I14<>"",LEFT(C14,2)<>"NC",I14<>"H. Sale Real"),IF(I15-I14<0.208333333333333,I15-I14,""),IF(AND(I13<>"",LEFT(C13,2)<>"NC",I13<>"H. Sale Real"),IF(I15-I13<0.208333333333333,I15-I13,""),IF(AND(I12<>"",LEFT(C12,2)<>"NC",I12<>"H. Sale Real"),IF(I15-I12<0.208333333333333,I15-I12,""),IF(AND(I11<>"",LEFT(C11,2)<>"NC",I11<>"H. Sale Real"),IF(I15-I11<0.208333333333333,I15-I11,""),IF(AND(I10<>"",LEFT(C10,2)<>"NC",I10<>"H. Sale Real"),IF(I15-I10<0.208333333333333,I15-I10,""),""))))),""),"") | T14: =IF(G14<>"H. Sale Real",IF(AND(G15<>"",LEFT(C15,2)<>"NC"),IF(AND(G14<>"",LEFT(C14,2)<>"NC",G14<>"H. Sale Real"),IF(G15-G14<0.208333333333333,G15-G14,""),IF(AND(G13<>"",LEFT(C13,2)<>"NC",G13<>"H. Sale Real"),IF(G15-G13<0.208333333333333,G15-G13,""),IF(AND(G12<>"",LEFT(C12,2)<>"NC",G12<>"H. Sale Real"),IF(G15-G12<0.208333333333333,G15-G12,""),IF(AND(G11<>"",LEFT(C11,2)<>"NC",G11<>"H. Sale Real"),IF(G15-G11<0.208333333333333,G15-G11,""),IF(AND(G10<>"",LEFT(C10,2)<>"NC",G10<>"H. Sale Real"),IF(G15-G10<0.208333333333333,G15-G10,""),""))))),""),"") | W14: =IF(G14<>"",IF(AND(W13<>"IE",P14<>0,R14<>""),IF(IFERROR((P14/R14),0) <=1,IFERROR(P14/R14,""),1),""),"") | AB14: =HOUR(AH14)+1 -> 1 | AE14: =IFERROR( IF(AND(OR(AC14="C",AC14="c"), VLOOKUP(AF14,[1]Diccionario!B:N,13,0)="C"), "OK",IF(AND(OR(AC14="C",AC14="c"), OR(VLOOKUP(AF14,[1]Diccionario!B:N,13,0)="B", VLOOKUP(AF14,[1]Diccionario!B:N,13,0)="A")), "DEFICIT",IF( AND(OR(AC14="B", AC14="BPAL"), VLOOKUP(AF14,[1]Diccionario!B:N,13,0)="B"), "OK",IF(AND(OR(AC14="B", AC14="BPAL"), VLOOKUP(AF14,[1]Diccionario!B:N,13,0)="A"), "DEFICIT",IF(AND(OR(AC14="B", AC14="BPAL"), VLOOKUP(AF14,[1]Diccionario!B:N,13,0)="C"), "SOBREOFERTA",IF(AND(AC14="A", VLOOKUP(AF14,[1]Diccionario!B:N,13,0)="A"), "OK",IF( AND(AC14="A", OR(VLOOKUP(AF14,[1]Diccionario!B:N,13,0)="B", VLOOKUP(AF14,[1]Diccionario!B:N,13,0)="C")), "SOBREOFERTA","" ))))))),"") | AI14: =IF(AJ14="","",IF(AND((AJ14-AH14)>=TIME(0,0,0),(AJ14-AH14)<TIME(0,3,0)),"OK",IF(AND((AJ14-AH14)>=TIME(0,3,0),(AJ14-AH14)<TIME(0,5,0)),"RETRASO DE 3-5 MIN",IF(AND((AJ14-AH14)>=TIME(0,5,0),(AJ14-AH14)<TIME(0,10,0)),"RETRASO DE 5-10 MIN",IF((AJ14-AH14)>=TIME(0,10,0),"RETRASO >10 MIN", IF(AND((AH14-AJ14)>=TIME(0,0,0),(AH14-AJ14)<TIME(0,3,0)),"OK",IF((AH14-AJ14)>=TIME(0,3,0),"ADELANTADO"))))))) | AK14: =IF(AB14<>"",HLOOKUP(VALUE(TEXT(AH14,"h:mm:ss")),IF($C$6="Laboral",[1]Input!$A$4:$Y$227,IF($C$6="Sábado",[1]Input!$A$231:$Y$452,[1]Input!$A$456:$Y$656)),VLOOKUP($C$4,[1]Input!$AG$2:$AI$99,3,0)+IF(AD$5="Ida",0,1),1),"") -> #N/A | AL14: =IF(AB15<>AB14,AVERAGEIF(AB$9:AB14,AB14,AK$9:AK14),"") | AM14: =IFERROR(IF(AB15<>AB14,AVERAGEIF(AB$9:AB14,AB14,AT$9:AT14),""),"") | AN14: =IFERROR(IF(AB15<>AB14,AVERAGEIF(AB$9:AB14,AB14,AU$9:AU14),""),"") | AO14: {=IFERROR(IF(AB15<>AB14,_xlfn.STDEV.P(IF(AB$9:AB14=AB14,AU$9:AU14)),""),"")} | AP14: {=IFERROR(IF(AB15<>AB14,_xlfn.STDEV.P(IF(AB$9:AB14=AB14,AT$9:AT14)),""),"")} | AQ14: =IFERROR(IF(AB14<>AB15,MAX((((AN14*24*60)/2)*(1+POWER((((AO14*24*60) / (AN14*24*60) )),2))) + ((AN14*24*60 )*-0.1 + (AL14*0.015)) +1,(((AN14*24*60)/2)*(1+POWER((((AO14*24*60) / (AN14*24*60 ))),2)))),""),"") | AR14: =IF(AND(AP14<>"",AM14<>""),IF(AB14<>AB15,((AM14*24*60) / 2 ) * (1 + POWER(((AP14*24*60) / (AM14*24*60)),2)),""),"") | AS14: =IF(AR14<>"",MAX(AQ14,AR14),"") | AT14: =IF(AJ14<>"H. Sale Real",IF(AND(AJ15<>"",LEFT(AD15,2)<>"NC"),IF(AND(AJ14<>"",LEFT(AD14,2)<>"NC",AJ14<>"H. Sale Real"),IF(AJ15-AJ14<0.208333333333333,AJ15-AJ14,""),IF(AND(AJ13<>"",LEFT(AD13,2)<>"NC",AJ13<>"H. Sale Real"),IF(AJ15-AJ13<0.208333333333333,AJ15-AJ13,""),IF(AND(AJ12<>"",LEFT(AD12,2)<>"NC",AJ12<>"H. Sale Real"),IF(AJ15-AJ12<0.208333333333333,AJ15-AJ12,""),IF(AND(AJ11<>"",LEFT(AD11,2)<>"NC",AJ11<>"H. Sale Real"),IF(AJ15-AJ11<0.208333333333333,AJ15-AJ11,""),IF(AND(AJ10<>"",LEFT(AD10,2)<>"NC",AJ10<>"H. Sale Real"),IF(AJ15-AJ10<0.208333333333333,AJ15-AJ10,""),""))))),""),"") | AU14: =IF(AH14<>"H. Sale Real",IF(AND(AH15<>"",LEFT(AD15,2)<>"NC"),IF(AND(AH14<>"",LEFT(AD14,2)<>"NC",AH14<>"H. Sale Real"),IF(AH15-AH14<0.208333333333333,AH15-AH14,""),IF(AND(AH13<>"",LEFT(AD13,2)<>"NC",AH13<>"H. Sale Real"),IF(AH15-AH13<0.208333333333333,AH15-AH13,""),IF(AND(AH12<>"",LEFT(AD12,2)<>"NC",AH12<>"H. Sale Real"),IF(AH15-AH12<0.208333333333333,AH15-AH12,""),IF(AND(AH11<>"",LEFT(AD11,2)<>"NC",AH11<>"H. Sale Real"),IF(AH15-AH11<0.208333333333333,AH15-AH11,""),IF(AND(AH10<>"",LEFT(AD10,2)<>"NC",AH10<>"H. Sale Real"),IF(AH15-AH10<0.208333333333333,AH15-AH10,""),""))))),""),"") | AX14: {=IF(AH14<>"",IF(AND(AX12:AX13<>"IE",AQ14<>0,AS14<>""),IF(IFERROR((AQ14/AS14),0) <=1,IFERROR(AQ14/AS14,""),1),""),"")} | BC14: 2 | BD14: =COUNTIFS($A:$A,$BC14,$C:$C,$BC$11) -> 0 | BE14: =BD14-COUNTIFS($A:$A,$BC14,$C:$C,$BC$11,$H:$H,"") -> 0 | BF14: =IFERROR((BE14/BD14),"") | BG14: =_xlfn.XLOOKUP(BC14,$A:$A,$R:$R,"0",0,-1) -> 0 | BH14: =_xlfn.XLOOKUP(BC14,$A:$A,$P:$P,"0",0,-1) -> 0 | BI14: =_xlfn.XLOOKUP(BC14,$A:$A,$W:$W,"",0,-1) | BL14: 2 | BM14: =COUNTIFS($AB:$AB,$BL14,$AD:$AD,$BL$11) -> 0 | BN14: =BM14-COUNTIFS($AB:$AB,$BL14,$AD:$AD,$BL$11,$AI:$AI,"") -> 0 | BO14: =IFERROR((BN14/BM14),"") | BP14: =_xlfn.XLOOKUP(BL14,$AB:$AB,$AS:$AS,"0",0,-1) -> 0 | BQ14: =_xlfn.XLOOKUP(BL14,$AB:$AB,$AQ:$AQ,"0",0,-1) -> 0 | BR14: =_xlfn.XLOOKUP(BL14,$AB:$AB,$AX:$AX,"",0,-1)
A15: =HOUR(G15)+1 -> 1 | D15: =IFERROR( IF(AND(OR(Planilla!B15="C",Planilla!B15="c"), VLOOKUP(E15,[1]Diccionario!B:N,13,0)="C"), "OK",IF(AND(OR(Planilla!B15="C",Planilla!B15="c"), OR(VLOOKUP(E15,[1]Diccionario!B:N,13,0)="B", VLOOKUP(E15,[1]Diccionario!B:N,13,0)="A")), "DEFICIT",IF( AND(OR(Planilla!B15="B", Planilla!B15="BPAL"), VLOOKUP(E15,[1]Diccionario!B:N,13,0)="B"), "OK",IF(AND(OR(Planilla!B15="B", Planilla!B15="BPAL"), VLOOKUP(E15,[1]Diccionario!B:N,13,0)="A"), "DEFICIT",IF(AND(OR(Planilla!B15="B", Planilla!B15="BPAL"), VLOOKUP(E15,[1]Diccionario!B:N,13,0)="C"), "SOBREOFERTA",IF(AND(Planilla!B15="A", VLOOKUP(E15,[1]Diccionario!B:N,13,0)="A"), "OK",IF( AND(Planilla!B15="A", OR(VLOOKUP(E15,[1]Diccionario!B:N,13,0)="B", VLOOKUP(E15,[1]Diccionario!B:N,13,0)="C")), "SOBREOFERTA","" ))))))),"") | F15: =+IF(G15="","",INT(G15*48+1.00001)) | H15: =IF(I15="","",IF(AND((I15-G15)>=TIME(0,0,0),(I15-G15)<TIME(0,3,0)),"OK",IF(AND((I15-G15)>=TIME(0,3,0),(I15-G15)<TIME(0,5,0)),"RETRASO DE 3-5 MIN",IF(AND((I15-G15)>=TIME(0,5,0),(I15-G15)<TIME(0,10,0)),"RETRASO DE 5-10 MIN",IF((I15-G15)>=TIME(0,10,0),"RETRASO >10 MIN", IF(AND((G15-I15)>=TIME(0,0,0),(G15-I15)<TIME(0,3,0)),"OK",IF((G15-I15)>=TIME(0,3,0),"ADELANTADO"))))))) | J15: =IF(A15<>"",HLOOKUP(VALUE(TEXT(G15,"h:mm:ss")),IF($C$6="Laboral",[1]Input!$A$4:$Y$227,IF($C$6="Sábado",[1]Input!$A$231:$Y$452,[1]Input!$A$456:$Y$656)),VLOOKUP($C$4,[1]Input!$AG$2:$AI$99,3,0)+IF(C$5="Ida",0,1),1),"") -> #N/A | K15: =IF(A16<>A15,AVERAGEIF(A$9:A15,A15,J$13:J15),"") | L15: =IFERROR(IF(A16<>A15,AVERAGEIF(A$9:A15,A15,S$13:S15),""),"") | M15: =IFERROR(IF(A16<>A15,AVERAGEIF(A$9:A15,A15,T$8:T15),""),"") | N15: {=IFERROR(IF(A16<>A15,_xlfn.STDEV.P(IF(A$9:A15=A15,T$7:T15)),""),"")} | O15: {=IFERROR(IF(A16<>A15,_xlfn.STDEV.P(IF(A$9:A15=A15,S$7:S15)),""),"")} | P15: =IFERROR(IF(A15<>A16,MAX((((M15*24*60)/2)*(1+POWER((((N15*24*60) / (M15*24*60) )),2))) + ((M15*24*60 )*-0.1 + (K15*0.015)) +1,(((M15*24*60)/2)*(1+POWER((((N15*24*60) / (M15*24*60 ))),2)))),""),"") | Q15: =IF(AND(O15<>"",L15<>""),IF(A15<>A16,((L15*24*60) / 2 ) * (1 + POWER(((O15*24*60) / (L15*24*60)),2)),""),"") | R15: =IF(Q15<>"",MAX(P15,Q15),"") | S15: =IF(I15<>"H. Sale Real",IF(AND(I16<>"",LEFT(C16,2)<>"NC"),IF(AND(I15<>"",LEFT(C15,2)<>"NC",I15<>"H. Sale Real"),IF(I16-I15<0.208333333333333,I16-I15,""),IF(AND(I14<>"",LEFT(C14,2)<>"NC",I14<>"H. Sale Real"),IF(I16-I14<0.208333333333333,I16-I14,""),IF(AND(I13<>"",LEFT(C13,2)<>"NC",I13<>"H. Sale Real"),IF(I16-I13<0.208333333333333,I16-I13,""),IF(AND(I12<>"",LEFT(C12,2)<>"NC",I12<>"H. Sale Real"),IF(I16-I12<0.208333333333333,I16-I12,""),IF(AND(I11<>"",LEFT(C11,2)<>"NC",I11<>"H. Sale Real"),IF(I16-I11<0.208333333333333,I16-I11,""),""))))),""),"") | T15: =IF(G15<>"H. Sale Real",IF(AND(G16<>"",LEFT(C16,2)<>"NC"),IF(AND(G15<>"",LEFT(C15,2)<>"NC",G15<>"H. Sale Real"),IF(G16-G15<0.208333333333333,G16-G15,""),IF(AND(G14<>"",LEFT(C14,2)<>"NC",G14<>"H. Sale Real"),IF(G16-G14<0.208333333333333,G16-G14,""),IF(AND(G13<>"",LEFT(C13,2)<>"NC",G13<>"H. Sale Real"),IF(G16-G13<0.208333333333333,G16-G13,""),IF(AND(G12<>"",LEFT(C12,2)<>"NC",G12<>"H. Sale Real"),IF(G16-G12<0.208333333333333,G16-G12,""),IF(AND(G11<>"",LEFT(C11,2)<>"NC",G11<>"H. Sale Real"),IF(G16-G11<0.208333333333333,G16-G11,""),""))))),""),"") | W15: =IF(G15<>"",IF(AND(W14<>"IE",P15<>0,R15<>""),IF(IFERROR((P15/R15),0) <=1,IFERROR(P15/R15,""),1),""),"") | AB15: =HOUR(AH15)+1 -> 1 | AE15: =IFERROR( IF(AND(OR(AC15="C",AC15="c"), VLOOKUP(AF15,[1]Diccionario!B:N,13,0)="C"), "OK",IF(AND(OR(AC15="C",AC15="c"), OR(VLOOKUP(AF15,[1]Diccionario!B:N,13,0)="B", VLOOKUP(AF15,[1]Diccionario!B:N,13,0)="A")), "DEFICIT",IF( AND(OR(AC15="B", AC15="BPAL"), VLOOKUP(AF15,[1]Diccionario!B:N,13,0)="B"), "OK",IF(AND(OR(AC15="B", AC15="BPAL"), VLOOKUP(AF15,[1]Diccionario!B:N,13,0)="A"), "DEFICIT",IF(AND(OR(AC15="B", AC15="BPAL"), VLOOKUP(AF15,[1]Diccionario!B:N,13,0)="C"), "SOBREOFERTA",IF(AND(AC15="A", VLOOKUP(AF15,[1]Diccionario!B:N,13,0)="A"), "OK",IF( AND(AC15="A", OR(VLOOKUP(AF15,[1]Diccionario!B:N,13,0)="B", VLOOKUP(AF15,[1]Diccionario!B:N,13,0)="C")), "SOBREOFERTA","" ))))))),"") | AI15: =IF(AJ15="","",IF(AND((AJ15-AH15)>=TIME(0,0,0),(AJ15-AH15)<TIME(0,3,0)),"OK",IF(AND((AJ15-AH15)>=TIME(0,3,0),(AJ15-AH15)<TIME(0,5,0)),"RETRASO DE 3-5 MIN",IF(AND((AJ15-AH15)>=TIME(0,5,0),(AJ15-AH15)<TIME(0,10,0)),"RETRASO DE 5-10 MIN",IF((AJ15-AH15)>=TIME(0,10,0),"RETRASO >10 MIN", IF(AND((AH15-AJ15)>=TIME(0,0,0),(AH15-AJ15)<TIME(0,3,0)),"OK",IF((AH15-AJ15)>=TIME(0,3,0),"ADELANTADO"))))))) | AK15: =IF(AB15<>"",HLOOKUP(VALUE(TEXT(AH15,"h:mm:ss")),IF($C$6="Laboral",[1]Input!$A$4:$Y$227,IF($C$6="Sábado",[1]Input!$A$231:$Y$452,[1]Input!$A$456:$Y$656)),VLOOKUP($C$4,[1]Input!$AG$2:$AI$99,3,0)+IF(AD$5="Ida",0,1),1),"") -> #N/A | AL15: =IF(AB16<>AB15,AVERAGEIF(AB$9:AB15,AB15,AK$9:AK15),"") | AM15: =IFERROR(IF(AB16<>AB15,AVERAGEIF(AB$9:AB15,AB15,AT$9:AT15),""),"") | AN15: =IFERROR(IF(AB16<>AB15,AVERAGEIF(AB$9:AB15,AB15,AU$9:AU15),""),"") | AO15: {=IFERROR(IF(AB16<>AB15,_xlfn.STDEV.P(IF(AB$9:AB15=AB15,AU$9:AU15)),""),"")} | AP15: {=IFERROR(IF(AB16<>AB15,_xlfn.STDEV.P(IF(AB$9:AB15=AB15,AT$9:AT15)),""),"")} | AQ15: =IFERROR(IF(AB15<>AB16,MAX((((AN15*24*60)/2)*(1+POWER((((AO15*24*60) / (AN15*24*60) )),2))) + ((AN15*24*60 )*-0.1 + (AL15*0.015)) +1,(((AN15*24*60)/2)*(1+POWER((((AO15*24*60) / (AN15*24*60 ))),2)))),""),"") | AR15: =IF(AND(AP15<>"",AM15<>""),IF(AB15<>AB16,((AM15*24*60) / 2 ) * (1 + POWER(((AP15*24*60) / (AM15*24*60)),2)),""),"") | AS15: =IF(AR15<>"",MAX(AQ15,AR15),"") | AT15: =IF(AJ15<>"H. Sale Real",IF(AND(AJ16<>"",LEFT(AD16,2)<>"NC"),IF(AND(AJ15<>"",LEFT(AD15,2)<>"NC",AJ15<>"H. Sale Real"),IF(AJ16-AJ15<0.208333333333333,AJ16-AJ15,""),IF(AND(AJ14<>"",LEFT(AD14,2)<>"NC",AJ14<>"H. Sale Real"),IF(AJ16-AJ14<0.208333333333333,AJ16-AJ14,""),IF(AND(AJ13<>"",LEFT(AD13,2)<>"NC",AJ13<>"H. Sale Real"),IF(AJ16-AJ13<0.208333333333333,AJ16-AJ13,""),IF(AND(AJ12<>"",LEFT(AD12,2)<>"NC",AJ12<>"H. Sale Real"),IF(AJ16-AJ12<0.208333333333333,AJ16-AJ12,""),IF(AND(AJ11<>"",LEFT(AD11,2)<>"NC",AJ11<>"H. Sale Real"),IF(AJ16-AJ11<0.208333333333333,AJ16-AJ11,""),""))))),""),"") | AU15: =IF(AH15<>"H. Sale Real",IF(AND(AH16<>"",LEFT(AD16,2)<>"NC"),IF(AND(AH15<>"",LEFT(AD15,2)<>"NC",AH15<>"H. Sale Real"),IF(AH16-AH15<0.208333333333333,AH16-AH15,""),IF(AND(AH14<>"",LEFT(AD14,2)<>"NC",AH14<>"H. Sale Real"),IF(AH16-AH14<0.208333333333333,AH16-AH14,""),IF(AND(AH13<>"",LEFT(AD13,2)<>"NC",AH13<>"H. Sale Real"),IF(AH16-AH13<0.208333333333333,AH16-AH13,""),IF(AND(AH12<>"",LEFT(AD12,2)<>"NC",AH12<>"H. Sale Real"),IF(AH16-AH12<0.208333333333333,AH16-AH12,""),IF(AND(AH11<>"",LEFT(AD11,2)<>"NC",AH11<>"H. Sale Real"),IF(AH16-AH11<0.208333333333333,AH16-AH11,""),""))))),""),"") | AX15: {=IF(AH15<>"",IF(AND(AX13:AX14<>"IE",AQ15<>0,AS15<>""),IF(IFERROR((AQ15/AS15),0) <=1,IFERROR(AQ15/AS15,""),1),""),"")} | BC15: 3 | BD15: =COUNTIFS($A:$A,$BC15,$C:$C,$BC$11) -> 0 | BE15: =BD15-COUNTIFS($A:$A,$BC15,$C:$C,$BC$11,$H:$H,"") -> 0 | BF15: =IFERROR((BE15/BD15),"") | BG15: =_xlfn.XLOOKUP(BC15,$A:$A,$R:$R,"0",0,-1) -> 0 | BH15: =_xlfn.XLOOKUP(BC15,$A:$A,$P:$P,"0",0,-1) -> 0 | BI15: =_xlfn.XLOOKUP(BC15,$A:$A,$W:$W,"",0,-1) | BL15: 3 | BM15: =COUNTIFS($AB:$AB,$BL15,$AD:$AD,$BL$11) -> 0 | BN15: =BM15-COUNTIFS($AB:$AB,$BL15,$AD:$AD,$BL$11,$AI:$AI,"") -> 0 | BO15: =IFERROR((BN15/BM15),"") | BP15: =_xlfn.XLOOKUP(BL15,$AB:$AB,$AS:$AS,"0",0,-1) -> 0 | BQ15: =_xlfn.XLOOKUP(BL15,$AB:$AB,$AQ:$AQ,"0",0,-1) -> 0 | BR15: =_xlfn.XLOOKUP(BL15,$AB:$AB,$AX:$AX,"",0,-1)
A16: =HOUR(G16)+1 -> 1 | D16: =IFERROR( IF(AND(OR(Planilla!B16="C",Planilla!B16="c"), VLOOKUP(E16,[1]Diccionario!B:N,13,0)="C"), "OK",IF(AND(OR(Planilla!B16="C",Planilla!B16="c"), OR(VLOOKUP(E16,[1]Diccionario!B:N,13,0)="B", VLOOKUP(E16,[1]Diccionario!B:N,13,0)="A")), "DEFICIT",IF( AND(OR(Planilla!B16="B", Planilla!B16="BPAL"), VLOOKUP(E16,[1]Diccionario!B:N,13,0)="B"), "OK",IF(AND(OR(Planilla!B16="B", Planilla!B16="BPAL"), VLOOKUP(E16,[1]Diccionario!B:N,13,0)="A"), "DEFICIT",IF(AND(OR(Planilla!B16="B", Planilla!B16="BPAL"), VLOOKUP(E16,[1]Diccionario!B:N,13,0)="C"), "SOBREOFERTA",IF(AND(Planilla!B16="A", VLOOKUP(E16,[1]Diccionario!B:N,13,0)="A"), "OK",IF( AND(Planilla!B16="A", OR(VLOOKUP(E16,[1]Diccionario!B:N,13,0)="B", VLOOKUP(E16,[1]Diccionario!B:N,13,0)="C")), "SOBREOFERTA","" ))))))),"") | F16: =+IF(G16="","",INT(G16*48+1.00001)) | H16: =IF(I16="","",IF(AND((I16-G16)>=TIME(0,0,0),(I16-G16)<TIME(0,3,0)),"OK",IF(AND((I16-G16)>=TIME(0,3,0),(I16-G16)<TIME(0,5,0)),"RETRASO DE 3-5 MIN",IF(AND((I16-G16)>=TIME(0,5,0),(I16-G16)<TIME(0,10,0)),"RETRASO DE 5-10 MIN",IF((I16-G16)>=TIME(0,10,0),"RETRASO >10 MIN", IF(AND((G16-I16)>=TIME(0,0,0),(G16-I16)<TIME(0,3,0)),"OK",IF((G16-I16)>=TIME(0,3,0),"ADELANTADO"))))))) | J16: =IF(A16<>"",HLOOKUP(VALUE(TEXT(G16,"h:mm:ss")),IF($C$6="Laboral",[1]Input!$A$4:$Y$227,IF($C$6="Sábado",[1]Input!$A$231:$Y$452,[1]Input!$A$456:$Y$656)),VLOOKUP($C$4,[1]Input!$AG$2:$AI$99,3,0)+IF(C$5="Ida",0,1),1),"") -> #N/A | K16: =IF(A17<>A16,AVERAGEIF(A$9:A16,A16,J$13:J16),"") | L16: =IFERROR(IF(A17<>A16,AVERAGEIF(A$9:A16,A16,S$13:S16),""),"") | M16: =IFERROR(IF(A17<>A16,AVERAGEIF(A$9:A16,A16,T$8:T16),""),"") | N16: {=IFERROR(IF(A17<>A16,_xlfn.STDEV.P(IF(A$9:A16=A16,T$7:T16)),""),"")} | O16: {=IFERROR(IF(A17<>A16,_xlfn.STDEV.P(IF(A$9:A16=A16,S$7:S16)),""),"")} | P16: =IFERROR(IF(A16<>A17,MAX((((M16*24*60)/2)*(1+POWER((((N16*24*60) / (M16*24*60) )),2))) + ((M16*24*60 )*-0.1 + (K16*0.015)) +1,(((M16*24*60)/2)*(1+POWER((((N16*24*60) / (M16*24*60 ))),2)))),""),"") | Q16: =IF(AND(O16<>"",L16<>""),IF(A16<>A17,((L16*24*60) / 2 ) * (1 + POWER(((O16*24*60) / (L16*24*60)),2)),""),"") | R16: =IF(Q16<>"",MAX(P16,Q16),"") | S16: =IF(I16<>"H. Sale Real",IF(AND(I17<>"",LEFT(C17,2)<>"NC"),IF(AND(I16<>"",LEFT(C16,2)<>"NC",I16<>"H. Sale Real"),IF(I17-I16<0.208333333333333,I17-I16,""),IF(AND(I15<>"",LEFT(C15,2)<>"NC",I15<>"H. Sale Real"),IF(I17-I15<0.208333333333333,I17-I15,""),IF(AND(I14<>"",LEFT(C14,2)<>"NC",I14<>"H. Sale Real"),IF(I17-I14<0.208333333333333,I17-I14,""),IF(AND(I13<>"",LEFT(C13,2)<>"NC",I13<>"H. Sale Real"),IF(I17-I13<0.208333333333333,I17-I13,""),IF(AND(I12<>"",LEFT(C12,2)<>"NC",I12<>"H. Sale Real"),IF(I17-I12<0.208333333333333,I17-I12,""),""))))),""),"") | T16: =IF(G16<>"H. Sale Real",IF(AND(G17<>"",LEFT(C17,2)<>"NC"),IF(AND(G16<>"",LEFT(C16,2)<>"NC",G16<>"H. Sale Real"),IF(G17-G16<0.208333333333333,G17-G16,""),IF(AND(G15<>"",LEFT(C15,2)<>"NC",G15<>"H. Sale Real"),IF(G17-G15<0.208333333333333,G17-G15,""),IF(AND(G14<>"",LEFT(C14,2)<>"NC",G14<>"H. Sale Real"),IF(G17-G14<0.208333333333333,G17-G14,""),IF(AND(G13<>"",LEFT(C13,2)<>"NC",G13<>"H. Sale Real"),IF(G17-G13<0.208333333333333,G17-G13,""),IF(AND(G12<>"",LEFT(C12,2)<>"NC",G12<>"H. Sale Real"),IF(G17-G12<0.208333333333333,G17-G12,""),""))))),""),"") | W16: =IF(G16<>"",IF(AND(W15<>"IE",P16<>0,R16<>""),IF(IFERROR((P16/R16),0) <=1,IFERROR(P16/R16,""),1),""),"") | AB16: =HOUR(AH16)+1 -> 1 | AE16: =IFERROR( IF(AND(OR(AC16="C",AC16="c"), VLOOKUP(AF16,[1]Diccionario!B:N,13,0)="C"), "OK",IF(AND(OR(AC16="C",AC16="c"), OR(VLOOKUP(AF16,[1]Diccionario!B:N,13,0)="B", VLOOKUP(AF16,[1]Diccionario!B:N,13,0)="A")), "DEFICIT",IF( AND(OR(AC16="B", AC16="BPAL"), VLOOKUP(AF16,[1]Diccionario!B:N,13,0)="B"), "OK",IF(AND(OR(AC16="B", AC16="BPAL"), VLOOKUP(AF16,[1]Diccionario!B:N,13,0)="A"), "DEFICIT",IF(AND(OR(AC16="B", AC16="BPAL"), VLOOKUP(AF16,[1]Diccionario!B:N,13,0)="C"), "SOBREOFERTA",IF(AND(AC16="A", VLOOKUP(AF16,[1]Diccionario!B:N,13,0)="A"), "OK",IF( AND(AC16="A", OR(VLOOKUP(AF16,[1]Diccionario!B:N,13,0)="B", VLOOKUP(AF16,[1]Diccionario!B:N,13,0)="C")), "SOBREOFERTA","" ))))))),"") | AI16: =IF(AJ16="","",IF(AND((AJ16-AH16)>=TIME(0,0,0),(AJ16-AH16)<TIME(0,3,0)),"OK",IF(AND((AJ16-AH16)>=TIME(0,3,0),(AJ16-AH16)<TIME(0,5,0)),"RETRASO DE 3-5 MIN",IF(AND((AJ16-AH16)>=TIME(0,5,0),(AJ16-AH16)<TIME(0,10,0)),"RETRASO DE 5-10 MIN",IF((AJ16-AH16)>=TIME(0,10,0),"RETRASO >10 MIN", IF(AND((AH16-AJ16)>=TIME(0,0,0),(AH16-AJ16)<TIME(0,3,0)),"OK",IF((AH16-AJ16)>=TIME(0,3,0),"ADELANTADO"))))))) | AK16: =IF(AB16<>"",HLOOKUP(VALUE(TEXT(AH16,"h:mm:ss")),IF($C$6="Laboral",[1]Input!$A$4:$Y$227,IF($C$6="Sábado",[1]Input!$A$231:$Y$452,[1]Input!$A$456:$Y$656)),VLOOKUP($C$4,[1]Input!$AG$2:$AI$99,3,0)+IF(AD$5="Ida",0,1),1),"") -> #N/A | AL16: =IF(AB17<>AB16,AVERAGEIF(AB$9:AB16,AB16,AK$9:AK16),"") | AM16: =IFERROR(IF(AB17<>AB16,AVERAGEIF(AB$9:AB16,AB16,AT$9:AT16),""),"") | AN16: =IFERROR(IF(AB17<>AB16,AVERAGEIF(AB$9:AB16,AB16,AU$9:AU16),""),"") | AO16: {=IFERROR(IF(AB17<>AB16,_xlfn.STDEV.P(IF(AB$9:AB16=AB16,AU$9:AU16)),""),"")} | AP16: {=IFERROR(IF(AB17<>AB16,_xlfn.STDEV.P(IF(AB$9:AB16=AB16,AT$9:AT16)),""),"")} | AQ16: =IFERROR(IF(AB16<>AB17,MAX((((AN16*24*60)/2)*(1+POWER((((AO16*24*60) / (AN16*24*60) )),2))) + ((AN16*24*60 )*-0.1 + (AL16*0.015)) +1,(((AN16*24*60)/2)*(1+POWER((((AO16*24*60) / (AN16*24*60 ))),2)))),""),"") | AR16: =IF(AND(AP16<>"",AM16<>""),IF(AB16<>AB17,((AM16*24*60) / 2 ) * (1 + POWER(((AP16*24*60) / (AM16*24*60)),2)),""),"") | AS16: =IF(AR16<>"",MAX(AQ16,AR16),"") | AT16: =IF(AJ16<>"H. Sale Real",IF(AND(AJ17<>"",LEFT(AD17,2)<>"NC"),IF(AND(AJ16<>"",LEFT(AD16,2)<>"NC",AJ16<>"H. Sale Real"),IF(AJ17-AJ16<0.208333333333333,AJ17-AJ16,""),IF(AND(AJ15<>"",LEFT(AD15,2)<>"NC",AJ15<>"H. Sale Real"),IF(AJ17-AJ15<0.208333333333333,AJ17-AJ15,""),IF(AND(AJ14<>"",LEFT(AD14,2)<>"NC",AJ14<>"H. Sale Real"),IF(AJ17-AJ14<0.208333333333333,AJ17-AJ14,""),IF(AND(AJ13<>"",LEFT(AD13,2)<>"NC",AJ13<>"H. Sale Real"),IF(AJ17-AJ13<0.208333333333333,AJ17-AJ13,""),IF(AND(AJ12<>"",LEFT(AD12,2)<>"NC",AJ12<>"H. Sale Real"),IF(AJ17-AJ12<0.208333333333333,AJ17-AJ12,""),""))))),""),"") | AU16: =IF(AH16<>"H. Sale Real",IF(AND(AH17<>"",LEFT(AD17,2)<>"NC"),IF(AND(AH16<>"",LEFT(AD16,2)<>"NC",AH16<>"H. Sale Real"),IF(AH17-AH16<0.208333333333333,AH17-AH16,""),IF(AND(AH15<>"",LEFT(AD15,2)<>"NC",AH15<>"H. Sale Real"),IF(AH17-AH15<0.208333333333333,AH17-AH15,""),IF(AND(AH14<>"",LEFT(AD14,2)<>"NC",AH14<>"H. Sale Real"),IF(AH17-AH14<0.208333333333333,AH17-AH14,""),IF(AND(AH13<>"",LEFT(AD13,2)<>"NC",AH13<>"H. Sale Real"),IF(AH17-AH13<0.208333333333333,AH17-AH13,""),IF(AND(AH12<>"",LEFT(AD12,2)<>"NC",AH12<>"H. Sale Real"),IF(AH17-AH12<0.208333333333333,AH17-AH12,""),""))))),""),"") | AX16: {=IF(AH16<>"",IF(AND(AX14:AX15<>"IE",AQ16<>0,AS16<>""),IF(IFERROR((AQ16/AS16),0) <=1,IFERROR(AQ16/AS16,""),1),""),"")} | BC16: 4 | BD16: =COUNTIFS($A:$A,$BC16,$C:$C,$BC$11) -> 0 | BE16: =BD16-COUNTIFS($A:$A,$BC16,$C:$C,$BC$11,$H:$H,"") -> 0 | BF16: =IFERROR((BE16/BD16),"") | BG16: =_xlfn.XLOOKUP(BC16,$A:$A,$R:$R,"0",0,-1) -> 0 | BH16: =_xlfn.XLOOKUP(BC16,$A:$A,$P:$P,"0",0,-1) -> 0 | BI16: =_xlfn.XLOOKUP(BC16,$A:$A,$W:$W,"",0,-1) | BL16: 4 | BM16: =COUNTIFS($AB:$AB,$BL16,$AD:$AD,$BL$11) -> 0 | BN16: =BM16-COUNTIFS($AB:$AB,$BL16,$AD:$AD,$BL$11,$AI:$AI,"") -> 0 | BO16: =IFERROR((BN16/BM16),"") | BP16: =_xlfn.XLOOKUP(BL16,$AB:$AB,$AS:$AS,"0",0,-1) -> 0 | BQ16: =_xlfn.XLOOKUP(BL16,$AB:$AB,$AQ:$AQ,"0",0,-1) -> 0 | BR16: =_xlfn.XLOOKUP(BL16,$AB:$AB,$AX:$AX,"",0,-1)
A17: =HOUR(G17)+1 -> 1 | D17: =IFERROR( IF(AND(OR(Planilla!B17="C",Planilla!B17="c"), VLOOKUP(E17,[1]Diccionario!B:N,13,0)="C"), "OK",IF(AND(OR(Planilla!B17="C",Planilla!B17="c"), OR(VLOOKUP(E17,[1]Diccionario!B:N,13,0)="B", VLOOKUP(E17,[1]Diccionario!B:N,13,0)="A")), "DEFICIT",IF( AND(OR(Planilla!B17="B", Planilla!B17="BPAL"), VLOOKUP(E17,[1]Diccionario!B:N,13,0)="B"), "OK",IF(AND(OR(Planilla!B17="B", Planilla!B17="BPAL"), VLOOKUP(E17,[1]Diccionario!B:N,13,0)="A"), "DEFICIT",IF(AND(OR(Planilla!B17="B", Planilla!B17="BPAL"), VLOOKUP(E17,[1]Diccionario!B:N,13,0)="C"), "SOBREOFERTA",IF(AND(Planilla!B17="A", VLOOKUP(E17,[1]Diccionario!B:N,13,0)="A"), "OK",IF( AND(Planilla!B17="A", OR(VLOOKUP(E17,[1]Diccionario!B:N,13,0)="B", VLOOKUP(E17,[1]Diccionario!B:N,13,0)="C")), "SOBREOFERTA","" ))))))),"") | F17: =+IF(G17="","",INT(G17*48+1.00001)) | H17: =IF(I17="","",IF(AND((I17-G17)>=TIME(0,0,0),(I17-G17)<TIME(0,3,0)),"OK",IF(AND((I17-G17)>=TIME(0,3,0),(I17-G17)<TIME(0,5,0)),"RETRASO DE 3-5 MIN",IF(AND((I17-G17)>=TIME(0,5,0),(I17-G17)<TIME(0,10,0)),"RETRASO DE 5-10 MIN",IF((I17-G17)>=TIME(0,10,0),"RETRASO >10 MIN", IF(AND((G17-I17)>=TIME(0,0,0),(G17-I17)<TIME(0,3,0)),"OK",IF((G17-I17)>=TIME(0,3,0),"ADELANTADO"))))))) | J17: =IF(A17<>"",HLOOKUP(VALUE(TEXT(G17,"h:mm:ss")),IF($C$6="Laboral",[1]Input!$A$4:$Y$227,IF($C$6="Sábado",[1]Input!$A$231:$Y$452,[1]Input!$A$456:$Y$656)),VLOOKUP($C$4,[1]Input!$AG$2:$AI$99,3,0)+IF(C$5="Ida",0,1),1),"") -> #N/A | K17: =IF(A18<>A17,AVERAGEIF(A$9:A17,A17,J$13:J17),"") | L17: =IFERROR(IF(A18<>A17,AVERAGEIF(A$9:A17,A17,S$13:S17),""),"") | M17: =IFERROR(IF(A18<>A17,AVERAGEIF(A$9:A17,A17,T$8:T17),""),"") | N17: {=IFERROR(IF(A18<>A17,_xlfn.STDEV.P(IF(A$9:A17=A17,T$7:T17)),""),"")} | O17: {=IFERROR(IF(A18<>A17,_xlfn.STDEV.P(IF(A$9:A17=A17,S$7:S17)),""),"")} | P17: =IFERROR(IF(A17<>A18,MAX((((M17*24*60)/2)*(1+POWER((((N17*24*60) / (M17*24*60) )),2))) + ((M17*24*60 )*-0.1 + (K17*0.015)) +1,(((M17*24*60)/2)*(1+POWER((((N17*24*60) / (M17*24*60 ))),2)))),""),"") | Q17: =IF(AND(O17<>"",L17<>""),IF(A17<>A18,((L17*24*60) / 2 ) * (1 + POWER(((O17*24*60) / (L17*24*60)),2)),""),"") | R17: =IF(Q17<>"",MAX(P17,Q17),"") | S17: =IF(I17<>"H. Sale Real",IF(AND(I18<>"",LEFT(C18,2)<>"NC"),IF(AND(I17<>"",LEFT(C17,2)<>"NC",I17<>"H. Sale Real"),IF(I18-I17<0.208333333333333,I18-I17,""),IF(AND(I16<>"",LEFT(C16,2)<>"NC",I16<>"H. Sale Real"),IF(I18-I16<0.208333333333333,I18-I16,""),IF(AND(I15<>"",LEFT(C15,2)<>"NC",I15<>"H. Sale Real"),IF(I18-I15<0.208333333333333,I18-I15,""),IF(AND(I14<>"",LEFT(C14,2)<>"NC",I14<>"H. Sale Real"),IF(I18-I14<0.208333333333333,I18-I14,""),IF(AND(I13<>"",LEFT(C13,2)<>"NC",I13<>"H. Sale Real"),IF(I18-I13<0.208333333333333,I18-I13,""),""))))),""),"") | T17: =IF(G17<>"H. Sale Real",IF(AND(G18<>"",LEFT(C18,2)<>"NC"),IF(AND(G17<>"",LEFT(C17,2)<>"NC",G17<>"H. Sale Real"),IF(G18-G17<0.208333333333333,G18-G17,""),IF(AND(G16<>"",LEFT(C16,2)<>"NC",G16<>"H. Sale Real"),IF(G18-G16<0.208333333333333,G18-G16,""),IF(AND(G15<>"",LEFT(C15,2)<>"NC",G15<>"H. Sale Real"),IF(G18-G15<0.208333333333333,G18-G15,""),IF(AND(G14<>"",LEFT(C14,2)<>"NC",G14<>"H. Sale Real"),IF(G18-G14<0.208333333333333,G18-G14,""),IF(AND(G13<>"",LEFT(C13,2)<>"NC",G13<>"H. Sale Real"),IF(G18-G13<0.208333333333333,G18-G13,""),""))))),""),"") | W17: =IF(G17<>"",IF(AND(W16<>"IE",P17<>0,R17<>""),IF(IFERROR((P17/R17),0) <=1,IFERROR(P17/R17,""),1),""),"") | AB17: =HOUR(AH17)+1 -> 1 | AE17: =IFERROR( IF(AND(OR(AC17="C",AC17="c"), VLOOKUP(AF17,[1]Diccionario!B:N,13,0)="C"), "OK",IF(AND(OR(AC17="C",AC17="c"), OR(VLOOKUP(AF17,[1]Diccionario!B:N,13,0)="B", VLOOKUP(AF17,[1]Diccionario!B:N,13,0)="A")), "DEFICIT",IF( AND(OR(AC17="B", AC17="BPAL"), VLOOKUP(AF17,[1]Diccionario!B:N,13,0)="B"), "OK",IF(AND(OR(AC17="B", AC17="BPAL"), VLOOKUP(AF17,[1]Diccionario!B:N,13,0)="A"), "DEFICIT",IF(AND(OR(AC17="B", AC17="BPAL"), VLOOKUP(AF17,[1]Diccionario!B:N,13,0)="C"), "SOBREOFERTA",IF(AND(AC17="A", VLOOKUP(AF17,[1]Diccionario!B:N,13,0)="A"), "OK",IF( AND(AC17="A", OR(VLOOKUP(AF17,[1]Diccionario!B:N,13,0)="B", VLOOKUP(AF17,[1]Diccionario!B:N,13,0)="C")), "SOBREOFERTA","" ))))))),"") | AI17: =IF(AJ17="","",IF(AND((AJ17-AH17)>=TIME(0,0,0),(AJ17-AH17)<TIME(0,3,0)),"OK",IF(AND((AJ17-AH17)>=TIME(0,3,0),(AJ17-AH17)<TIME(0,5,0)),"RETRASO DE 3-5 MIN",IF(AND((AJ17-AH17)>=TIME(0,5,0),(AJ17-AH17)<TIME(0,10,0)),"RETRASO DE 5-10 MIN",IF((AJ17-AH17)>=TIME(0,10,0),"RETRASO >10 MIN", IF(AND((AH17-AJ17)>=TIME(0,0,0),(AH17-AJ17)<TIME(0,3,0)),"OK",IF((AH17-AJ17)>=TIME(0,3,0),"ADELANTADO"))))))) | AK17: =IF(AB17<>"",HLOOKUP(VALUE(TEXT(AH17,"h:mm:ss")),IF($C$6="Laboral",[1]Input!$A$4:$Y$227,IF($C$6="Sábado",[1]Input!$A$231:$Y$452,[1]Input!$A$456:$Y$656)),VLOOKUP($C$4,[1]Input!$AG$2:$AI$99,3,0)+IF(AD$5="Ida",0,1),1),"") -> #N/A | AL17: =IF(AB18<>AB17,AVERAGEIF(AB$9:AB17,AB17,AK$9:AK17),"") | AM17: =IFERROR(IF(AB18<>AB17,AVERAGEIF(AB$9:AB17,AB17,AT$9:AT17),""),"") | AN17: =IFERROR(IF(AB18<>AB17,AVERAGEIF(AB$9:AB17,AB17,AU$9:AU17),""),"") | AO17: {=IFERROR(IF(AB18<>AB17,_xlfn.STDEV.P(IF(AB$9:AB17=AB17,AU$9:AU17)),""),"")} | AP17: {=IFERROR(IF(AB18<>AB17,_xlfn.STDEV.P(IF(AB$9:AB17=AB17,AT$9:AT17)),""),"")} | AQ17: =IFERROR(IF(AB17<>AB18,MAX((((AN17*24*60)/2)*(1+POWER((((AO17*24*60) / (AN17*24*60) )),2))) + ((AN17*24*60 )*-0.1 + (AL17*0.015)) +1,(((AN17*24*60)/2)*(1+POWER((((AO17*24*60) / (AN17*24*60 ))),2)))),""),"") | AR17: =IF(AND(AP17<>"",AM17<>""),IF(AB17<>AB18,((AM17*24*60) / 2 ) * (1 + POWER(((AP17*24*60) / (AM17*24*60)),2)),""),"") | AS17: =IF(AR17<>"",MAX(AQ17,AR17),"") | AT17: =IF(AJ17<>"H. Sale Real",IF(AND(AJ18<>"",LEFT(AD18,2)<>"NC"),IF(AND(AJ17<>"",LEFT(AD17,2)<>"NC",AJ17<>"H. Sale Real"),IF(AJ18-AJ17<0.208333333333333,AJ18-AJ17,""),IF(AND(AJ16<>"",LEFT(AD16,2)<>"NC",AJ16<>"H. Sale Real"),IF(AJ18-AJ16<0.208333333333333,AJ18-AJ16,""),IF(AND(AJ15<>"",LEFT(AD15,2)<>"NC",AJ15<>"H. Sale Real"),IF(AJ18-AJ15<0.208333333333333,AJ18-AJ15,""),IF(AND(AJ14<>"",LEFT(AD14,2)<>"NC",AJ14<>"H. Sale Real"),IF(AJ18-AJ14<0.208333333333333,AJ18-AJ14,""),IF(AND(AJ13<>"",LEFT(AD13,2)<>"NC",AJ13<>"H. Sale Real"),IF(AJ18-AJ13<0.208333333333333,AJ18-AJ13,""),""))))),""),"") | AU17: =IF(AH17<>"H. Sale Real",IF(AND(AH18<>"",LEFT(AD18,2)<>"NC"),IF(AND(AH17<>"",LEFT(AD17,2)<>"NC",AH17<>"H. Sale Real"),IF(AH18-AH17<0.208333333333333,AH18-AH17,""),IF(AND(AH16<>"",LEFT(AD16,2)<>"NC",AH16<>"H. Sale Real"),IF(AH18-AH16<0.208333333333333,AH18-AH16,""),IF(AND(AH15<>"",LEFT(AD15,2)<>"NC",AH15<>"H. Sale Real"),IF(AH18-AH15<0.208333333333333,AH18-AH15,""),IF(AND(AH14<>"",LEFT(AD14,2)<>"NC",AH14<>"H. Sale Real"),IF(AH18-AH14<0.208333333333333,AH18-AH14,""),IF(AND(AH13<>"",LEFT(AD13,2)<>"NC",AH13<>"H. Sale Real"),IF(AH18-AH13<0.208333333333333,AH18-AH13,""),""))))),""),"") | AX17: {=IF(AH17<>"",IF(AND(AX15:AX16<>"IE",AQ17<>0,AS17<>""),IF(IFERROR((AQ17/AS17),0) <=1,IFERROR(AQ17/AS17,""),1),""),"")} | BC17: 5 | BD17: =COUNTIFS($A:$A,$BC17,$C:$C,$BC$11) -> 0 | BE17: =BD17-COUNTIFS($A:$A,$BC17,$C:$C,$BC$11,$H:$H,"") -> 0 | BF17: =IFERROR((BE17/BD17),"") | BG17: =_xlfn.XLOOKUP(BC17,$A:$A,$R:$R,"0",0,-1) -> 0 | BH17: =_xlfn.XLOOKUP(BC17,$A:$A,$P:$P,"0",0,-1) -> 0 | BI17: =_xlfn.XLOOKUP(BC17,$A:$A,$W:$W,"",0,-1) | BL17: 5 | BM17: =COUNTIFS($AB:$AB,$BL17,$AD:$AD,$BL$11) -> 0 | BN17: =BM17-COUNTIFS($AB:$AB,$BL17,$AD:$AD,$BL$11,$AI:$AI,"") -> 0 | BO17: =IFERROR((BN17/BM17),"") | BP17: =_xlfn.XLOOKUP(BL17,$AB:$AB,$AS:$AS,"0",0,-1) -> 0 | BQ17: =_xlfn.XLOOKUP(BL17,$AB:$AB,$AQ:$AQ,"0",0,-1) -> 0 | BR17: =_xlfn.XLOOKUP(BL17,$AB:$AB,$AX:$AX,"",0,-1)
A18: =HOUR(G18)+1 -> 1 | D18: =IFERROR( IF(AND(OR(Planilla!B18="C",Planilla!B18="c"), VLOOKUP(E18,[1]Diccionario!B:N,13,0)="C"), "OK",IF(AND(OR(Planilla!B18="C",Planilla!B18="c"), OR(VLOOKUP(E18,[1]Diccionario!B:N,13,0)="B", VLOOKUP(E18,[1]Diccionario!B:N,13,0)="A")), "DEFICIT",IF( AND(OR(Planilla!B18="B", Planilla!B18="BPAL"), VLOOKUP(E18,[1]Diccionario!B:N,13,0)="B"), "OK",IF(AND(OR(Planilla!B18="B", Planilla!B18="BPAL"), VLOOKUP(E18,[1]Diccionario!B:N,13,0)="A"), "DEFICIT",IF(AND(OR(Planilla!B18="B", Planilla!B18="BPAL"), VLOOKUP(E18,[1]Diccionario!B:N,13,0)="C"), "SOBREOFERTA",IF(AND(Planilla!B18="A", VLOOKUP(E18,[1]Diccionario!B:N,13,0)="A"), "OK",IF( AND(Planilla!B18="A", OR(VLOOKUP(E18,[1]Diccionario!B:N,13,0)="B", VLOOKUP(E18,[1]Diccionario!B:N,13,0)="C")), "SOBREOFERTA","" ))))))),"") | F18: =+IF(G18="","",INT(G18*48+1.00001)) | H18: =IF(I18="","",IF(AND((I18-G18)>=TIME(0,0,0),(I18-G18)<TIME(0,3,0)),"OK",IF(AND((I18-G18)>=TIME(0,3,0),(I18-G18)<TIME(0,5,0)),"RETRASO DE 3-5 MIN",IF(AND((I18-G18)>=TIME(0,5,0),(I18-G18)<TIME(0,10,0)),"RETRASO DE 5-10 MIN",IF((I18-G18)>=TIME(0,10,0),"RETRASO >10 MIN", IF(AND((G18-I18)>=TIME(0,0,0),(G18-I18)<TIME(0,3,0)),"OK",IF((G18-I18)>=TIME(0,3,0),"ADELANTADO"))))))) | J18: =IF(A18<>"",HLOOKUP(VALUE(TEXT(G18,"h:mm:ss")),IF($C$6="Laboral",[1]Input!$A$4:$Y$227,IF($C$6="Sábado",[1]Input!$A$231:$Y$452,[1]Input!$A$456:$Y$656)),VLOOKUP($C$4,[1]Input!$AG$2:$AI$99,3,0)+IF(C$5="Ida",0,1),1),"") -> #N/A | K18: =IF(A19<>A18,AVERAGEIF(A$9:A18,A18,J$13:J18),"") | L18: =IFERROR(IF(A19<>A18,AVERAGEIF(A$9:A18,A18,S$13:S18),""),"") | M18: =IFERROR(IF(A19<>A18,AVERAGEIF(A$9:A18,A18,T$8:T18),""),"") | N18: {=IFERROR(IF(A19<>A18,_xlfn.STDEV.P(IF(A$9:A18=A18,T$7:T18)),""),"")} | O18: {=IFERROR(IF(A19<>A18,_xlfn.STDEV.P(IF(A$9:A18=A18,S$7:S18)),""),"")} | P18: =IFERROR(IF(A18<>A19,MAX((((M18*24*60)/2)*(1+POWER((((N18*24*60) / (M18*24*60) )),2))) + ((M18*24*60 )*-0.1 + (K18*0.015)) +1,(((M18*24*60)/2)*(1+POWER((((N18*24*60) / (M18*24*60 ))),2)))),""),"") | Q18: =IF(AND(O18<>"",L18<>""),IF(A18<>A19,((L18*24*60) / 2 ) * (1 + POWER(((O18*24*60) / (L18*24*60)),2)),""),"") | R18: =IF(Q18<>"",MAX(P18,Q18),"") | S18: =IF(I18<>"H. Sale Real",IF(AND(I19<>"",LEFT(C19,2)<>"NC"),IF(AND(I18<>"",LEFT(C18,2)<>"NC",I18<>"H. Sale Real"),IF(I19-I18<0.208333333333333,I19-I18,""),IF(AND(I17<>"",LEFT(C17,2)<>"NC",I17<>"H. Sale Real"),IF(I19-I17<0.208333333333333,I19-I17,""),IF(AND(I16<>"",LEFT(C16,2)<>"NC",I16<>"H. Sale Real"),IF(I19-I16<0.208333333333333,I19-I16,""),IF(AND(I15<>"",LEFT(C15,2)<>"NC",I15<>"H. Sale Real"),IF(I19-I15<0.208333333333333,I19-I15,""),IF(AND(I14<>"",LEFT(C14,2)<>"NC",I14<>"H. Sale Real"),IF(I19-I14<0.208333333333333,I19-I14,""),""))))),""),"") | T18: =IF(G18<>"H. Sale Real",IF(AND(G19<>"",LEFT(C19,2)<>"NC"),IF(AND(G18<>"",LEFT(C18,2)<>"NC",G18<>"H. Sale Real"),IF(G19-G18<0.208333333333333,G19-G18,""),IF(AND(G17<>"",LEFT(C17,2)<>"NC",G17<>"H. Sale Real"),IF(G19-G17<0.208333333333333,G19-G17,""),IF(AND(G16<>"",LEFT(C16,2)<>"NC",G16<>"H. Sale Real"),IF(G19-G16<0.208333333333333,G19-G16,""),IF(AND(G15<>"",LEFT(C15,2)<>"NC",G15<>"H. Sale Real"),IF(G19-G15<0.208333333333333,G19-G15,""),IF(AND(G14<>"",LEFT(C14,2)<>"NC",G14<>"H. Sale Real"),IF(G19-G14<0.208333333333333,G19-G14,""),""))))),""),"") | W18: =IF(G18<>"",IF(AND(W17<>"IE",P18<>0,R18<>""),IF(IFERROR((P18/R18),0) <=1,IFERROR(P18/R18,""),1),""),"") | AB18: =HOUR(AH18)+1 -> 1 | AE18: =IFERROR( IF(AND(OR(AC18="C",AC18="c"), VLOOKUP(AF18,[1]Diccionario!B:N,13,0)="C"), "OK",IF(AND(OR(AC18="C",AC18="c"), OR(VLOOKUP(AF18,[1]Diccionario!B:N,13,0)="B", VLOOKUP(AF18,[1]Diccionario!B:N,13,0)="A")), "DEFICIT",IF( AND(OR(AC18="B", AC18="BPAL"), VLOOKUP(AF18,[1]Diccionario!B:N,13,0)="B"), "OK",IF(AND(OR(AC18="B", AC18="BPAL"), VLOOKUP(AF18,[1]Diccionario!B:N,13,0)="A"), "DEFICIT",IF(AND(OR(AC18="B", AC18="BPAL"), VLOOKUP(AF18,[1]Diccionario!B:N,13,0)="C"), "SOBREOFERTA",IF(AND(AC18="A", VLOOKUP(AF18,[1]Diccionario!B:N,13,0)="A"), "OK",IF( AND(AC18="A", OR(VLOOKUP(AF18,[1]Diccionario!B:N,13,0)="B", VLOOKUP(AF18,[1]Diccionario!B:N,13,0)="C")), "SOBREOFERTA","" ))))))),"") | AI18: =IF(AJ18="","",IF(AND((AJ18-AH18)>=TIME(0,0,0),(AJ18-AH18)<TIME(0,3,0)),"OK",IF(AND((AJ18-AH18)>=TIME(0,3,0),(AJ18-AH18)<TIME(0,5,0)),"RETRASO DE 3-5 MIN",IF(AND((AJ18-AH18)>=TIME(0,5,0),(AJ18-AH18)<TIME(0,10,0)),"RETRASO DE 5-10 MIN",IF((AJ18-AH18)>=TIME(0,10,0),"RETRASO >10 MIN", IF(AND((AH18-AJ18)>=TIME(0,0,0),(AH18-AJ18)<TIME(0,3,0)),"OK",IF((AH18-AJ18)>=TIME(0,3,0),"ADELANTADO"))))))) | AK18: =IF(AB18<>"",HLOOKUP(VALUE(TEXT(AH18,"h:mm:ss")),IF($C$6="Laboral",[1]Input!$A$4:$Y$227,IF($C$6="Sábado",[1]Input!$A$231:$Y$452,[1]Input!$A$456:$Y$656)),VLOOKUP($C$4,[1]Input!$AG$2:$AI$99,3,0)+IF(AD$5="Ida",0,1),1),"") -> #N/A | AL18: =IF(AB19<>AB18,AVERAGEIF(AB$9:AB18,AB18,AK$9:AK18),"") | AM18: =IFERROR(IF(AB19<>AB18,AVERAGEIF(AB$9:AB18,AB18,AT$9:AT18),""),"") | AN18: =IFERROR(IF(AB19<>AB18,AVERAGEIF(AB$9:AB18,AB18,AU$9:AU18),""),"") | AO18: {=IFERROR(IF(AB19<>AB18,_xlfn.STDEV.P(IF(AB$9:AB18=AB18,AU$9:AU18)),""),"")} | AP18: {=IFERROR(IF(AB19<>AB18,_xlfn.STDEV.P(IF(AB$9:AB18=AB18,AT$9:AT18)),""),"")} | AQ18: =IFERROR(IF(AB18<>AB19,MAX((((AN18*24*60)/2)*(1+POWER((((AO18*24*60) / (AN18*24*60) )),2))) + ((AN18*24*60 )*-0.1 + (AL18*0.015)) +1,(((AN18*24*60)/2)*(1+POWER((((AO18*24*60) / (AN18*24*60 ))),2)))),""),"") | AR18: =IF(AND(AP18<>"",AM18<>""),IF(AB18<>AB19,((AM18*24*60) / 2 ) * (1 + POWER(((AP18*24*60) / (AM18*24*60)),2)),""),"") | AS18: =IF(AR18<>"",MAX(AQ18,AR18),"") | AT18: =IF(AJ18<>"H. Sale Real",IF(AND(AJ19<>"",LEFT(AD19,2)<>"NC"),IF(AND(AJ18<>"",LEFT(AD18,2)<>"NC",AJ18<>"H. Sale Real"),IF(AJ19-AJ18<0.208333333333333,AJ19-AJ18,""),IF(AND(AJ17<>"",LEFT(AD17,2)<>"NC",AJ17<>"H. Sale Real"),IF(AJ19-AJ17<0.208333333333333,AJ19-AJ17,""),IF(AND(AJ16<>"",LEFT(AD16,2)<>"NC",AJ16<>"H. Sale Real"),IF(AJ19-AJ16<0.208333333333333,AJ19-AJ16,""),IF(AND(AJ15<>"",LEFT(AD15,2)<>"NC",AJ15<>"H. Sale Real"),IF(AJ19-AJ15<0.208333333333333,AJ19-AJ15,""),IF(AND(AJ14<>"",LEFT(AD14,2)<>"NC",AJ14<>"H. Sale Real"),IF(AJ19-AJ14<0.208333333333333,AJ19-AJ14,""),""))))),""),"") | AU18: =IF(AH18<>"H. Sale Real",IF(AND(AH19<>"",LEFT(AD19,2)<>"NC"),IF(AND(AH18<>"",LEFT(AD18,2)<>"NC",AH18<>"H. Sale Real"),IF(AH19-AH18<0.208333333333333,AH19-AH18,""),IF(AND(AH17<>"",LEFT(AD17,2)<>"NC",AH17<>"H. Sale Real"),IF(AH19-AH17<0.208333333333333,AH19-AH17,""),IF(AND(AH16<>"",LEFT(AD16,2)<>"NC",AH16<>"H. Sale Real"),IF(AH19-AH16<0.208333333333333,AH19-AH16,""),IF(AND(AH15<>"",LEFT(AD15,2)<>"NC",AH15<>"H. Sale Real"),IF(AH19-AH15<0.208333333333333,AH19-AH15,""),IF(AND(AH14<>"",LEFT(AD14,2)<>"NC",AH14<>"H. Sale Real"),IF(AH19-AH14<0.208333333333333,AH19-AH14,""),""))))),""),"") | AX18: {=IF(AH18<>"",IF(AND(AX16:AX17<>"IE",AQ18<>0,AS18<>""),IF(IFERROR((AQ18/AS18),0) <=1,IFERROR(AQ18/AS18,""),1),""),"")} | BC18: 6 | BD18: =COUNTIFS($A:$A,$BC18,$C:$C,$BC$11) -> 0 | BE18: =BD18-COUNTIFS($A:$A,$BC18,$C:$C,$BC$11,$H:$H,"") -> 0 | BF18: =IFERROR((BE18/BD18),"") | BG18: =_xlfn.XLOOKUP(BC18,$A:$A,$R:$R,"0",0,-1) -> 0 | BH18: =_xlfn.XLOOKUP(BC18,$A:$A,$P:$P,"0",0,-1) -> 0 | BI18: =_xlfn.XLOOKUP(BC18,$A:$A,$W:$W,"",0,-1) | BL18: 6 | BM18: =COUNTIFS($AB:$AB,$BL18,$AD:$AD,$BL$11) -> 0 | BN18: =BM18-COUNTIFS($AB:$AB,$BL18,$AD:$AD,$BL$11,$AI:$AI,"") -> 0 | BO18: =IFERROR((BN18/BM18),"") | BP18: =_xlfn.XLOOKUP(BL18,$AB:$AB,$AS:$AS,"0",0,-1) -> 0 | BQ18: =_xlfn.XLOOKUP(BL18,$AB:$AB,$AQ:$AQ,"0",0,-1) -> 0 | BR18: =_xlfn.XLOOKUP(BL18,$AB:$AB,$AX:$AX,"",0,-1)
A19: =HOUR(G19)+1 -> 1 | D19: =IFERROR( IF(AND(OR(Planilla!B19="C",Planilla!B19="c"), VLOOKUP(E19,[1]Diccionario!B:N,13,0)="C"), "OK",IF(AND(OR(Planilla!B19="C",Planilla!B19="c"), OR(VLOOKUP(E19,[1]Diccionario!B:N,13,0)="B", VLOOKUP(E19,[1]Diccionario!B:N,13,0)="A")), "DEFICIT",IF( AND(OR(Planilla!B19="B", Planilla!B19="BPAL"), VLOOKUP(E19,[1]Diccionario!B:N,13,0)="B"), "OK",IF(AND(OR(Planilla!B19="B", Planilla!B19="BPAL"), VLOOKUP(E19,[1]Diccionario!B:N,13,0)="A"), "DEFICIT",IF(AND(OR(Planilla!B19="B", Planilla!B19="BPAL"), VLOOKUP(E19,[1]Diccionario!B:N,13,0)="C"), "SOBREOFERTA",IF(AND(Planilla!B19="A", VLOOKUP(E19,[1]Diccionario!B:N,13,0)="A"), "OK",IF( AND(Planilla!B19="A", OR(VLOOKUP(E19,[1]Diccionario!B:N,13,0)="B", VLOOKUP(E19,[1]Diccionario!B:N,13,0)="C")), "SOBREOFERTA","" ))))))),"") | F19: =+IF(G19="","",INT(G19*48+1.00001)) | H19: =IF(I19="","",IF(AND((I19-G19)>=TIME(0,0,0),(I19-G19)<TIME(0,3,0)),"OK",IF(AND((I19-G19)>=TIME(0,3,0),(I19-G19)<TIME(0,5,0)),"RETRASO DE 3-5 MIN",IF(AND((I19-G19)>=TIME(0,5,0),(I19-G19)<TIME(0,10,0)),"RETRASO DE 5-10 MIN",IF((I19-G19)>=TIME(0,10,0),"RETRASO >10 MIN", IF(AND((G19-I19)>=TIME(0,0,0),(G19-I19)<TIME(0,3,0)),"OK",IF((G19-I19)>=TIME(0,3,0),"ADELANTADO"))))))) | J19: =IF(A19<>"",HLOOKUP(VALUE(TEXT(G19,"h:mm:ss")),IF($C$6="Laboral",[1]Input!$A$4:$Y$227,IF($C$6="Sábado",[1]Input!$A$231:$Y$452,[1]Input!$A$456:$Y$656)),VLOOKUP($C$4,[1]Input!$AG$2:$AI$99,3,0)+IF(C$5="Ida",0,1),1),"") -> #N/A | K19: =IF(A20<>A19,AVERAGEIF(A$9:A19,A19,J$13:J19),"") | L19: =IFERROR(IF(A20<>A19,AVERAGEIF(A$9:A19,A19,S$13:S19),""),"") | M19: =IFERROR(IF(A20<>A19,AVERAGEIF(A$9:A19,A19,T$8:T19),""),"") | N19: {=IFERROR(IF(A20<>A19,_xlfn.STDEV.P(IF(A$9:A19=A19,T$7:T19)),""),"")} | O19: {=IFERROR(IF(A20<>A19,_xlfn.STDEV.P(IF(A$9:A19=A19,S$7:S19)),""),"")} | P19: =IFERROR(IF(A19<>A20,MAX((((M19*24*60)/2)*(1+POWER((((N19*24*60) / (M19*24*60) )),2))) + ((M19*24*60 )*-0.1 + (K19*0.015)) +1,(((M19*24*60)/2)*(1+POWER((((N19*24*60) / (M19*24*60 ))),2)))),""),"") | Q19: =IF(AND(O19<>"",L19<>""),IF(A19<>A20,((L19*24*60) / 2 ) * (1 + POWER(((O19*24*60) / (L19*24*60)),2)),""),"") | R19: =IF(Q19<>"",MAX(P19,Q19),"") | S19: =IF(I19<>"H. Sale Real",IF(AND(I20<>"",LEFT(C20,2)<>"NC"),IF(AND(I19<>"",LEFT(C19,2)<>"NC",I19<>"H. Sale Real"),IF(I20-I19<0.208333333333333,I20-I19,""),IF(AND(I18<>"",LEFT(C18,2)<>"NC",I18<>"H. Sale Real"),IF(I20-I18<0.208333333333333,I20-I18,""),IF(AND(I17<>"",LEFT(C17,2)<>"NC",I17<>"H. Sale Real"),IF(I20-I17<0.208333333333333,I20-I17,""),IF(AND(I16<>"",LEFT(C16,2)<>"NC",I16<>"H. Sale Real"),IF(I20-I16<0.208333333333333,I20-I16,""),IF(AND(I15<>"",LEFT(C15,2)<>"NC",I15<>"H. Sale Real"),IF(I20-I15<0.208333333333333,I20-I15,""),""))))),""),"") | T19: =IF(G19<>"H. Sale Real",IF(AND(G20<>"",LEFT(C20,2)<>"NC"),IF(AND(G19<>"",LEFT(C19,2)<>"NC",G19<>"H. Sale Real"),IF(G20-G19<0.208333333333333,G20-G19,""),IF(AND(G18<>"",LEFT(C18,2)<>"NC",G18<>"H. Sale Real"),IF(G20-G18<0.208333333333333,G20-G18,""),IF(AND(G17<>"",LEFT(C17,2)<>"NC",G17<>"H. Sale Real"),IF(G20-G17<0.208333333333333,G20-G17,""),IF(AND(G16<>"",LEFT(C16,2)<>"NC",G16<>"H. Sale Real"),IF(G20-G16<0.208333333333333,G20-G16,""),IF(AND(G15<>"",LEFT(C15,2)<>"NC",G15<>"H. Sale Real"),IF(G20-G15<0.208333333333333,G20-G15,""),""))))),""),"") | W19: =IF(G19<>"",IF(AND(W18<>"IE",P19<>0,R19<>""),IF(IFERROR((P19/R19),0) <=1,IFERROR(P19/R19,""),1),""),"") | AB19: =HOUR(AH19)+1 -> 1 | AE19: =IFERROR( IF(AND(OR(AC19="C",AC19="c"), VLOOKUP(AF19,[1]Diccionario!B:N,13,0)="C"), "OK",IF(AND(OR(AC19="C",AC19="c"), OR(VLOOKUP(AF19,[1]Diccionario!B:N,13,0)="B", VLOOKUP(AF19,[1]Diccionario!B:N,13,0)="A")), "DEFICIT",IF( AND(OR(AC19="B", AC19="BPAL"), VLOOKUP(AF19,[1]Diccionario!B:N,13,0)="B"), "OK",IF(AND(OR(AC19="B", AC19="BPAL"), VLOOKUP(AF19,[1]Diccionario!B:N,13,0)="A"), "DEFICIT",IF(AND(OR(AC19="B", AC19="BPAL"), VLOOKUP(AF19,[1]Diccionario!B:N,13,0)="C"), "SOBREOFERTA",IF(AND(AC19="A", VLOOKUP(AF19,[1]Diccionario!B:N,13,0)="A"), "OK",IF( AND(AC19="A", OR(VLOOKUP(AF19,[1]Diccionario!B:N,13,0)="B", VLOOKUP(AF19,[1]Diccionario!B:N,13,0)="C")), "SOBREOFERTA","" ))))))),"") | AI19: =IF(AJ19="","",IF(AND((AJ19-AH19)>=TIME(0,0,0),(AJ19-AH19)<TIME(0,3,0)),"OK",IF(AND((AJ19-AH19)>=TIME(0,3,0),(AJ19-AH19)<TIME(0,5,0)),"RETRASO DE 3-5 MIN",IF(AND((AJ19-AH19)>=TIME(0,5,0),(AJ19-AH19)<TIME(0,10,0)),"RETRASO DE 5-10 MIN",IF((AJ19-AH19)>=TIME(0,10,0),"RETRASO >10 MIN", IF(AND((AH19-AJ19)>=TIME(0,0,0),(AH19-AJ19)<TIME(0,3,0)),"OK",IF((AH19-AJ19)>=TIME(0,3,0),"ADELANTADO"))))))) | AK19: =IF(AB19<>"",HLOOKUP(VALUE(TEXT(AH19,"h:mm:ss")),IF($C$6="Laboral",[1]Input!$A$4:$Y$227,IF($C$6="Sábado",[1]Input!$A$231:$Y$452,[1]Input!$A$456:$Y$656)),VLOOKUP($C$4,[1]Input!$AG$2:$AI$99,3,0)+IF(AD$5="Ida",0,1),1),"") -> #N/A | AL19: =IF(AB20<>AB19,AVERAGEIF(AB$9:AB19,AB19,AK$9:AK19),"") | AM19: =IFERROR(IF(AB20<>AB19,AVERAGEIF(AB$9:AB19,AB19,AT$9:AT19),""),"") | AN19: =IFERROR(IF(AB20<>AB19,AVERAGEIF(AB$9:AB19,AB19,AU$9:AU19),""),"") | AO19: {=IFERROR(IF(AB20<>AB19,_xlfn.STDEV.P(IF(AB$9:AB19=AB19,AU$9:AU19)),""),"")} | AP19: {=IFERROR(IF(AB20<>AB19,_xlfn.STDEV.P(IF(AB$9:AB19=AB19,AT$9:AT19)),""),"")} | AQ19: =IFERROR(IF(AB19<>AB20,MAX((((AN19*24*60)/2)*(1+POWER((((AO19*24*60) / (AN19*24*60) )),2))) + ((AN19*24*60 )*-0.1 + (AL19*0.015)) +1,(((AN19*24*60)/2)*(1+POWER((((AO19*24*60) / (AN19*24*60 ))),2)))),""),"") | AR19: =IF(AND(AP19<>"",AM19<>""),IF(AB19<>AB20,((AM19*24*60) / 2 ) * (1 + POWER(((AP19*24*60) / (AM19*24*60)),2)),""),"") | AS19: =IF(AR19<>"",MAX(AQ19,AR19),"") | AT19: =IF(AJ19<>"H. Sale Real",IF(AND(AJ20<>"",LEFT(AD20,2)<>"NC"),IF(AND(AJ19<>"",LEFT(AD19,2)<>"NC",AJ19<>"H. Sale Real"),IF(AJ20-AJ19<0.208333333333333,AJ20-AJ19,""),IF(AND(AJ18<>"",LEFT(AD18,2)<>"NC",AJ18<>"H. Sale Real"),IF(AJ20-AJ18<0.208333333333333,AJ20-AJ18,""),IF(AND(AJ17<>"",LEFT(AD17,2)<>"NC",AJ17<>"H. Sale Real"),IF(AJ20-AJ17<0.208333333333333,AJ20-AJ17,""),IF(AND(AJ16<>"",LEFT(AD16,2)<>"NC",AJ16<>"H. Sale Real"),IF(AJ20-AJ16<0.208333333333333,AJ20-AJ16,""),IF(AND(AJ15<>"",LEFT(AD15,2)<>"NC",AJ15<>"H. Sale Real"),IF(AJ20-AJ15<0.208333333333333,AJ20-AJ15,""),""))))),""),"") | AU19: =IF(AH19<>"H. Sale Real",IF(AND(AH20<>"",LEFT(AD20,2)<>"NC"),IF(AND(AH19<>"",LEFT(AD19,2)<>"NC",AH19<>"H. Sale Real"),IF(AH20-AH19<0.208333333333333,AH20-AH19,""),IF(AND(AH18<>"",LEFT(AD18,2)<>"NC",AH18<>"H. Sale Real"),IF(AH20-AH18<0.208333333333333,AH20-AH18,""),IF(AND(AH17<>"",LEFT(AD17,2)<>"NC",AH17<>"H. Sale Real"),IF(AH20-AH17<0.208333333333333,AH20-AH17,""),IF(AND(AH16<>"",LEFT(AD16,2)<>"NC",AH16<>"H. Sale Real"),IF(AH20-AH16<0.208333333333333,AH20-AH16,""),IF(AND(AH15<>"",LEFT(AD15,2)<>"NC",AH15<>"H. Sale Real"),IF(AH20-AH15<0.208333333333333,AH20-AH15,""),""))))),""),"") | AX19: {=IF(AH19<>"",IF(AND(AX17:AX18<>"IE",AQ19<>0,AS19<>""),IF(IFERROR((AQ19/AS19),0) <=1,IFERROR(AQ19/AS19,""),1),""),"")} | BC19: 7 | BD19: =COUNTIFS($A:$A,$BC19,$C:$C,$BC$11) -> 0 | BE19: =BD19-COUNTIFS($A:$A,$BC19,$C:$C,$BC$11,$H:$H,"") -> 0 | BF19: =IFERROR((BE19/BD19),"") | BG19: =_xlfn.XLOOKUP(BC19,$A:$A,$R:$R,"0",0,-1) -> 0 | BH19: =_xlfn.XLOOKUP(BC19,$A:$A,$P:$P,"0",0,-1) -> 0 | BI19: =_xlfn.XLOOKUP(BC19,$A:$A,$W:$W,"",0,-1) | BL19: 7 | BM19: =COUNTIFS($AB:$AB,$BL19,$AD:$AD,$BL$11) -> 0 | BN19: =BM19-COUNTIFS($AB:$AB,$BL19,$AD:$AD,$BL$11,$AI:$AI,"") -> 0 | BO19: =IFERROR((BN19/BM19),"") | BP19: =_xlfn.XLOOKUP(BL19,$AB:$AB,$AS:$AS,"0",0,-1) -> 0 | BQ19: =_xlfn.XLOOKUP(BL19,$AB:$AB,$AQ:$AQ,"0",0,-1) -> 0 | BR19: =_xlfn.XLOOKUP(BL19,$AB:$AB,$AX:$AX,"",0,-1)
