Workbook

Sheet Planilla
EW1: Diccio | EX1: N° Interno | EY1: N° Chasis | EZ1: N Motor | FA1: Marca chasis | FB1: Modelo Chasis | FC1: Marca Carrocería | FD1: Modelo Carrocería | FE1: Año | FF1: Tipo de Bus | FG1: Nombre Terminal Asignado | FH1: Dirección Terminal | FI1: Comuna | FJ1: Tipo de bus | FM1: 3003 / SFWZ-16| | FN1: SFWZ-16| | FO1: SFWZ-16 | FP1: =VLOOKUP(FO1,EX:FF,9,0) -> B | FU1: SI(A13<>"";BUSCARH(VALOR(TEXTO(G13;"h:mm:ss"));SI($C$6="Laboral";$FT$4:$GR$227;SI($C$6="Sábado";$FT$231:$GR$452;$FT$456:$GR$656));BUSCARV($C$4;Input!$GZ$2:$HB$99;3;0)+SI(C$5="Ida";0;1);1);"") | GU1: 84 | GV1: 85 | GW1: 86 | GY1: ZTS | GZ1: SERVICIO TS | HA1: SERVICIO UN | HB1: POS | HF1: unidad | HG1: servicio | HH1: Terminal | HI1: CODIGO TS SERVICIO
EW2: Diccionario 1 | EY2: De Baja | EZ2: De Baja | FA2: De Baja | FB2: De Baja | FC2: De Baja | FD2: De Baja | FE2: De Baja | FF2: De Baja | FG2: De Baja | FH2: De Baja | FI2: De Baja | FM2: 3003 / SFWZ-16| | FN2: SFWZ-16| | FO2: SFWZ-16 | FP2: =VLOOKUP(FO2,EX:FF,9,0) -> B | FT2: INTERVALO PROGRAMADO | GY2: U9 | GZ2: B01 | HA2: B01 | HB2: 3 | HF2: AlfaU9 | HG2: B01 | HH2: Condell | HI2: 801
B3: Terminal | AC3: Terminal | EW3: Diccionario 1 | EX3: 1000 | EY3: D8478292K2PL | EZ3: YV3T7U524KA195142 | FA3: Volvo | FB3: B8R | FC3: MARCOPOLO | FD3: TORINO | FE3: 2019 | FF3: B2PAL | FG3: LOS LIBERTADORES | FH3: Los Liberadores 6450, Lote 4A | FI3: Huechuraba | FJ3: B | FM3: 3003 / SFWZ-16| | FN3: SFWZ-16| | FO3: SFWZ-16 | FP3: =VLOOKUP(FO3,EX:FF,9,0) -> B | FT3: LABORAL | FU3: P1 | FV3: P2 | FW3: P3 | FX3: P4 | FY3: P5 | FZ3: P6 | GA3: P7 | GB3: P8 | GC3: P9 | GD3: P10 | GE3: P11 | GF3: P12 | GG3: P13 | GH3: P14 | GI3: P15 | GJ3: P16 | GK3: P17 | GL3: P18 | GM3: P19 | GN3: P20 | GO3: P21 | GP3: P22 | GQ3: P23 | GR3: P24 | GY3: U9 | GZ3: B03 | HA3: B03 | HB3: 4 | HF3: AlfaU9 | HG3: B03 | HH3: El Retiro | HI3: 803
B4: Servicio | AC4: Servicio | EW4: Diccionario 1 | EX4: 1096 | EY4: D8482685K2PL | EZ4: YV3T7U521KA195230 | FA4: Volvo | FB4: B8R | FC4: MARCOPOLO | FD4: TORINO | FE4: 2019 | FF4: B2PAL | FG4: LOS LIBERTADORES | FH4: Los Liberadores 6450, Lote 4A | FI4: Huechuraba | FJ4: B | FM4: 3003 / SFWZ-16| | FN4: SFWZ-16| | FO4: SFWZ-16 | FP4: =VLOOKUP(FO4,EX:FF,9,0) -> B | FT4: MH | FU4: 0 | FV4: 0.041666667 | FW4: 0.083333333 | FX4: 0.125 | FY4: 0.16666667 | FZ4: 0.20833333 | GA4: 0.25 | GB4: 0.29166667 | GC4: 0.33333333 | GD4: 0.375 | GE4: 0.41666667 | GF4: 0.45833333 | GG4: 0.5 | GH4: 0.54166667 | GI4: 0.58333333 | GJ4: 0.625 | GK4: 0.66666667 | GL4: 0.70833333 | GM4: 0.75 | GN4: 0.79166667 | GO4: 0.83333333 | GP4: 0.875 | GQ4: 0.91666667 | GR4: 0.95833333 | GU4: 1 | GY4: U9 | GZ4: 105 | HA4: 105 | HB4: 5 | HF4: AlfaU9 | HG4: 105 | HH4: El Retiro | HI4: 805
B5: Sentido | AC5: Sentido | EW5: Diccionario 1 | EX5: 1002 | EY5: D8483833K2PL | EZ5: YV3T7U520KA195641 | FA5: Volvo | FB5: B8R | FC5: MARCOPOLO | FD5: TORINO | FE5: 2019 | FF5: B2PAL | FG5: LOS LIBERTADORES | FH5: Los Liberadores 6450, Lote 4A | FI5: Huechuraba | FJ5: B | FM5: 3003 / SFWZ-16| | FN5: SFWZ-16| | FO5: SFWZ-16 | FP5: =VLOOKUP(FO5,EX:FF,9,0) -> B | FT5: LP | FU5: 1 | FV5: 1 | FW5: 1 | FX5: 1 | FY5: 1 | FZ5: 1 | GA5: 1 | GB5: 1 | GC5: 1 | GD5: 1 | GE5: 1 | GF5: 1 | GG5: 1 | GH5: 1 | GI5: 1 | GJ5: 1 | GK5: 1 | GL5: 1 | GM5: 1 | GN5: 1 | GO5: 1 | GP5: 1 | GQ5: 1 | GR5: 1 | GU5: 2 | GY5: U9 | GZ5: B07 | HA5: B07 | HB5: 8 | HF5: AlfaU9 | HG5: B07 | HH5: Santa Marta | HI5: 807
B6: tipo de día | AC6: tipo de día | EW6: Diccionario 1 | EX6: 1003 | EY6: D8483530K2PL | EZ6: YV3T7U522KA195642 | FA6: Volvo | FB6: B8R | FC6: MARCOPOLO | FD6: TORINO | FE6: 2019 | FF6: B2PAL | FG6: LOS LIBERTADORES | FH6: Los Liberadores 6450, Lote 4A | FI6: Huechuraba | FJ6: B | FM6: 3004 / SFWZ-31| | FN6: SFWZ-31| | FO6: SFWZ-31 | FP6: =VLOOKUP(FO6,EX:FF,9,0) -> B | FT6: B01 | FU6: 28.92 | FV6: 0 | FW6: 0 | FX6: 0 | FY6: 0 | FZ6: 8.85 | GA6: 15.76 | GB6: 13.79 | GC6: 14.87 | GD6: 16.63 | GE6: 16.95 | GF6: 16.38 | GG6: 15.68 | GH6: 15.93 | GI6: 16.02 | GJ6: 15.485 | GK6: 14.685 | GL6: 13.585 | GM6: 14.31 | GN6: 16.51 | GO6: 18.045 | GP6: 19.45 | GQ6: 22.085 | GR6: 24.735 | GU6: 3 | GY6: U9 | GZ6: B08 | HA6: B08 | HB6: 10 | HF6: AlfaU9 | HG6: B08 | HH6: Santa Marta | HI6: 808
EW7: Diccionario 1 | EX7: 1004 | EY7: D8483789K2PL | EZ7: YV3T7U524KA195643 | FA7: Volvo | FB7: B8R | FC7: MARCOPOLO | FD7: TORINO | FE7: 2019 | FF7: B2PAL | FG7: SAN JOSE | FH7: San José 030 (José Besa 669) | FI7: San Bernardo | FJ7: B | FM7: 3004 / SFWZ-31| | FN7: SFWZ-31| | FO7: SFWZ-31 | FP7: =VLOOKUP(FO7,EX:FF,9,0) -> B | FT7: B03 | FU7: 0 | FV7: 0 | FW7: 0 | FX7: 0 | FY7: 0 | FZ7: 17.585 | GA7: 14.575 | GB7: 14.64 | GC7: 15.78 | GD7: 16.4 | GE7: 16.01 | GF7: 15.555 | GG7: 15.34 | GH7: 15.045 | GI7: 14.625 | GJ7: 14.175 | GK7: 13.545 | GL7: 13.395 | GM7: 15.2 | GN7: 16.955 | GO7: 18.275 | GP7: 19.905 | GQ7: 21.615 | GR7: 0 | GU7: 4 | GV7: 1 | GY7: U9 | GZ7: B09 | HA7: B09 | HB7: 12 | HF7: AlfaU9 | HG7: B09 | HH7: El Retiro | HI7: 809
EW8: Diccionario 1 | EX8: 1005 | EY8: D8484480K2PL | EZ8: YV3T7U524KA195688 | FA8: Volvo | FB8: B8R | FC8: MARCOPOLO | FD8: TORINO | FE8: 2019 | FF8: B2PAL | FG8: SAN JOSE | FH8: San José 030 (José Besa 669) | FI8: San Bernardo | FJ8: B | FM8: 3004 / SFWZ-31| | FN8: SFWZ-31| | FO8: SFWZ-31 | FP8: =VLOOKUP(FO8,EX:FF,9,0) -> B | FT8: 105 | FU8: 0 | FV8: 0 | FW8: 0 | FX8: 0 | FY8: 0 | FZ8: 18.435 | GA8: 15.275 | GB8: 14.62 | GC8: 16.635 | GD8: 17.05 | GE8: 16.82 | GF8: 16.61 | GG8: 16.31 | GH8: 16.055 | GI8: 15.29 | GJ8: 14.71 | GK8: 13.055 | GL8: 12.495 | GM8: 14.34 | GN8: 16.7 | GO8: 18.44 | GP8: 19.865 | GQ8: 21.83 | GR8: 23.995 | GU8: 5 | GV8: 2 | GY8: U9 | GZ8: B10 | HA8: B10 | HB8: 13 | HF8: AlfaU9 | HG8: B10 | HH8: Santa Marta | HI8: 810
EW9: Diccionario 1 | EX9: 1006 | EY9: D8484637K2PL | EZ9: YV3T7U528KA195712 | FA9: Volvo | FB9: B8R | FC9: MARCOPOLO | FD9: TORINO | FE9: 2019 | FF9: B2PAL | FG9: SAN JOSE | FH9: San José 030 (José Besa 669) | FI9: San Bernardo | FJ9: B | FM9: 3004 / SFWZ-31| | FN9: SFWZ-31| | FO9: SFWZ-31 | FP9: =VLOOKUP(FO9,EX:FF,9,0) -> B | FT9: 105 | FU9: 0 | FV9: 0 | FW9: 0 | FX9: 0 | FY9: 0 | FZ9: 19.51 | GA9: 15.235 | GB9: 14.655 | GC9: 16.62 | GD9: 17.48 | GE9: 17.01 | GF9: 16.145 | GG9: 15.605 | GH9: 16.08 | GI9: 15.86 | GJ9: 15.355 | GK9: 14.66 | GL9: 13.605 | GM9: 14.395 | GN9: 17.055 | GO9: 18.48 | GP9: 19.235 | GQ9: 20.845 | GR9: 22.865 | GU9: 6 | GV9: 3 | GY9: U9 | GZ9: 120 | HA9: 120 | HB9: 14 | HF9: AlfaU9 | HG9: 120 | HH9: Condell | HI9: 812
EW10: Diccionario 1 | EX10: 1007 | EY10: D8484676K2PL | EZ10: YV3T7U52XKA195713 | FA10: Volvo | FB10: B8R | FC10: MARCOPOLO | FD10: TORINO | FE10: 2019 | FF10: B2PAL | FG10: LOS LIBERTADORES | FH10: Los Liberadores 6450, Lote 4A | FI10: Huechuraba | FJ10: B | FM10: 3004 / SFWZ-31| | FN10: SFWZ-31| | FO10: SFWZ-31 | FP10: =VLOOKUP(FO10,EX:FF,9,0) -> B | FT10: 105c | FU10: 0 | FV10: 0 | FW10: 0 | FX10: 0 | FY10: 0 | FZ10: 10.78 | GA10: 19.005 | GB10: 16.43 | GC10: 18.565 | GD10: 9.805 | GE10: 0 | GF10: 0 | GG10: 0 | GH10: 0 | GI10: 0 | GJ10: 0 | GK10: 8.115 | GL10: 14.65 | GM10: 15.24 | GN10: 18.095 | GO10: 19.5 | GP10: 0 | GQ10: 0 | GR10: 0 | GU10: 7 | GV10: 4 | GY10: U9 | GZ10: B13 | HA10: B13 | HB10: 16 | HF10: AlfaU9 | HG10: B13 | HH10: Santa Marta | HI10: 813
BC11: =C4&" "&C5 | BL11: =AD4&" "&MID(AD5,1,3) | EW11: Diccionario 1 | EX11: 1008 | EY11: D8484733K2PL | EZ11: YV3T7U526KA195742 | FA11: Volvo | FB11: B8R | FC11: MARCOPOLO | FD11: TORINO | FE11: 2019 | FF11: B2PAL | FG11: LOS LIBERTADORES | FH11: Los Liberadores 6450, Lote 4A | FI11: Huechuraba | FJ11: B | FM11: 3004 / SFWZ-31| | FN11: SFWZ-31| | FO11: SFWZ-31 | FP11: =VLOOKUP(FO11,EX:FF,9,0) -> B | FT11: B07 | FU11: 0 | FV11: 0 | FW11: 0 | FX11: 0 | FY11: 0 | FZ11: 12.58 | GA11: 20.03 | GB11: 17.86 | GC11: 21.28 | GD11: 23.915 | GE11: 24.295 | GF11: 24.33 | GG11: 24.31 | GH11: 24.125 | GI11: 24.315 | GJ11: 23.335 | GK11: 19.745 | GL11: 15.08 | GM11: 17.465 | GN11: 23.745 | GO11: 27.27 | GP11: 29.185 | GQ11: 28.615 | GR11: 0 | GU11: 8 | GV11: 5 | GY11: U9 | GZ11: B16 | HA11: B16 | HB11: 17 | HF11: AlfaU9 | HG11: B16 | HH11: Santa Marta | HI11: 816
A12: Periodo | B12: TB Programado | C12: Tipo de Salida | D12: Cumple TB | E12: Bus | F12: Media Hora despacho | G12: ="H Sale Terminal"&""&C3 -> H Sale Terminal | H12: Cumple despacho | I12: H. Sale Real | J12: KM PERIODO | K12: KM PROMEDIO | L12: IR_REAL_PROM | M12: IR_PROG_PROM | N12: IR_PROG_DESVEST | O12: IR_REAL_DESVEST | P12: TE_IDEAL | Q12: TE_OBS | R12: TE_OBS_NET | S12: IR_REAL | T12: IR_PROG | U12: ="H llegada Terminal"&""&AD3 -> H llegada Terminal | V12: Hora de Llegada Real | W12: IE | X12: Causa Perdidas | Y12: observación | AB12: Periodo | AC12: TB Programado | AD12: Tipo de Salida | AE12: Cumple TB | AF12: Bus | AG12: Media Hora despcaho | AH12: ="H Sale Terminal"&""&AD3 -> H Sale Terminal | AI12: Cumple despacho | AJ12: H. Sale Real | AK12: KM PERIODO | AL12: KM PROMEDIO | AM12: IR_REAL_PROM | AN12: IR_PROG_PROM | AO12: IR_PROG_DESVEST | AP12: IR_PROG_DESVEST | AQ12: TE_IDEAL | AR12: TE_OBS | AS12: TE_OBS_NET | AT12: IR_REAL | AU12: IR_PROG | AV12: ="H llegada Terminal"&""&C3 -> H llegada Terminal | AW12: Hora de Legada Real | AX12: IE | AY12: Causa Perdidas | AZ12: observación | BC12: Periodo | BD12: Teórico | BE12: Real | BF12: ICF-P | BG12: TE Obs | BH12: TE Ideal | BI12: IE | BL12: Periodo | BM12: Teórico | BN12: Real | BO12: ICF-P | BP12: TE Obs | BQ12: TE Ideal | BR12: IE | EW12: Diccionario 1 | EX12: 1009 | EY12: D8481621K2PL | EZ12: YV3T7U528KA195175 | FA12: Volvo | FB12: B8R | FC12: MARCOPOLO | FD12: TORINO | FE12: 2019 | FF12: B2PAL | FG12: LOS LIBERTADORES | FH12: Los Liberadores 6450, Lote 4A | FI12: Huechuraba | FJ12: B | FM12: 3004 / SFWZ-31| | FN12: SFWZ-31| | FO12: SFWZ-31 | FP12: =VLOOKUP(FO12,EX:FF,9,0) -> B | FT12: B07y | FU12: 0 | FV12: 0 | FW12: 0 | FX12: 0 | FY12: 0 | FZ12: 0 | GA12: 11.345 | GB12: 10.845 | GC12: 0 | GD12: 0 | GE12: 0 | GF12: 0 | GG12: 0 | GH12: 0 | GI12: 0 | GJ12: 0 | GK12: 0 | GL12: 0 | GM12: 0 | GN12: 0 | GO12: 0 | GP12: 0 | GQ12: 0 | GR12: 0 | GU12: 9 | GV12: 6 | GY12: U9 | GZ12: B17 | HA12: B17 | HB12: 19 | HF12: AlfaU9 | HG12: B17 | HH12: Condell | HI12: 817
A13: =HOUR(G13)+1 -> 1 | D13: =IFERROR( IF(AND(OR(Planilla!B13="C",Planilla!B13="c"), VLOOKUP(E13,EX:FJ,13,0)="C"), "OK",IF(AND(OR(Planilla!B13="C",Planilla!B13="c"), OR(VLOOKUP(E13,EX:FJ,13,0)="B", VLOOKUP(E13,EX:FJ,13,0)="A")), "DEFICIT",IF( AND(OR(Planilla!B13="B", Planilla!B13="BPAL"), VLOOKUP(E13,EX:FJ,13,0)="B"), "OK",IF(AND(OR(Planilla!B13="B", Planilla!B13="BPAL"), VLOOKUP(E13,EX:FJ,13,0)="A"), "DEFICIT",IF(AND(OR(Planilla!B13="B", Planilla!B13="BPAL"), VLOOKUP(E13,EX:FJ,13,0)="C"), "SOBREOFERTA",IF(AND(Planilla!B13="A", VLOOKUP(E13,EX:FJ,13,0)="A"), "OK",IF( AND(Planilla!B13="A", OR(VLOOKUP(E13,EX:FJ,13,0)="B", VLOOKUP(E13,EX:FJ,13,0)="C")), "SOBREOFERTA","" ))))))),"") | H13: =IF(I13="","",IF(AND((I13-G13)>=TIME(0,0,0),(I13-G13)<TIME(0,3,0)),"OK",IF(AND((I13-G13)>=TIME(0,3,0),(I13-G13)<TIME(0,5,0)),"RETRASO DE 3-5 MIN",IF(AND((I13-G13)>=TIME(0,5,0),(I13-G13)<TIME(0,10,0)),"RETRASO DE 5-10 MIN",IF((I13-G13)>=TIME(0,10,0),"RETRASO >10 MIN", IF(AND((G13-I13)>=TIME(0,0,0),(G13-I13)<TIME(0,3,0)),"OK",IF((G13-I13)>=TIME(0,3,0),"ADELANTADO"))))))) | J13: =IF(A13<>"",HLOOKUP(VALUE(TEXT(G13,"h:mm:ss")),IF($C$6="Laboral",$FT$4:$GR$227,IF($C$6="Sábado",$FT$231:$GR$452,$FT$456:$GR$656)),VLOOKUP($C$4,$GZ$2:$HB$99,3,0)+IF(C$5="Ida",0,1),1),"") -> #N/A | K13: =IF(A14<>A13,AVERAGEIF(A$9:A13,A13,J$9:J13),"") | L13: =IFERROR(IF(A14<>A13,AVERAGEIF(A$9:A13,A13,S$9:S13),""),"") | M13: =IFERROR(IF(A14<>A13,AVERAGEIF(A$9:A13,A13,T$9:T13),""),"") | N13: {=IFERROR(IF(A14<>A13,_xlfn.STDEV.P(IF(A$9:A13=A13,T$9:T13)),""),"")} | O13: {=IFERROR(IF(A14<>A13,_xlfn.STDEV.P(IF(A$9:A13=A13,S$9:S13)),""),"")} | P13: =IFERROR(IF(A13<>A14,MAX((((M13*24*60)/2)*(1+POWER((((N13*24*60) / (M13*24*60) )),2))) + ((M13*24*60 )*-0.1 + (K13*0.015)) +1,(((M13*24*60)/2)*(1+POWER((((N13*24*60) / (M13*24*60 ))),2)))),""),"") | Q13: =IF(AND(O13<>"",L13<>""),IF(A13<>A14,((L13*24*60) / 2 ) * (1 + POWER(((O13*24*60) / (L13*24*60)),2)),""),"") | R13: =IF(Q13<>"",MAX(P13,Q13),"") | S13: =IF(I13<>"H. Sale Real",IF(AND(I14<>"",LEFT(C14,2)<>"NC"),IF(AND(I13<>"",LEFT(C13,2)<>"NC",I13<>"H. Sale Real"),IF(I14-I13<0.208333333333333,I14-I13,""),IF(AND(I12<>"",LEFT(C12,2)<>"NC",I12<>"H. Sale Real"),IF(I14-I12<0.208333333333333,I14-I12,""),IF(AND(I11<>"",LEFT(C11,2)<>"NC",I11<>"H. Sale Real"),IF(I14-I11<0.208333333333333,I14-I11,""),IF(AND(I10<>"",LEFT(C10,2)<>"NC",I10<>"H. Sale Real"),IF(I14-I10<0.208333333333333,I14-I10,""),IF(AND(I9<>"",LEFT(C9,2)<>"NC",I9<>"H. Sale Real"),IF(I14-I9<0.208333333333333,I14-I9,""),""))))),""),"") | T13: =IF(G13<>"H. Sale Real",IF(AND(G14<>"",LEFT(C14,2)<>"NC"),IF(AND(G13<>"",LEFT(C13,2)<>"NC",G13<>"H. Sale Real"),IF(G14-G13<0.208333333333333,G14-G13,""),IF(AND(G12<>"",LEFT(C12,2)<>"NC",G12<>"H. Sale Real"),IF(G14-G12<0.208333333333333,G14-G12,""),IF(AND(G11<>"",LEFT(C11,2)<>"NC",G11<>"H. Sale Real"),IF(G14-G11<0.208333333333333,G14-G11,""),IF(AND(G10<>"",LEFT(C10,2)<>"NC",G10<>"H. Sale Real"),IF(G14-G10<0.208333333333333,G14-G10,""),IF(AND(G9<>"",LEFT(C9,2)<>"NC",G9<>"H. Sale Real"),IF(G14-G9<0.208333333333333,G14-G9,""),""))))),""),"") | U13: 0.055555556 | W13: =IF(G13<>"",IF(AND(W12<>"IE",P13<>0,R13<>""),IF(IFERROR((P13/R13),0) <=1,IFERROR(P13/R13,""),1),""),"") | AB13: =HOUR(AH13)+1 -> 1 | AI13: =IF(AJ13="","",IF(AND((AJ13-AH13)>=TIME(0,0,0),(AJ13-AH13)<TIME(0,3,0)),"OK",IF(AND((AJ13-AH13)>=TIME(0,3,0),(AJ13-AH13)<TIME(0,5,0)),"RETRASO DE 3-5 MIN",IF(AND((AJ13-AH13)>=TIME(0,5,0),(AJ13-AH13)<TIME(0,10,0)),"RETRASO DE 5-10 MIN",IF((AJ13-AH13)>=TIME(0,10,0),"RETRASO >10 MIN", IF(AND((AH13-AJ13)>=TIME(0,0,0),(AH13-AJ13)<TIME(0,3,0)),"OK",IF((AH13-AJ13)>=TIME(0,3,0),"ADELANTADO"))))))) | AK13: =IF(AB13<>"",HLOOKUP(VALUE(TEXT(AH13,"h:mm:ss")),IF($C$6="Laboral",$FT$4:$GR$227,IF($C$6="Sábado",$FT$231:$GR$452,$FT$456:$GR$656)),VLOOKUP($C$4,$GZ$2:$HB$99,3,0)+IF(AD$5="Ida",0,1),1),"") -> #N/A | AL13: =IF(AB14<>AB13,AVERAGEIF(AB$9:AB13,AB13,AK$9:AK13),"") | AM13: =IFERROR(IF(AB14<>AB13,AVERAGEIF(AB$9:AB13,AB13,AT$9:AT13),""),"") | AN13: =IFERROR(IF(AB14<>AB13,AVERAGEIF(AB$9:AB13,AB13,AU$9:AU13),""),"") | AO13: {=IFERROR(IF(AB14<>AB13,_xlfn.STDEV.P(IF(AB$9:AB13=AB13,AU$9:AU13)),""),"")} | AP13: {=IFERROR(IF(AB14<>AB13,_xlfn.STDEV.P(IF(AB$9:AB13=AB13,AT$9:AT13)),""),"")} | AQ13: =IFERROR(IF(AB13<>AB14,MAX((((AN13*24*60)/2)*(1+POWER((((AO13*24*60) / (AN13*24*60) )),2))) + ((AN13*24*60 )*-0.1 + (AL13*0.015)) +1,(((AN13*24*60)/2)*(1+POWER((((AO13*24*60) / (AN13*24*60 ))),2)))),""),"") | AR13: =IF(AND(AP13<>"",AM13<>""),IF(AB13<>AB14,((AM13*24*60) / 2 ) * (1 + POWER(((AP13*24*60) / (AM13*24*60)),2)),""),"") | AS13: =IF(AR13<>"",MAX(AQ13,AR13),"") | AT13: =IF(AJ13<>"H. Sale Real",IF(AND(AJ14<>"",LEFT(AD14,2)<>"NC"),IF(AND(AJ13<>"",LEFT(AD13,2)<>"NC",AJ13<>"H. Sale Real"),IF(AJ14-AJ13<0.208333333333333,AJ14-AJ13,""),IF(AND(AJ12<>"",LEFT(AD12,2)<>"NC",AJ12<>"H. Sale Real"),IF(AJ14-AJ12<0.208333333333333,AJ14-AJ12,""),IF(AND(AJ11<>"",LEFT(AD11,2)<>"NC",AJ11<>"H. Sale Real"),IF(AJ14-AJ11<0.208333333333333,AJ14-AJ11,""),IF(AND(AJ10<>"",LEFT(AD10,2)<>"NC",AJ10<>"H. Sale Real"),IF(AJ14-AJ10<0.208333333333333,AJ14-AJ10,""),IF(AND(AJ9<>"",LEFT(AD9,2)<>"NC",AJ9<>"H. Sale Real"),IF(AJ14-AJ9<0.208333333333333,AJ14-AJ9,""),""))))),""),"") | AU13: =IF(AH13<>"H. Sale Real",IF(AND(AH14<>"",LEFT(AD14,2)<>"NC"),IF(AND(AH13<>"",LEFT(AD13,2)<>"NC",AH13<>"H. Sale Real"),IF(AH14-AH13<0.208333333333333,AH14-AH13,""),IF(AND(AH12<>"",LEFT(AD12,2)<>"NC",AH12<>"H. Sale Real"),IF(AH14-AH12<0.208333333333333,AH14-AH12,""),IF(AND(AH11<>"",LEFT(AD11,2)<>"NC",AH11<>"H. Sale Real"),IF(AH14-AH11<0.208333333333333,AH14-AH11,""),IF(AND(AH10<>"",LEFT(AD10,2)<>"NC",AH10<>"H. Sale Real"),IF(AH14-AH10<0.208333333333333,AH14-AH10,""),IF(AND(AH9<>"",LEFT(AD9,2)<>"NC",AH9<>"H. Sale Real"),IF(AH14-AH9<0.208333333333333,AH14-AH9,""),""))))),""),"") | AX13: =IF(AH13<>"",IF(AND(AX12<>"IE",AQ13<>0,AS13<>""),IF(IFERROR((AQ13/AS13),0) <=1,IFERROR(AQ13/AS13,""),1),""),"") | BC13: 1 | BD13: =COUNTIFS($A:$A,$BC13,$C:$C,$BC$11) -> 0 | BE13: =BD13-COUNTIFS($A:$A,$BC13,$C:$C,$BC$11,$H:$H,"") -> 0 | BF13: =IFERROR((BE13/BD13),"") | BG13: =_xlfn.XLOOKUP(BC13,$A:$A,$R:$R,"0",0,-1) | BH13: =_xlfn.XLOOKUP(BC13,$A:$A,$P:$P,"0",0,-1) | BI13: =_xlfn.XLOOKUP(BC13,$A:$A,$W:$W,"",0,-1) | BL13: 1 | BM13: =COUNTIFS($AB:$AB,$BL13,$AD:$AD,$BL$11) -> 0 | BN13: =BM13-COUNTIFS($AB:$AB,$BL13,$AD:$AD,$BL$11,$AI:$AI,"") -> 0 | BO13: =IFERROR((BN13/BM13),"") | BP13: =_xlfn.XLOOKUP(BL13,$AB:$AB,$AS:$AS,"0",0,-1) | BQ13: =_xlfn.XLOOKUP(BL13,$AB:$AB,$AQ:$AQ,"0",0,-1) | BR13: =_xlfn.XLOOKUP(BL13,$AB:$AB,$AX:$AX,"",0,-1) | EW13: Diccionario 1 | EX13: 1010 | EY13: D8482769K2PL | EZ13: YV3T7U522KA195303 | FA13: Volvo | FB13: B8R | FC13: MARCOPOLO | FD13: TORINO | FE13: 2019 | FF13: B2PAL | FG13: LOS LIBERTADORES | FH13: Los Liberadores 6450, Lote 4A | FI13: Huechuraba | FJ13: B | FM13: 3004 / SFWZ-31| | FN13: SFWZ-31| | FO13: SFWZ-31 | FP13: =VLOOKUP(FO13,EX:FF,9,0) -> B | FT13: B08 | FU13: 14.46 | FV13: 0 | FW13: 0 | FX13: 0 | FY13: 0 | FZ13: 9.73 | GA13: 14.47 | GB13: 12.28 | GC13: 14.715 | GD13: 16.955 | GE13: 17.62 | GF13: 17.205 | GG13: 16.905 | GH13: 16.73 | GI13: 17.195 | GJ13: 16.89 | GK13: 15.54 | GL13: 12.46 | GM13: 13.01 | GN13: 17.045 | GO13: 20.16 | GP13: 22.21 | GQ13: 24.05 | GR13: 26.41 | GU13: 10 | GV13: 7 | GY13: U9 | GZ13: B18 | HA13: B18 | HB13: 20 | HF13: AlfaU9 | HG13: B18 | HH13: Santa Marta | HI13: 818
A14: =HOUR(G14)+1 -> 1 | D14: =IFERROR( IF(AND(OR(Planilla!B14="C",Planilla!B14="c"), VLOOKUP(E14,EX:FJ,13,0)="C"), "OK",IF(AND(OR(Planilla!B14="C",Planilla!B14="c"), OR(VLOOKUP(E14,EX:FJ,13,0)="B", VLOOKUP(E14,EX:FJ,13,0)="A")), "DEFICIT",IF( AND(OR(Planilla!B14="B", Planilla!B14="BPAL"), VLOOKUP(E14,EX:FJ,13,0)="B"), "OK",IF(AND(OR(Planilla!B14="B", Planilla!B14="BPAL"), VLOOKUP(E14,EX:FJ,13,0)="A"), "DEFICIT",IF(AND(OR(Planilla!B14="B", Planilla!B14="BPAL"), VLOOKUP(E14,EX:FJ,13,0)="C"), "SOBREOFERTA",IF(AND(Planilla!B14="A", VLOOKUP(E14,EX:FJ,13,0)="A"), "OK",IF( AND(Planilla!B14="A", OR(VLOOKUP(E14,EX:FJ,13,0)="B", VLOOKUP(E14,EX:FJ,13,0)="C")), "SOBREOFERTA","" ))))))),"") | H14: =IF(I14="","",IF(AND((I14-G14)>=TIME(0,0,0),(I14-G14)<TIME(0,3,0)),"OK",IF(AND((I14-G14)>=TIME(0,3,0),(I14-G14)<TIME(0,5,0)),"RETRASO DE 3-5 MIN",IF(AND((I14-G14)>=TIME(0,5,0),(I14-G14)<TIME(0,10,0)),"RETRASO DE 5-10 MIN",IF((I14-G14)>=TIME(0,10,0),"RETRASO >10 MIN", IF(AND((G14-I14)>=TIME(0,0,0),(G14-I14)<TIME(0,3,0)),"OK",IF((G14-I14)>=TIME(0,3,0),"ADELANTADO"))))))) | J14: =IF(A14<>"",HLOOKUP(VALUE(TEXT(G14,"h:mm:ss")),IF($C$6="Laboral",$FT$4:$GR$227,IF($C$6="Sábado",$FT$231:$GR$452,$FT$456:$GR$656)),VLOOKUP($C$4,$GZ$2:$HB$99,3,0)+IF(C$5="Ida",0,1),1),"") -> #N/A | K14: =IF(A15<>A14,AVERAGEIF(A$9:A14,A14,J$9:J14),"") | L14: =IFERROR(IF(A15<>A14,AVERAGEIF(A$9:A14,A14,S$9:S14),""),"") | M14: =IFERROR(IF(A15<>A14,AVERAGEIF(A$9:A14,A14,T$9:T14),""),"") | N14: {=IFERROR(IF(A15<>A14,_xlfn.STDEV.P(IF(A$9:A14=A14,T$9:T14)),""),"")} | O14: {=IFERROR(IF(A15<>A14,_xlfn.STDEV.P(IF(A$9:A14=A14,S$9:S14)),""),"")} | P14: =IFERROR(IF(A14<>A15,MAX((((M14*24*60)/2)*(1+POWER((((N14*24*60) / (M14*24*60) )),2))) + ((M14*24*60 )*-0.1 + (K14*0.015)) +1,(((M14*24*60)/2)*(1+POWER((((N14*24*60) / (M14*24*60 ))),2)))),""),"") | Q14: =IF(AND(O14<>"",L14<>""),IF(A14<>A15,((L14*24*60) / 2 ) * (1 + POWER(((O14*24*60) / (L14*24*60)),2)),""),"") | R14: =IF(Q14<>"",MAX(P14,Q14),"") | S14: =IF(I14<>"H. Sale Real",IF(AND(I15<>"",LEFT(C15,2)<>"NC"),IF(AND(I14<>"",LEFT(C14,2)<>"NC",I14<>"H. Sale Real"),IF(I15-I14<0.208333333333333,I15-I14,""),IF(AND(I13<>"",LEFT(C13,2)<>"NC",I13<>"H. Sale Real"),IF(I15-I13<0.208333333333333,I15-I13,""),IF(AND(I12<>"",LEFT(C12,2)<>"NC",I12<>"H. Sale Real"),IF(I15-I12<0.208333333333333,I15-I12,""),IF(AND(I11<>"",LEFT(C11,2)<>"NC",I11<>"H. Sale Real"),IF(I15-I11<0.208333333333333,I15-I11,""),IF(AND(I10<>"",LEFT(C10,2)<>"NC",I10<>"H. Sale Real"),IF(I15-I10<0.208333333333333,I15-I10,""),""))))),""),"") | T14: =IF(G14<>"H. Sale Real",IF(AND(G15<>"",LEFT(C15,2)<>"NC"),IF(AND(G14<>"",LEFT(C14,2)<>"NC",G14<>"H. Sale Real"),IF(G15-G14<0.208333333333333,G15-G14,""),IF(AND(G13<>"",LEFT(C13,2)<>"NC",G13<>"H. Sale Real"),IF(G15-G13<0.208333333333333,G15-G13,""),IF(AND(G12<>"",LEFT(C12,2)<>"NC",G12<>"H. Sale Real"),IF(G15-G12<0.208333333333333,G15-G12,""),IF(AND(G11<>"",LEFT(C11,2)<>"NC",G11<>"H. Sale Real"),IF(G15-G11<0.208333333333333,G15-G11,""),IF(AND(G10<>"",LEFT(C10,2)<>"NC",G10<>"H. Sale Real"),IF(G15-G10<0.208333333333333,G15-G10,""),""))))),""),"") | U14: 0.073611111 | W14: =IF(G14<>"",IF(AND(W13<>"IE",P14<>0,R14<>""),IF(IFERROR((P14/R14),0) <=1,IFERROR(P14/R14,""),1),""),"") | AB14: =HOUR(AH14)+1 -> 1 | AI14: =IF(AJ14="","",IF(AND((AJ14-AH14)>=TIME(0,0,0),(AJ14-AH14)<TIME(0,3,0)),"OK",IF(AND((AJ14-AH14)>=TIME(0,3,0),(AJ14-AH14)<TIME(0,5,0)),"RETRASO DE 3-5 MIN",IF(AND((AJ14-AH14)>=TIME(0,5,0),(AJ14-AH14)<TIME(0,10,0)),"RETRASO DE 5-10 MIN",IF((AJ14-AH14)>=TIME(0,10,0),"RETRASO >10 MIN", IF(AND((AH14-AJ14)>=TIME(0,0,0),(AH14-AJ14)<TIME(0,3,0)),"OK",IF((AH14-AJ14)>=TIME(0,3,0),"ADELANTADO"))))))) | AK14: =IF(AB14<>"",HLOOKUP(VALUE(TEXT(AH14,"h:mm:ss")),IF($C$6="Laboral",$FT$4:$GR$227,IF($C$6="Sábado",$FT$231:$GR$452,$FT$456:$GR$656)),VLOOKUP($C$4,$GZ$2:$HB$99,3,0)+IF(AD$5="Ida",0,1),1),"") -> #N/A | AL14: =IF(AB15<>AB14,AVERAGEIF(AB$9:AB14,AB14,AK$9:AK14),"") | AM14: =IFERROR(IF(AB15<>AB14,AVERAGEIF(AB$9:AB14,AB14,AT$9:AT14),""),"") | AN14: =IFERROR(IF(AB15<>AB14,AVERAGEIF(AB$9:AB14,AB14,AU$9:AU14),""),"") | AO14: {=IFERROR(IF(AB15<>AB14,_xlfn.STDEV.P(IF(AB$9:AB14=AB14,AU$9:AU14)),""),"")} | AP14: {=IFERROR(IF(AB15<>AB14,_xlfn.STDEV.P(IF(AB$9:AB14=AB14,AT$9:AT14)),""),"")} | AQ14: =IFERROR(IF(AB14<>AB15,MAX((((AN14*24*60)/2)*(1+POWER((((AO14*24*60) / (AN14*24*60) )),2))) + ((AN14*24*60 )*-0.1 + (AL14*0.015)) +1,(((AN14*24*60)/2)*(1+POWER((((AO14*24*60) / (AN14*24*60 ))),2)))),""),"") | AR14: =IF(AND(AP14<>"",AM14<>""),IF(AB14<>AB15,((AM14*24*60) / 2 ) * (1 + POWER(((AP14*24*60) / (AM14*24*60)),2)),""),"") | AS14: =IF(AR14<>"",MAX(AQ14,AR14),"") | AT14: =IF(AJ14<>"H. Sale Real",IF(AND(AJ15<>"",LEFT(AD15,2)<>"NC"),IF(AND(AJ14<>"",LEFT(AD14,2)<>"NC",AJ14<>"H. Sale Real"),IF(AJ15-AJ14<0.208333333333333,AJ15-AJ14,""),IF(AND(AJ13<>"",LEFT(AD13,2)<>"NC",AJ13<>"H. Sale Real"),IF(AJ15-AJ13<0.208333333333333,AJ15-AJ13,""),IF(AND(AJ12<>"",LEFT(AD12,2)<>"NC",AJ12<>"H. Sale Real"),IF(AJ15-AJ12<0.208333333333333,AJ15-AJ12,""),IF(AND(AJ11<>"",LEFT(AD11,2)<>"NC",AJ11<>"H. Sale Real"),IF(AJ15-AJ11<0.208333333333333,AJ15-AJ11,""),IF(AND(AJ10<>"",LEFT(AD10,2)<>"NC",AJ10<>"H. Sale Real"),IF(AJ15-AJ10<0.208333333333333,AJ15-AJ10,""),""))))),""),"") | AU14: =IF(AH14<>"H. Sale Real",IF(AND(AH15<>"",LEFT(AD15,2)<>"NC"),IF(AND(AH14<>"",LEFT(AD14,2)<>"NC",AH14<>"H. Sale Real"),IF(AH15-AH14<0.208333333333333,AH15-AH14,""),IF(AND(AH13<>"",LEFT(AD13,2)<>"NC",AH13<>"H. Sale Real"),IF(AH15-AH13<0.208333333333333,AH15-AH13,""),IF(AND(AH12<>"",LEFT(AD12,2)<>"NC",AH12<>"H. Sale Real"),IF(AH15-AH12<0.208333333333333,AH15-AH12,""),IF(AND(AH11<>"",LEFT(AD11,2)<>"NC",AH11<>"H. Sale Real"),IF(AH15-AH11<0.208333333333333,AH15-AH11,""),IF(AND(AH10<>"",LEFT(AD10,2)<>"NC",AH10<>"H. Sale Real"),IF(AH15-AH10<0.208333333333333,AH15-AH10,""),""))))),""),"") | AX14: =IF(AH14<>"",IF(AND(AX13<>"IE",AQ14<>0,AS14<>""),IF(IFERROR((AQ14/AS14),0) <=1,IFERROR(AQ14/AS14,""),1),""),"") | BC14: 2 | BD14: =COUNTIFS($A:$A,$BC14,$C:$C,$BC$11) -> 0 | BE14: =BD14-COUNTIFS($A:$A,$BC14,$C:$C,$BC$11,$H:$H,"") -> 0 | BF14: =IFERROR((BE14/BD14),"") | BG14: =_xlfn.XLOOKUP(BC14,$A:$A,$R:$R,"0",0,-1) -> 0 | BH14: =_xlfn.XLOOKUP(BC14,$A:$A,$P:$P,"0",0,-1) -> 0 | BI14: =_xlfn.XLOOKUP(BC14,$A:$A,$W:$W,"",0,-1) | BL14: 2 | BM14: =COUNTIFS($AB:$AB,$BL14,$AD:$AD,$BL$11) -> 0 | BN14: =BM14-COUNTIFS($AB:$AB,$BL14,$AD:$AD,$BL$11,$AI:$AI,"") -> 0 | BO14: =IFERROR((BN14/BM14),"") | BP14: =_xlfn.XLOOKUP(BL14,$AB:$AB,$AS:$AS,"0",0,-1) -> 0 | BQ14: =_xlfn.XLOOKUP(BL14,$AB:$AB,$AQ:$AQ,"0",0,-1) -> 0 | BR14: =_xlfn.XLOOKUP(BL14,$AB:$AB,$AX:$AX,"",0,-1) | EW14: Diccionario 1 | EX14: 1011 | EY14: D8478205K2PL | EZ14: YV3T7U520KA195140 | FA14: Volvo | FB14: B8R | FC14: MARCOPOLO | FD14: TORINO | FE14: 2019 | FF14: B2PAL | FG14: LOS LIBERTADORES | FH14: Los Liberadores 6450, Lote 4A | FI14: Huechuraba | FJ14: B | FM14: 3005 / SFWZ-39| | FN14: SFWZ-39| | FO14: SFWZ-39 | FP14: =VLOOKUP(FO14,EX:FF,9,0) -> B | FT14: B08 | FU14: 0 | FV14: 0 | FW14: 0 | FX14: 0 | FY14: 14.545 | FZ14: 26.045 | GA14: 18.89 | GB14: 13.08 | GC14: 16.9 | GD14: 18.97 | GE14: 18.605 | GF14: 18.11 | GG14: 17.29 | GH14: 17.27 | GI14: 17.1 | GJ14: 16.02 | GK14: 15.145 | GL14: 13.705 | GM14: 13.455 | GN14: 16.795 | GO14: 19.67 | GP14: 21.5 | GQ14: 23.315 | GR14: 26.9 | GU14: 11 | GV14: 8 | GY14: U9 | GZ14: B20 | HA14: B20 | HB14: 24 | HF14: AlfaU9 | HG14: B20 | HH14: El Retiro | HI14: 820
A15: =HOUR(G15)+1 -> 1 | D15: =IFERROR( IF(AND(OR(Planilla!B15="C",Planilla!B15="c"), VLOOKUP(E15,EX:FJ,13,0)="C"), "OK",IF(AND(OR(Planilla!B15="C",Planilla!B15="c"), OR(VLOOKUP(E15,EX:FJ,13,0)="B", VLOOKUP(E15,EX:FJ,13,0)="A")), "DEFICIT",IF( AND(OR(Planilla!B15="B", Planilla!B15="BPAL"), VLOOKUP(E15,EX:FJ,13,0)="B"), "OK",IF(AND(OR(Planilla!B15="B", Planilla!B15="BPAL"), VLOOKUP(E15,EX:FJ,13,0)="A"), "DEFICIT",IF(AND(OR(Planilla!B15="B", Planilla!B15="BPAL"), VLOOKUP(E15,EX:FJ,13,0)="C"), "SOBREOFERTA",IF(AND(Planilla!B15="A", VLOOKUP(E15,EX:FJ,13,0)="A"), "OK",IF( AND(Planilla!B15="A", OR(VLOOKUP(E15,EX:FJ,13,0)="B", VLOOKUP(E15,EX:FJ,13,0)="C")), "SOBREOFERTA","" ))))))),"") | H15: =IF(I15="","",IF(AND((I15-G15)>=TIME(0,0,0),(I15-G15)<TIME(0,3,0)),"OK",IF(AND((I15-G15)>=TIME(0,3,0),(I15-G15)<TIME(0,5,0)),"RETRASO DE 3-5 MIN",IF(AND((I15-G15)>=TIME(0,5,0),(I15-G15)<TIME(0,10,0)),"RETRASO DE 5-10 MIN",IF((I15-G15)>=TIME(0,10,0),"RETRASO >10 MIN", IF(AND((G15-I15)>=TIME(0,0,0),(G15-I15)<TIME(0,3,0)),"OK",IF((G15-I15)>=TIME(0,3,0),"ADELANTADO"))))))) | J15: =IF(A15<>"",HLOOKUP(VALUE(TEXT(G15,"h:mm:ss")),IF($C$6="Laboral",$FT$4:$GR$227,IF($C$6="Sábado",$FT$231:$GR$452,$FT$456:$GR$656)),VLOOKUP($C$4,$GZ$2:$HB$99,3,0)+IF(C$5="Ida",0,1),1),"") -> #N/A | K15: =IF(A16<>A15,AVERAGEIF(A$9:A15,A15,J$9:J15),"") | L15: =IFERROR(IF(A16<>A15,AVERAGEIF(A$9:A15,A15,S$9:S15),""),"") | M15: =IFERROR(IF(A16<>A15,AVERAGEIF(A$9:A15,A15,T$9:T15),""),"") | N15: {=IFERROR(IF(A16<>A15,_xlfn.STDEV.P(IF(A$9:A15=A15,T$9:T15)),""),"")} | O15: {=IFERROR(IF(A16<>A15,_xlfn.STDEV.P(IF(A$9:A15=A15,S$9:S15)),""),"")} | P15: =IFERROR(IF(A15<>A16,MAX((((M15*24*60)/2)*(1+POWER((((N15*24*60) / (M15*24*60) )),2))) + ((M15*24*60 )*-0.1 + (K15*0.015)) +1,(((M15*24*60)/2)*(1+POWER((((N15*24*60) / (M15*24*60 ))),2)))),""),"") | Q15: =IF(AND(O15<>"",L15<>""),IF(A15<>A16,((L15*24*60) / 2 ) * (1 + POWER(((O15*24*60) / (L15*24*60)),2)),""),"") | R15: =IF(Q15<>"",MAX(P15,Q15),"") | S15: =IF(I15<>"H. Sale Real",IF(AND(I16<>"",LEFT(C16,2)<>"NC"),IF(AND(I15<>"",LEFT(C15,2)<>"NC",I15<>"H. Sale Real"),IF(I16-I15<0.208333333333333,I16-I15,""),IF(AND(I14<>"",LEFT(C14,2)<>"NC",I14<>"H. Sale Real"),IF(I16-I14<0.208333333333333,I16-I14,""),IF(AND(I13<>"",LEFT(C13,2)<>"NC",I13<>"H. Sale Real"),IF(I16-I13<0.208333333333333,I16-I13,""),IF(AND(I12<>"",LEFT(C12,2)<>"NC",I12<>"H. Sale Real"),IF(I16-I12<0.208333333333333,I16-I12,""),IF(AND(I11<>"",LEFT(C11,2)<>"NC",I11<>"H. Sale Real"),IF(I16-I11<0.208333333333333,I16-I11,""),""))))),""),"") | T15: =IF(G15<>"H. Sale Real",IF(AND(G16<>"",LEFT(C16,2)<>"NC"),IF(AND(G15<>"",LEFT(C15,2)<>"NC",G15<>"H. Sale Real"),IF(G16-G15<0.208333333333333,G16-G15,""),IF(AND(G14<>"",LEFT(C14,2)<>"NC",G14<>"H. Sale Real"),IF(G16-G14<0.208333333333333,G16-G14,""),IF(AND(G13<>"",LEFT(C13,2)<>"NC",G13<>"H. Sale Real"),IF(G16-G13<0.208333333333333,G16-G13,""),IF(AND(G12<>"",LEFT(C12,2)<>"NC",G12<>"H. Sale Real"),IF(G16-G12<0.208333333333333,G16-G12,""),IF(AND(G11<>"",LEFT(C11,2)<>"NC",G11<>"H. Sale Real"),IF(G16-G11<0.208333333333333,G16-G11,""),""))))),""),"") | U15: 0.094444444 | W15: =IF(G15<>"",IF(AND(W14<>"IE",P15<>0,R15<>""),IF(IFERROR((P15/R15),0) <=1,IFERROR(P15/R15,""),1),""),"") | AB15: =HOUR(AH15)+1 -> 1 | AI15: =IF(AJ15="","",IF(AND((AJ15-AH15)>=TIME(0,0,0),(AJ15-AH15)<TIME(0,3,0)),"OK",IF(AND((AJ15-AH15)>=TIME(0,3,0),(AJ15-AH15)<TIME(0,5,0)),"RETRASO DE 3-5 MIN",IF(AND((AJ15-AH15)>=TIME(0,5,0),(AJ15-AH15)<TIME(0,10,0)),"RETRASO DE 5-10 MIN",IF((AJ15-AH15)>=TIME(0,10,0),"RETRASO >10 MIN", IF(AND((AH15-AJ15)>=TIME(0,0,0),(AH15-AJ15)<TIME(0,3,0)),"OK",IF((AH15-AJ15)>=TIME(0,3,0),"ADELANTADO"))))))) | AK15: =IF(AB15<>"",HLOOKUP(VALUE(TEXT(AH15,"h:mm:ss")),IF($C$6="Laboral",$FT$4:$GR$227,IF($C$6="Sábado",$FT$231:$GR$452,$FT$456:$GR$656)),VLOOKUP($C$4,$GZ$2:$HB$99,3,0)+IF(AD$5="Ida",0,1),1),"") -> #N/A | AL15: =IF(AB16<>AB15,AVERAGEIF(AB$9:AB15,AB15,AK$9:AK15),"") | AM15: =IFERROR(IF(AB16<>AB15,AVERAGEIF(AB$9:AB15,AB15,AT$9:AT15),""),"") | AN15: =IFERROR(IF(AB16<>AB15,AVERAGEIF(AB$9:AB15,AB15,AU$9:AU15),""),"") | AO15: {=IFERROR(IF(AB16<>AB15,_xlfn.STDEV.P(IF(AB$9:AB15=AB15,AU$9:AU15)),""),"")} | AP15: {=IFERROR(IF(AB16<>AB15,_xlfn.STDEV.P(IF(AB$9:AB15=AB15,AT$9:AT15)),""),"")} | AQ15: =IFERROR(IF(AB15<>AB16,MAX((((AN15*24*60)/2)*(1+POWER((((AO15*24*60) / (AN15*24*60) )),2))) + ((AN15*24*60 )*-0.1 + (AL15*0.015)) +1,(((AN15*24*60)/2)*(1+POWER((((AO15*24*60) / (AN15*24*60 ))),2)))),""),"") | AR15: =IF(AND(AP15<>"",AM15<>""),IF(AB15<>AB16,((AM15*24*60) / 2 ) * (1 + POWER(((AP15*24*60) / (AM15*24*60)),2)),""),"") | AS15: =IF(AR15<>"",MAX(AQ15,AR15),"") | AT15: =IF(AJ15<>"H. Sale Real",IF(AND(AJ16<>"",LEFT(AD16,2)<>"NC"),IF(AND(AJ15<>"",LEFT(AD15,2)<>"NC",AJ15<>"H. Sale Real"),IF(AJ16-AJ15<0.208333333333333,AJ16-AJ15,""),IF(AND(AJ14<>"",LEFT(AD14,2)<>"NC",AJ14<>"H. Sale Real"),IF(AJ16-AJ14<0.208333333333333,AJ16-AJ14,""),IF(AND(AJ13<>"",LEFT(AD13,2)<>"NC",AJ13<>"H. Sale Real"),IF(AJ16-AJ13<0.208333333333333,AJ16-AJ13,""),IF(AND(AJ12<>"",LEFT(AD12,2)<>"NC",AJ12<>"H. Sale Real"),IF(AJ16-AJ12<0.208333333333333,AJ16-AJ12,""),IF(AND(AJ11<>"",LEFT(AD11,2)<>"NC",AJ11<>"H. Sale Real"),IF(AJ16-AJ11<0.208333333333333,AJ16-AJ11,""),""))))),""),"") | AU15: =IF(AH15<>"H. Sale Real",IF(AND(AH16<>"",LEFT(AD16,2)<>"NC"),IF(AND(AH15<>"",LEFT(AD15,2)<>"NC",AH15<>"H. Sale Real"),IF(AH16-AH15<0.208333333333333,AH16-AH15,""),IF(AND(AH14<>"",LEFT(AD14,2)<>"NC",AH14<>"H. Sale Real"),IF(AH16-AH14<0.208333333333333,AH16-AH14,""),IF(AND(AH13<>"",LEFT(AD13,2)<>"NC",AH13<>"H. Sale Real"),IF(AH16-AH13<0.208333333333333,AH16-AH13,""),IF(AND(AH12<>"",LEFT(AD12,2)<>"NC",AH12<>"H. Sale Real"),IF(AH16-AH12<0.208333333333333,AH16-AH12,""),IF(AND(AH11<>"",LEFT(AD11,2)<>"NC",AH11<>"H. Sale Real"),IF(AH16-AH11<0.208333333333333,AH16-AH11,""),""))))),""),"") | AX15: =IF(AH15<>"",IF(AND(AX14<>"IE",AQ15<>0,AS15<>""),IF(IFERROR((AQ15/AS15),0) <=1,IFERROR(AQ15/AS15,""),1),""),"") | BC15: 3 | BD15: =COUNTIFS($A:$A,$BC15,$C:$C,$BC$11) -> 0 | BE15: =BD15-COUNTIFS($A:$A,$BC15,$C:$C,$BC$11,$H:$H,"") -> 0 | BF15: =IFERROR((BE15/BD15),"") | BG15: =_xlfn.XLOOKUP(BC15,$A:$A,$R:$R,"0",0,-1) -> 0 | BH15: =_xlfn.XLOOKUP(BC15,$A:$A,$P:$P,"0",0,-1) -> 0 | BI15: =_xlfn.XLOOKUP(BC15,$A:$A,$W:$W,"",0,-1) | BL15: 3 | BM15: =COUNTIFS($AB:$AB,$BL15,$AD:$AD,$BL$11) -> 0 | BN15: =BM15-COUNTIFS($AB:$AB,$BL15,$AD:$AD,$BL$11,$AI:$AI,"") -> 0 | BO15: =IFERROR((BN15/BM15),"") | BP15: =_xlfn.XLOOKUP(BL15,$AB:$AB,$AS:$AS,"0",0,-1) -> 0 | BQ15: =_xlfn.XLOOKUP(BL15,$AB:$AB,$AQ:$AQ,"0",0,-1) -> 0 | BR15: =_xlfn.XLOOKUP(BL15,$AB:$AB,$AX:$AX,"",0,-1) | EW15: Diccionario 1 | EX15: 1012 | EY15: D8481556K2PL | EZ15: YV3T7U521KA195177 | FA15: Volvo | FB15: B8R | FC15: MARCOPOLO | FD15: TORINO | FE15: 2019 | FF15: B2PAL | FG15: SAN JOSE | FH15: San José 030 (José Besa 669) | FI15: San Bernardo | FJ15: B | FM15: 3005 / SFWZ-39| | FN15: SFWZ-39| | FO15: SFWZ-39 | FP15: =VLOOKUP(FO15,EX:FF,9,0) -> B | FT15: B09 | FU15: 0 | FV15: 0 | FW15: 0 | FX15: 0 | FY15: 13.245 | FZ15: 23.725 | GA15: 18.46 | GB15: 17.055 | GC15: 20.3 | GD15: 21.73 | GE15: 21.455 | GF15: 20.605 | GG15: 19.165 | GH15: 18.745 | GI15: 18.565 | GJ15: 17.68 | GK15: 17.115 | GL15: 16.725 | GM15: 18.5 | GN15: 21.01 | GO15: 23.135 | GP15: 25.075 | GQ15: 26.45 | GR15: 0 | GU15: 12 | GV15: 9 | GY15: U9 | GZ15: 722 | HA15: 722 | HB15: 25 | HF15: AlfaU9 | HG15: 722 | HH15: Santa Marta | HI15: 822
A16: =HOUR(G16)+1 -> 1 | D16: =IFERROR( IF(AND(OR(Planilla!B16="C",Planilla!B16="c"), VLOOKUP(E16,EX:FJ,13,0)="C"), "OK",IF(AND(OR(Planilla!B16="C",Planilla!B16="c"), OR(VLOOKUP(E16,EX:FJ,13,0)="B", VLOOKUP(E16,EX:FJ,13,0)="A")), "DEFICIT",IF( AND(OR(Planilla!B16="B", Planilla!B16="BPAL"), VLOOKUP(E16,EX:FJ,13,0)="B"), "OK",IF(AND(OR(Planilla!B16="B", Planilla!B16="BPAL"), VLOOKUP(E16,EX:FJ,13,0)="A"), "DEFICIT",IF(AND(OR(Planilla!B16="B", Planilla!B16="BPAL"), VLOOKUP(E16,EX:FJ,13,0)="C"), "SOBREOFERTA",IF(AND(Planilla!B16="A", VLOOKUP(E16,EX:FJ,13,0)="A"), "OK",IF( AND(Planilla!B16="A", OR(VLOOKUP(E16,EX:FJ,13,0)="B", VLOOKUP(E16,EX:FJ,13,0)="C")), "SOBREOFERTA","" ))))))),"") | H16: =IF(I16="","",IF(AND((I16-G16)>=TIME(0,0,0),(I16-G16)<TIME(0,3,0)),"OK",IF(AND((I16-G16)>=TIME(0,3,0),(I16-G16)<TIME(0,5,0)),"RETRASO DE 3-5 MIN",IF(AND((I16-G16)>=TIME(0,5,0),(I16-G16)<TIME(0,10,0)),"RETRASO DE 5-10 MIN",IF((I16-G16)>=TIME(0,10,0),"RETRASO >10 MIN", IF(AND((G16-I16)>=TIME(0,0,0),(G16-I16)<TIME(0,3,0)),"OK",IF((G16-I16)>=TIME(0,3,0),"ADELANTADO"))))))) | J16: =IF(A16<>"",HLOOKUP(VALUE(TEXT(G16,"h:mm:ss")),IF($C$6="Laboral",$FT$4:$GR$227,IF($C$6="Sábado",$FT$231:$GR$452,$FT$456:$GR$656)),VLOOKUP($C$4,$GZ$2:$HB$99,3,0)+IF(C$5="Ida",0,1),1),"") -> #N/A | K16: =IF(A17<>A16,AVERAGEIF(A$9:A16,A16,J$9:J16),"") | L16: =IFERROR(IF(A17<>A16,AVERAGEIF(A$9:A16,A16,S$9:S16),""),"") | M16: =IFERROR(IF(A17<>A16,AVERAGEIF(A$9:A16,A16,T$9:T16),""),"") | N16: {=IFERROR(IF(A17<>A16,_xlfn.STDEV.P(IF(A$9:A16=A16,T$9:T16)),""),"")} | O16: {=IFERROR(IF(A17<>A16,_xlfn.STDEV.P(IF(A$9:A16=A16,S$9:S16)),""),"")} | P16: =IFERROR(IF(A16<>A17,MAX((((M16*24*60)/2)*(1+POWER((((N16*24*60) / (M16*24*60) )),2))) + ((M16*24*60 )*-0.1 + (K16*0.015)) +1,(((M16*24*60)/2)*(1+POWER((((N16*24*60) / (M16*24*60 ))),2)))),""),"") | Q16: =IF(AND(O16<>"",L16<>""),IF(A16<>A17,((L16*24*60) / 2 ) * (1 + POWER(((O16*24*60) / (L16*24*60)),2)),""),"") | R16: =IF(Q16<>"",MAX(P16,Q16),"") | S16: =IF(I16<>"H. Sale Real",IF(AND(I17<>"",LEFT(C17,2)<>"NC"),IF(AND(I16<>"",LEFT(C16,2)<>"NC",I16<>"H. Sale Real"),IF(I17-I16<0.208333333333333,I17-I16,""),IF(AND(I15<>"",LEFT(C15,2)<>"NC",I15<>"H. Sale Real"),IF(I17-I15<0.208333333333333,I17-I15,""),IF(AND(I14<>"",LEFT(C14,2)<>"NC",I14<>"H. Sale Real"),IF(I17-I14<0.208333333333333,I17-I14,""),IF(AND(I13<>"",LEFT(C13,2)<>"NC",I13<>"H. Sale Real"),IF(I17-I13<0.208333333333333,I17-I13,""),IF(AND(I12<>"",LEFT(C12,2)<>"NC",I12<>"H. Sale Real"),IF(I17-I12<0.208333333333333,I17-I12,""),""))))),""),"") | T16: =IF(G16<>"H. Sale Real",IF(AND(G17<>"",LEFT(C17,2)<>"NC"),IF(AND(G16<>"",LEFT(C16,2)<>"NC",G16<>"H. Sale Real"),IF(G17-G16<0.208333333333333,G17-G16,""),IF(AND(G15<>"",LEFT(C15,2)<>"NC",G15<>"H. Sale Real"),IF(G17-G15<0.208333333333333,G17-G15,""),IF(AND(G14<>"",LEFT(C14,2)<>"NC",G14<>"H. Sale Real"),IF(G17-G14<0.208333333333333,G17-G14,""),IF(AND(G13<>"",LEFT(C13,2)<>"NC",G13<>"H. Sale Real"),IF(G17-G13<0.208333333333333,G17-G13,""),IF(AND(G12<>"",LEFT(C12,2)<>"NC",G12<>"H. Sale Real"),IF(G17-G12<0.208333333333333,G17-G12,""),""))))),""),"") | U16: 0.10833333 | W16: =IF(G16<>"",IF(AND(W15<>"IE",P16<>0,R16<>""),IF(IFERROR((P16/R16),0) <=1,IFERROR(P16/R16,""),1),""),"") | AB16: =HOUR(AH16)+1 -> 1 | AI16: =IF(AJ16="","",IF(AND((AJ16-AH16)>=TIME(0,0,0),(AJ16-AH16)<TIME(0,3,0)),"OK",IF(AND((AJ16-AH16)>=TIME(0,3,0),(AJ16-AH16)<TIME(0,5,0)),"RETRASO DE 3-5 MIN",IF(AND((AJ16-AH16)>=TIME(0,5,0),(AJ16-AH16)<TIME(0,10,0)),"RETRASO DE 5-10 MIN",IF((AJ16-AH16)>=TIME(0,10,0),"RETRASO >10 MIN", IF(AND((AH16-AJ16)>=TIME(0,0,0),(AH16-AJ16)<TIME(0,3,0)),"OK",IF((AH16-AJ16)>=TIME(0,3,0),"ADELANTADO"))))))) | AK16: =IF(AB16<>"",HLOOKUP(VALUE(TEXT(AH16,"h:mm:ss")),IF($C$6="Laboral",$FT$4:$GR$227,IF($C$6="Sábado",$FT$231:$GR$452,$FT$456:$GR$656)),VLOOKUP($C$4,$GZ$2:$HB$99,3,0)+IF(AD$5="Ida",0,1),1),"") -> #N/A | AL16: =IF(AB17<>AB16,AVERAGEIF(AB$9:AB16,AB16,AK$9:AK16),"") | AM16: =IFERROR(IF(AB17<>AB16,AVERAGEIF(AB$9:AB16,AB16,AT$9:AT16),""),"") | AN16: =IFERROR(IF(AB17<>AB16,AVERAGEIF(AB$9:AB16,AB16,AU$9:AU16),""),"") | AO16: {=IFERROR(IF(AB17<>AB16,_xlfn.STDEV.P(IF(AB$9:AB16=AB16,AU$9:AU16)),""),"")} | AP16: {=IFERROR(IF(AB17<>AB16,_xlfn.STDEV.P(IF(AB$9:AB16=AB16,AT$9:AT16)),""),"")} | AQ16: =IFERROR(IF(AB16<>AB17,MAX((((AN16*24*60)/2)*(1+POWER((((AO16*24*60) / (AN16*24*60) )),2))) + ((AN16*24*60 )*-0.1 + (AL16*0.015)) +1,(((AN16*24*60)/2)*(1+POWER((((AO16*24*60) / (AN16*24*60 ))),2)))),""),"") | AR16: =IF(AND(AP16<>"",AM16<>""),IF(AB16<>AB17,((AM16*24*60) / 2 ) * (1 + POWER(((AP16*24*60) / (AM16*24*60)),2)),""),"") | AS16: =IF(AR16<>"",MAX(AQ16,AR16),"") | AT16: =IF(AJ16<>"H. Sale Real",IF(AND(AJ17<>"",LEFT(AD17,2)<>"NC"),IF(AND(AJ16<>"",LEFT(AD16,2)<>"NC",AJ16<>"H. Sale Real"),IF(AJ17-AJ16<0.208333333333333,AJ17-AJ16,""),IF(AND(AJ15<>"",LEFT(AD15,2)<>"NC",AJ15<>"H. Sale Real"),IF(AJ17-AJ15<0.208333333333333,AJ17-AJ15,""),IF(AND(AJ14<>"",LEFT(AD14,2)<>"NC",AJ14<>"H. Sale Real"),IF(AJ17-AJ14<0.208333333333333,AJ17-AJ14,""),IF(AND(AJ13<>"",LEFT(AD13,2)<>"NC",AJ13<>"H. Sale Real"),IF(AJ17-AJ13<0.208333333333333,AJ17-AJ13,""),IF(AND(AJ12<>"",LEFT(AD12,2)<>"NC",AJ12<>"H. Sale Real"),IF(AJ17-AJ12<0.208333333333333,AJ17-AJ12,""),""))))),""),"") | AU16: =IF(AH16<>"H. Sale Real",IF(AND(AH17<>"",LEFT(AD17,2)<>"NC"),IF(AND(AH16<>"",LEFT(AD16,2)<>"NC",AH16<>"H. Sale Real"),IF(AH17-AH16<0.208333333333333,AH17-AH16,""),IF(AND(AH15<>"",LEFT(AD15,2)<>"NC",AH15<>"H. Sale Real"),IF(AH17-AH15<0.208333333333333,AH17-AH15,""),IF(AND(AH14<>"",LEFT(AD14,2)<>"NC",AH14<>"H. Sale Real"),IF(AH17-AH14<0.208333333333333,AH17-AH14,""),IF(AND(AH13<>"",LEFT(AD13,2)<>"NC",AH13<>"H. Sale Real"),IF(AH17-AH13<0.208333333333333,AH17-AH13,""),IF(AND(AH12<>"",LEFT(AD12,2)<>"NC",AH12<>"H. Sale Real"),IF(AH17-AH12<0.208333333333333,AH17-AH12,""),""))))),""),"") | AX16: =IF(AH16<>"",IF(AND(AX15<>"IE",AQ16<>0,AS16<>""),IF(IFERROR((AQ16/AS16),0) <=1,IFERROR(AQ16/AS16,""),1),""),"") | BC16: 4 | BD16: =COUNTIFS($A:$A,$BC16,$C:$C,$BC$11) -> 0 | BE16: =BD16-COUNTIFS($A:$A,$BC16,$C:$C,$BC$11,$H:$H,"") -> 0 | BF16: =IFERROR((BE16/BD16),"") | BG16: =_xlfn.XLOOKUP(BC16,$A:$A,$R:$R,"0",0,-1) -> 0 | BH16: =_xlfn.XLOOKUP(BC16,$A:$A,$P:$P,"0",0,-1) -> 0 | BI16: =_xlfn.XLOOKUP(BC16,$A:$A,$W:$W,"",0,-1) | BL16: 4 | BM16: =COUNTIFS($AB:$AB,$BL16,$AD:$AD,$BL$11) -> 0 | BN16: =BM16-COUNTIFS($AB:$AB,$BL16,$AD:$AD,$BL$11,$AI:$AI,"") -> 0 | BO16: =IFERROR((BN16/BM16),"") | BP16: =_xlfn.XLOOKUP(BL16,$AB:$AB,$AS:$AS,"0",0,-1) -> 0 | BQ16: =_xlfn.XLOOKUP(BL16,$AB:$AB,$AQ:$AQ,"0",0,-1) -> 0 | BR16: =_xlfn.XLOOKUP(BL16,$AB:$AB,$AX:$AX,"",0,-1) | EW16: Diccionario 1 | EX16: 1013 | EY16: D8482482K2PL | EZ16: YV3T7U523KA195326 | FA16: Volvo | FB16: B8R | FC16: MARCOPOLO | FD16: TORINO | FE16: 2019 | FF16: B2PAL | FG16: LOS LIBERTADORES | FH16: Los Liberadores 6450, Lote 4A | FI16: Huechuraba | FJ16: B | FM16: 3005 / SFWZ-39| | FN16: SFWZ-39| | FO16: SFWZ-39 | FP16: =VLOOKUP(FO16,EX:FF,9,0) -> B | FT16: B10 | FU16: 0 | FV16: 0 | FW16: 0 | FX16: 0 | FY16: 0 | FZ16: 9.58 | GA16: 15.145 | GB16: 12.605 | GC16: 14.385 | GD16: 15.19 | GE16: 15.085 | GF16: 14.8 | GG16: 14.43 | GH16: 14.59 | GI16: 14.42 | GJ16: 13.86 | GK16: 12.755 | GL16: 11.79 | GM16: 12.895 | GN16: 14.885 | GO16: 16.585 | GP16: 17.96 | GQ16: 20.45 | GR16: 23.575 | GU16: 13 | GV16: 10 | GY16: U9 | GZ16: B24 | HA16: B24 | HB16: 27 | HF16: AlfaU9 | HG16: B24 | HH16: Condell | HI16: 824
A17: =HOUR(G17)+1 -> 1 | D17: =IFERROR( IF(AND(OR(Planilla!B17="C",Planilla!B17="c"), VLOOKUP(E17,EX:FJ,13,0)="C"), "OK",IF(AND(OR(Planilla!B17="C",Planilla!B17="c"), OR(VLOOKUP(E17,EX:FJ,13,0)="B", VLOOKUP(E17,EX:FJ,13,0)="A")), "DEFICIT",IF( AND(OR(Planilla!B17="B", Planilla!B17="BPAL"), VLOOKUP(E17,EX:FJ,13,0)="B"), "OK",IF(AND(OR(Planilla!B17="B", Planilla!B17="BPAL"), VLOOKUP(E17,EX:FJ,13,0)="A"), "DEFICIT",IF(AND(OR(Planilla!B17="B", Planilla!B17="BPAL"), VLOOKUP(E17,EX:FJ,13,0)="C"), "SOBREOFERTA",IF(AND(Planilla!B17="A", VLOOKUP(E17,EX:FJ,13,0)="A"), "OK",IF( AND(Planilla!B17="A", OR(VLOOKUP(E17,EX:FJ,13,0)="B", VLOOKUP(E17,EX:FJ,13,0)="C")), "SOBREOFERTA","" ))))))),"") | H17: =IF(I17="","",IF(AND((I17-G17)>=TIME(0,0,0),(I17-G17)<TIME(0,3,0)),"OK",IF(AND((I17-G17)>=TIME(0,3,0),(I17-G17)<TIME(0,5,0)),"RETRASO DE 3-5 MIN",IF(AND((I17-G17)>=TIME(0,5,0),(I17-G17)<TIME(0,10,0)),"RETRASO DE 5-10 MIN",IF((I17-G17)>=TIME(0,10,0),"RETRASO >10 MIN", IF(AND((G17-I17)>=TIME(0,0,0),(G17-I17)<TIME(0,3,0)),"OK",IF((G17-I17)>=TIME(0,3,0),"ADELANTADO"))))))) | J17: =IF(A17<>"",HLOOKUP(VALUE(TEXT(G17,"h:mm:ss")),IF($C$6="Laboral",$FT$4:$GR$227,IF($C$6="Sábado",$FT$231:$GR$452,$FT$456:$GR$656)),VLOOKUP($C$4,$GZ$2:$HB$99,3,0)+IF(C$5="Ida",0,1),1),"") -> #N/A | K17: =IF(A18<>A17,AVERAGEIF(A$9:A17,A17,J$9:J17),"") | L17: =IFERROR(IF(A18<>A17,AVERAGEIF(A$9:A17,A17,S$9:S17),""),"") | M17: =IFERROR(IF(A18<>A17,AVERAGEIF(A$9:A17,A17,T$9:T17),""),"") | N17: {=IFERROR(IF(A18<>A17,_xlfn.STDEV.P(IF(A$9:A17=A17,T$9:T17)),""),"")} | O17: {=IFERROR(IF(A18<>A17,_xlfn.STDEV.P(IF(A$9:A17=A17,S$9:S17)),""),"")} | P17: =IFERROR(IF(A17<>A18,MAX((((M17*24*60)/2)*(1+POWER((((N17*24*60) / (M17*24*60) )),2))) + ((M17*24*60 )*-0.1 + (K17*0.015)) +1,(((M17*24*60)/2)*(1+POWER((((N17*24*60) / (M17*24*60 ))),2)))),""),"") | Q17: =IF(AND(O17<>"",L17<>""),IF(A17<>A18,((L17*24*60) / 2 ) * (1 + POWER(((O17*24*60) / (L17*24*60)),2)),""),"") | R17: =IF(Q17<>"",MAX(P17,Q17),"") | S17: =IF(I17<>"H. Sale Real",IF(AND(I18<>"",LEFT(C18,2)<>"NC"),IF(AND(I17<>"",LEFT(C17,2)<>"NC",I17<>"H. Sale Real"),IF(I18-I17<0.208333333333333,I18-I17,""),IF(AND(I16<>"",LEFT(C16,2)<>"NC",I16<>"H. Sale Real"),IF(I18-I16<0.208333333333333,I18-I16,""),IF(AND(I15<>"",LEFT(C15,2)<>"NC",I15<>"H. Sale Real"),IF(I18-I15<0.208333333333333,I18-I15,""),IF(AND(I14<>"",LEFT(C14,2)<>"NC",I14<>"H. Sale Real"),IF(I18-I14<0.208333333333333,I18-I14,""),IF(AND(I13<>"",LEFT(C13,2)<>"NC",I13<>"H. Sale Real"),IF(I18-I13<0.208333333333333,I18-I13,""),""))))),""),"") | T17: =IF(G17<>"H. Sale Real",IF(AND(G18<>"",LEFT(C18,2)<>"NC"),IF(AND(G17<>"",LEFT(C17,2)<>"NC",G17<>"H. Sale Real"),IF(G18-G17<0.208333333333333,G18-G17,""),IF(AND(G16<>"",LEFT(C16,2)<>"NC",G16<>"H. Sale Real"),IF(G18-G16<0.208333333333333,G18-G16,""),IF(AND(G15<>"",LEFT(C15,2)<>"NC",G15<>"H. Sale Real"),IF(G18-G15<0.208333333333333,G18-G15,""),IF(AND(G14<>"",LEFT(C14,2)<>"NC",G14<>"H. Sale Real"),IF(G18-G14<0.208333333333333,G18-G14,""),IF(AND(G13<>"",LEFT(C13,2)<>"NC",G13<>"H. Sale Real"),IF(G18-G13<0.208333333333333,G18-G13,""),""))))),""),"") | U17: 0.12083333 | W17: =IF(G17<>"",IF(AND(W16<>"IE",P17<>0,R17<>""),IF(IFERROR((P17/R17),0) <=1,IFERROR(P17/R17,""),1),""),"") | AB17: =HOUR(AH17)+1 -> 1 | AI17: =IF(AJ17="","",IF(AND((AJ17-AH17)>=TIME(0,0,0),(AJ17-AH17)<TIME(0,3,0)),"OK",IF(AND((AJ17-AH17)>=TIME(0,3,0),(AJ17-AH17)<TIME(0,5,0)),"RETRASO DE 3-5 MIN",IF(AND((AJ17-AH17)>=TIME(0,5,0),(AJ17-AH17)<TIME(0,10,0)),"RETRASO DE 5-10 MIN",IF((AJ17-AH17)>=TIME(0,10,0),"RETRASO >10 MIN", IF(AND((AH17-AJ17)>=TIME(0,0,0),(AH17-AJ17)<TIME(0,3,0)),"OK",IF((AH17-AJ17)>=TIME(0,3,0),"ADELANTADO"))))))) | AK17: =IF(AB17<>"",HLOOKUP(VALUE(TEXT(AH17,"h:mm:ss")),IF($C$6="Laboral",$FT$4:$GR$227,IF($C$6="Sábado",$FT$231:$GR$452,$FT$456:$GR$656)),VLOOKUP($C$4,$GZ$2:$HB$99,3,0)+IF(AD$5="Ida",0,1),1),"") -> #N/A | AL17: =IF(AB18<>AB17,AVERAGEIF(AB$9:AB17,AB17,AK$9:AK17),"") | AM17: =IFERROR(IF(AB18<>AB17,AVERAGEIF(AB$9:AB17,AB17,AT$9:AT17),""),"") | AN17: =IFERROR(IF(AB18<>AB17,AVERAGEIF(AB$9:AB17,AB17,AU$9:AU17),""),"") | AO17: {=IFERROR(IF(AB18<>AB17,_xlfn.STDEV.P(IF(AB$9:AB17=AB17,AU$9:AU17)),""),"")} | AP17: {=IFERROR(IF(AB18<>AB17,_xlfn.STDEV.P(IF(AB$9:AB17=AB17,AT$9:AT17)),""),"")} | AQ17: =IFERROR(IF(AB17<>AB18,MAX((((AN17*24*60)/2)*(1+POWER((((AO17*24*60) / (AN17*24*60) )),2))) + ((AN17*24*60 )*-0.1 + (AL17*0.015)) +1,(((AN17*24*60)/2)*(1+POWER((((AO17*24*60) / (AN17*24*60 ))),2)))),""),"") | AR17: =IF(AND(AP17<>"",AM17<>""),IF(AB17<>AB18,((AM17*24*60) / 2 ) * (1 + POWER(((AP17*24*60) / (AM17*24*60)),2)),""),"") | AS17: =IF(AR17<>"",MAX(AQ17,AR17),"") | AT17: =IF(AJ17<>"H. Sale Real",IF(AND(AJ18<>"",LEFT(AD18,2)<>"NC"),IF(AND(AJ17<>"",LEFT(AD17,2)<>"NC",AJ17<>"H. Sale Real"),IF(AJ18-AJ17<0.208333333333333,AJ18-AJ17,""),IF(AND(AJ16<>"",LEFT(AD16,2)<>"NC",AJ16<>"H. Sale Real"),IF(AJ18-AJ16<0.208333333333333,AJ18-AJ16,""),IF(AND(AJ15<>"",LEFT(AD15,2)<>"NC",AJ15<>"H. Sale Real"),IF(AJ18-AJ15<0.208333333333333,AJ18-AJ15,""),IF(AND(AJ14<>"",LEFT(AD14,2)<>"NC",AJ14<>"H. Sale Real"),IF(AJ18-AJ14<0.208333333333333,AJ18-AJ14,""),IF(AND(AJ13<>"",LEFT(AD13,2)<>"NC",AJ13<>"H. Sale Real"),IF(AJ18-AJ13<0.208333333333333,AJ18-AJ13,""),""))))),""),"") | AU17: =IF(AH17<>"H. Sale Real",IF(AND(AH18<>"",LEFT(AD18,2)<>"NC"),IF(AND(AH17<>"",LEFT(AD17,2)<>"NC",AH17<>"H. Sale Real"),IF(AH18-AH17<0.208333333333333,AH18-AH17,""),IF(AND(AH16<>"",LEFT(AD16,2)<>"NC",AH16<>"H. Sale Real"),IF(AH18-AH16<0.208333333333333,AH18-AH16,""),IF(AND(AH15<>"",LEFT(AD15,2)<>"NC",AH15<>"H. Sale Real"),IF(AH18-AH15<0.208333333333333,AH18-AH15,""),IF(AND(AH14<>"",LEFT(AD14,2)<>"NC",AH14<>"H. Sale Real"),IF(AH18-AH14<0.208333333333333,AH18-AH14,""),IF(AND(AH13<>"",LEFT(AD13,2)<>"NC",AH13<>"H. Sale Real"),IF(AH18-AH13<0.208333333333333,AH18-AH13,""),""))))),""),"") | AX17: =IF(AH17<>"",IF(AND(AX16<>"IE",AQ17<>0,AS17<>""),IF(IFERROR((AQ17/AS17),0) <=1,IFERROR(AQ17/AS17,""),1),""),"") | BC17: 5 | BD17: =COUNTIFS($A:$A,$BC17,$C:$C,$BC$11) -> 0 | BE17: =BD17-COUNTIFS($A:$A,$BC17,$C:$C,$BC$11,$H:$H,"") -> 0 | BF17: =IFERROR((BE17/BD17),"") | BG17: =_xlfn.XLOOKUP(BC17,$A:$A,$R:$R,"0",0,-1) -> 0 | BH17: =_xlfn.XLOOKUP(BC17,$A:$A,$P:$P,"0",0,-1) -> 0 | BI17: =_xlfn.XLOOKUP(BC17,$A:$A,$W:$W,"",0,-1) | BL17: 5 | BM17: =COUNTIFS($AB:$AB,$BL17,$AD:$AD,$BL$11) -> 0 | BN17: =BM17-COUNTIFS($AB:$AB,$BL17,$AD:$AD,$BL$11,$AI:$AI,"") -> 0 | BO17: =IFERROR((BN17/BM17),"") | BP17: =_xlfn.XLOOKUP(BL17,$AB:$AB,$AS:$AS,"0",0,-1) -> 0 | BQ17: =_xlfn.XLOOKUP(BL17,$AB:$AB,$AQ:$AQ,"0",0,-1) -> 0 | BR17: =_xlfn.XLOOKUP(BL17,$AB:$AB,$AX:$AX,"",0,-1) | EW17: Diccionario 1 | EX17: 1014 | EY17: D8482478K2PL | EZ17: YV3T7U525KA195327 | FA17: Volvo | FB17: B8R | FC17: MARCOPOLO | FD17: TORINO | FE17: 2019 | FF17: B2PAL | FG17: LOS LIBERTADORES | FH17: Los Liberadores 6450, Lote 4A | FI17: Huechuraba | FJ17: B | FM17: 3005 / SFWZ-39| | FN17: SFWZ-39| | FO17: SFWZ-39 | FP17: =VLOOKUP(FO17,EX:FF,9,0) -> B | FT17: 120 | FU17: 0 | FV17: 0 | FW17: 0 | FX17: 0 | FY17: 27.31 | FZ17: 22.005 | GA17: 16.685 | GB17: 14.945 | GC17: 16.83 | GD17: 17.985 | GE17: 18.065 | GF17: 17.725 | GG17: 17.03 | GH17: 17.105 | GI17: 16.605 | GJ17: 15.62 | GK17: 13.25 | GL17: 11.98 | GM17: 14.1 | GN17: 17.32 | GO17: 19.92 | GP17: 21.765 | GQ17: 23.685 | GR17: 25.535 | GU17: 14 | GV17: 11 | GY17: U9 | GZ17: B25 | HA17: B25 | HB17: 28 | HF17: AlfaU9 | HG17: B25 | HH17: Santa Marta | HI17: 825
A18: =HOUR(G18)+1 -> 1 | D18: =IFERROR( IF(AND(OR(Planilla!B18="C",Planilla!B18="c"), VLOOKUP(E18,EX:FJ,13,0)="C"), "OK",IF(AND(OR(Planilla!B18="C",Planilla!B18="c"), OR(VLOOKUP(E18,EX:FJ,13,0)="B", VLOOKUP(E18,EX:FJ,13,0)="A")), "DEFICIT",IF( AND(OR(Planilla!B18="B", Planilla!B18="BPAL"), VLOOKUP(E18,EX:FJ,13,0)="B"), "OK",IF(AND(OR(Planilla!B18="B", Planilla!B18="BPAL"), VLOOKUP(E18,EX:FJ,13,0)="A"), "DEFICIT",IF(AND(OR(Planilla!B18="B", Planilla!B18="BPAL"), VLOOKUP(E18,EX:FJ,13,0)="C"), "SOBREOFERTA",IF(AND(Planilla!B18="A", VLOOKUP(E18,EX:FJ,13,0)="A"), "OK",IF( AND(Planilla!B18="A", OR(VLOOKUP(E18,EX:FJ,13,0)="B", VLOOKUP(E18,EX:FJ,13,0)="C")), "SOBREOFERTA","" ))))))),"") | H18: =IF(I18="","",IF(AND((I18-G18)>=TIME(0,0,0),(I18-G18)<TIME(0,3,0)),"OK",IF(AND((I18-G18)>=TIME(0,3,0),(I18-G18)<TIME(0,5,0)),"RETRASO DE 3-5 MIN",IF(AND((I18-G18)>=TIME(0,5,0),(I18-G18)<TIME(0,10,0)),"RETRASO DE 5-10 MIN",IF((I18-G18)>=TIME(0,10,0),"RETRASO >10 MIN", IF(AND((G18-I18)>=TIME(0,0,0),(G18-I18)<TIME(0,3,0)),"OK",IF((G18-I18)>=TIME(0,3,0),"ADELANTADO"))))))) | J18: =IF(A18<>"",HLOOKUP(VALUE(TEXT(G18,"h:mm:ss")),IF($C$6="Laboral",$FT$4:$GR$227,IF($C$6="Sábado",$FT$231:$GR$452,$FT$456:$GR$656)),VLOOKUP($C$4,$GZ$2:$HB$99,3,0)+IF(C$5="Ida",0,1),1),"") -> #N/A | K18: =IF(A19<>A18,AVERAGEIF(A$9:A18,A18,J$9:J18),"") | L18: =IFERROR(IF(A19<>A18,AVERAGEIF(A$9:A18,A18,S$9:S18),""),"") | M18: =IFERROR(IF(A19<>A18,AVERAGEIF(A$9:A18,A18,T$9:T18),""),"") | N18: {=IFERROR(IF(A19<>A18,_xlfn.STDEV.P(IF(A$9:A18=A18,T$9:T18)),""),"")} | O18: {=IFERROR(IF(A19<>A18,_xlfn.STDEV.P(IF(A$9:A18=A18,S$9:S18)),""),"")} | P18: =IFERROR(IF(A18<>A19,MAX((((M18*24*60)/2)*(1+POWER((((N18*24*60) / (M18*24*60) )),2))) + ((M18*24*60 )*-0.1 + (K18*0.015)) +1,(((M18*24*60)/2)*(1+POWER((((N18*24*60) / (M18*24*60 ))),2)))),""),"") | Q18: =IF(AND(O18<>"",L18<>""),IF(A18<>A19,((L18*24*60) / 2 ) * (1 + POWER(((O18*24*60) / (L18*24*60)),2)),""),"") | R18: =IF(Q18<>"",MAX(P18,Q18),"") | S18: =IF(I18<>"H. Sale Real",IF(AND(I19<>"",LEFT(C19,2)<>"NC"),IF(AND(I18<>"",LEFT(C18,2)<>"NC",I18<>"H. Sale Real"),IF(I19-I18<0.208333333333333,I19-I18,""),IF(AND(I17<>"",LEFT(C17,2)<>"NC",I17<>"H. Sale Real"),IF(I19-I17<0.208333333333333,I19-I17,""),IF(AND(I16<>"",LEFT(C16,2)<>"NC",I16<>"H. Sale Real"),IF(I19-I16<0.208333333333333,I19-I16,""),IF(AND(I15<>"",LEFT(C15,2)<>"NC",I15<>"H. Sale Real"),IF(I19-I15<0.208333333333333,I19-I15,""),IF(AND(I14<>"",LEFT(C14,2)<>"NC",I14<>"H. Sale Real"),IF(I19-I14<0.208333333333333,I19-I14,""),""))))),""),"") | T18: =IF(G18<>"H. Sale Real",IF(AND(G19<>"",LEFT(C19,2)<>"NC"),IF(AND(G18<>"",LEFT(C18,2)<>"NC",G18<>"H. Sale Real"),IF(G19-G18<0.208333333333333,G19-G18,""),IF(AND(G17<>"",LEFT(C17,2)<>"NC",G17<>"H. Sale Real"),IF(G19-G17<0.208333333333333,G19-G17,""),IF(AND(G16<>"",LEFT(C16,2)<>"NC",G16<>"H. Sale Real"),IF(G19-G16<0.208333333333333,G19-G16,""),IF(AND(G15<>"",LEFT(C15,2)<>"NC",G15<>"H. Sale Real"),IF(G19-G15<0.208333333333333,G19-G15,""),IF(AND(G14<>"",LEFT(C14,2)<>"NC",G14<>"H. Sale Real"),IF(G19-G14<0.208333333333333,G19-G14,""),""))))),""),"") | U18: 0.13472222 | W18: =IF(G18<>"",IF(AND(W17<>"IE",P18<>0,R18<>""),IF(IFERROR((P18/R18),0) <=1,IFERROR(P18/R18,""),1),""),"") | AB18: =HOUR(AH18)+1 -> 1 | AI18: =IF(AJ18="","",IF(AND((AJ18-AH18)>=TIME(0,0,0),(AJ18-AH18)<TIME(0,3,0)),"OK",IF(AND((AJ18-AH18)>=TIME(0,3,0),(AJ18-AH18)<TIME(0,5,0)),"RETRASO DE 3-5 MIN",IF(AND((AJ18-AH18)>=TIME(0,5,0),(AJ18-AH18)<TIME(0,10,0)),"RETRASO DE 5-10 MIN",IF((AJ18-AH18)>=TIME(0,10,0),"RETRASO >10 MIN", IF(AND((AH18-AJ18)>=TIME(0,0,0),(AH18-AJ18)<TIME(0,3,0)),"OK",IF((AH18-AJ18)>=TIME(0,3,0),"ADELANTADO"))))))) | AK18: =IF(AB18<>"",HLOOKUP(VALUE(TEXT(AH18,"h:mm:ss")),IF($C$6="Laboral",$FT$4:$GR$227,IF($C$6="Sábado",$FT$231:$GR$452,$FT$456:$GR$656)),VLOOKUP($C$4,$GZ$2:$HB$99,3,0)+IF(AD$5="Ida",0,1),1),"") -> #N/A | AL18: =IF(AB19<>AB18,AVERAGEIF(AB$9:AB18,AB18,AK$9:AK18),"") | AM18: =IFERROR(IF(AB19<>AB18,AVERAGEIF(AB$9:AB18,AB18,AT$9:AT18),""),"") | AN18: =IFERROR(IF(AB19<>AB18,AVERAGEIF(AB$9:AB18,AB18,AU$9:AU18),""),"") | AO18: {=IFERROR(IF(AB19<>AB18,_xlfn.STDEV.P(IF(AB$9:AB18=AB18,AU$9:AU18)),""),"")} | AP18: {=IFERROR(IF(AB19<>AB18,_xlfn.STDEV.P(IF(AB$9:AB18=AB18,AT$9:AT18)),""),"")} | AQ18: =IFERROR(IF(AB18<>AB19,MAX((((AN18*24*60)/2)*(1+POWER((((AO18*24*60) / (AN18*24*60) )),2))) + ((AN18*24*60 )*-0.1 + (AL18*0.015)) +1,(((AN18*24*60)/2)*(1+POWER((((AO18*24*60) / (AN18*24*60 ))),2)))),""),"") | AR18: =IF(AND(AP18<>"",AM18<>""),IF(AB18<>AB19,((AM18*24*60) / 2 ) * (1 + POWER(((AP18*24*60) / (AM18*24*60)),2)),""),"") | AS18: =IF(AR18<>"",MAX(AQ18,AR18),"") | AT18: =IF(AJ18<>"H. Sale Real",IF(AND(AJ19<>"",LEFT(AD19,2)<>"NC"),IF(AND(AJ18<>"",LEFT(AD18,2)<>"NC",AJ18<>"H. Sale Real"),IF(AJ19-AJ18<0.208333333333333,AJ19-AJ18,""),IF(AND(AJ17<>"",LEFT(AD17,2)<>"NC",AJ17<>"H. Sale Real"),IF(AJ19-AJ17<0.208333333333333,AJ19-AJ17,""),IF(AND(AJ16<>"",LEFT(AD16,2)<>"NC",AJ16<>"H. Sale Real"),IF(AJ19-AJ16<0.208333333333333,AJ19-AJ16,""),IF(AND(AJ15<>"",LEFT(AD15,2)<>"NC",AJ15<>"H. Sale Real"),IF(AJ19-AJ15<0.208333333333333,AJ19-AJ15,""),IF(AND(AJ14<>"",LEFT(AD14,2)<>"NC",AJ14<>"H. Sale Real"),IF(AJ19-AJ14<0.208333333333333,AJ19-AJ14,""),""))))),""),"") | AU18: =IF(AH18<>"H. Sale Real",IF(AND(AH19<>"",LEFT(AD19,2)<>"NC"),IF(AND(AH18<>"",LEFT(AD18,2)<>"NC",AH18<>"H. Sale Real"),IF(AH19-AH18<0.208333333333333,AH19-AH18,""),IF(AND(AH17<>"",LEFT(AD17,2)<>"NC",AH17<>"H. Sale Real"),IF(AH19-AH17<0.208333333333333,AH19-AH17,""),IF(AND(AH16<>"",LEFT(AD16,2)<>"NC",AH16<>"H. Sale Real"),IF(AH19-AH16<0.208333333333333,AH19-AH16,""),IF(AND(AH15<>"",LEFT(AD15,2)<>"NC",AH15<>"H. Sale Real"),IF(AH19-AH15<0.208333333333333,AH19-AH15,""),IF(AND(AH14<>"",LEFT(AD14,2)<>"NC",AH14<>"H. Sale Real"),IF(AH19-AH14<0.208333333333333,AH19-AH14,""),""))))),""),"") | AX18: =IF(AH18<>"",IF(AND(AX17<>"IE",AQ18<>0,AS18<>""),IF(IFERROR((AQ18/AS18),0) <=1,IFERROR(AQ18/AS18,""),1),""),"") | BC18: 6 | BD18: =COUNTIFS($A:$A,$BC18,$C:$C,$BC$11) -> 0 | BE18: =BD18-COUNTIFS($A:$A,$BC18,$C:$C,$BC$11,$H:$H,"") -> 0 | BF18: =IFERROR((BE18/BD18),"") | BG18: =_xlfn.XLOOKUP(BC18,$A:$A,$R:$R,"0",0,-1) -> 0 | BH18: =_xlfn.XLOOKUP(BC18,$A:$A,$P:$P,"0",0,-1) -> 0 | BI18: =_xlfn.XLOOKUP(BC18,$A:$A,$W:$W,"",0,-1) | BL18: 6 | BM18: =COUNTIFS($AB:$AB,$BL18,$AD:$AD,$BL$11) -> 0 | BN18: =BM18-COUNTIFS($AB:$AB,$BL18,$AD:$AD,$BL$11,$AI:$AI,"") -> 0 | BO18: =IFERROR((BN18/BM18),"") | BP18: =_xlfn.XLOOKUP(BL18,$AB:$AB,$AS:$AS,"0",0,-1) -> 0 | BQ18: =_xlfn.XLOOKUP(BL18,$AB:$AB,$AQ:$AQ,"0",0,-1) -> 0 | BR18: =_xlfn.XLOOKUP(BL18,$AB:$AB,$AX:$AX,"",0,-1) | EW18: Diccionario 1 | EX18: 1015 | EY18: D8482400K2PL | EZ18: YV3T7U527KA195328 | FA18: Volvo | FB18: B8R | FC18: MARCOPOLO | FD18: TORINO | FE18: 2019 | FF18: B2PAL | FG18: LOS LIBERTADORES | FH18: Los Liberadores 6450, Lote 4A | FI18: Huechuraba | FJ18: B | FM18: 3005 / SFWZ-39| | FN18: SFWZ-39| | FO18: SFWZ-39 | FP18: =VLOOKUP(FO18,EX:FF,9,0) -> B | FT18: 120 | FU18: 28.4 | FV18: 0 | FW18: 0 | FX18: 0 | FY18: 0 | FZ18: 9.81 | GA18: 16.66 | GB18: 14.92 | GC18: 16.59 | GD18: 17.285 | GE18: 17.34 | GF18: 17.32 | GG18: 16.87 | GH18: 16.99 | GI18: 16.855 | GJ18: 16.6 | GK18: 16.175 | GL18: 14.875 | GM18: 15.675 | GN18: 17.97 | GO18: 19.545 | GP18: 20.605 | GQ18: 23.055 | GR18: 25.725 | GU18: 15 | GV18: 12 | GY18: U9 | GZ18: B26 | HA18: B26 | HB18: 29 | HF18: AlfaU9 | HG18: B26 | HH18: Santa Marta | HI18: 826
