Workbook

Sheet Planilla
FC1: Diccio | FD1: N° Interno | FE1: N° Chasis | FF1: N Motor | FG1: Marca chasis | FH1: Modelo Chasis | FI1: Marca Carrocería | FJ1: Modelo Carrocería | FK1: Año | FL1: Tipo de Bus | FM1: Nombre Terminal Asignado | FN1: Dirección Terminal | FO1: Comuna | FP1: Tipo de bus | FS1: 3003 / SFWZ-16| | FT1: SFWZ-16| | FU1: SFWZ-16 | FV1: =VLOOKUP(FU1,FD:FL,9,0) | GA1: SI(A13<>"";BUSCARH(VALOR(TEXTO(G13;"h:mm:ss"));SI($C$6="Laboral";$FT$4:$GR$227;SI($C$6="Sábado";$FT$231:$GR$452;$FT$456:$GR$656));BUSCARV($C$4;Input!$GZ$2:$HB$99;3;0)+SI(C$5="Ida";0;1);1);"") | HA1: 84 | HB1: 85 | HC1: 86 | HE1: ZTS | HF1: SERVICIO TS | HG1: SERVICIO UN | HH1: POS | HL1: unidad | HM1: servicio | HN1: Terminal | HO1: CODIGO TS SERVICIO
FC2: Diccionario 1 | FE2: De Baja | FF2: De Baja | FG2: De Baja | FH2: De Baja | FI2: De Baja | FJ2: De Baja | FK2: De Baja | FL2: De Baja | FM2: De Baja | FN2: De Baja | FO2: De Baja | FS2: 3003 / SFWZ-16| | FT2: SFWZ-16| | FU2: SFWZ-16 | FV2: =VLOOKUP(FU2,FD:FL,9,0) | FZ2: INTERVALO PROGRAMADO | HE2: U9 | HF2: B01 | HG2: B01 | HH2: 3 | HL2: AlfaU9 | HM2: B01 | HN2: Condell | HO2: 801
B3: Terminal | E3: Diccionario | W3: =IFERROR(SUMPRODUCT(--ISNUMBER($W$13:$W$547),--ISNUMBER($X$13:$X$547),--(MOD($X$13:$X$547-$W$13:$W$547+0.5,1)-0.5>=-1/1440),--(MOD($X$13:$X$547-$W$13:$W$547+0.5,1)-0.5<=4/1440))/SUMPRODUCT(--ISNUMBER($W$13:$W$547),--ISNUMBER($X$13:$X$547)),0) | X3: % OK | AF3: Terminal | AI3: Diccionario | BA3: =IFERROR(SUMPRODUCT(--ISNUMBER($BA$13:$BA$547),--ISNUMBER($BB$13:$BB$547),--(MOD($BB$13:$BB$547-$BA$13:$BA$547+0.5,1)-0.5>=-1/1440),--(MOD($BB$13:$BB$547-$BA$13:$BA$547+0.5,1)-0.5<=4/1440))/SUMPRODUCT(--ISNUMBER($BA$13:$BA$547),--ISNUMBER($BB$13:$BB$547)),0) | BB3: % OK | FC3: Diccionario 1 | FD3: 1000 | FE3: D8478292K2PL | FF3: YV3T7U524KA195142 | FG3: Volvo | FH3: B8R | FI3: MARCOPOLO | FJ3: TORINO | FK3: 2019 | FL3: B2PAL | FM3: LOS LIBERTADORES | FN3: Los Liberadores 6450, Lote 4A | FO3: Huechuraba | FP3: B | FS3: 3003 / SFWZ-16| | FT3: SFWZ-16| | FU3: SFWZ-16 | FV3: =VLOOKUP(FU3,FD:FL,9,0) | FZ3: LABORAL | GA3: P1 | GB3: P2 | GC3: P3 | GD3: P4 | GE3: P5 | GF3: P6 | GG3: P7 | GH3: P8 | GI3: P9 | GJ3: P10 | GK3: P11 | GL3: P12 | GM3: P13 | GN3: P14 | GO3: P15 | GP3: P16 | GQ3: P17 | GR3: P18 | GS3: P19 | GT3: P20 | GU3: P21 | GV3: P22 | GW3: P23 | GX3: P24 | HE3: U9 | HF3: B03 | HG3: B03 | HH3: 4 | HL3: AlfaU9 | HM3: B03 | HN3: El Retiro | HO3: 803
B4: Servicio | G4: Vacío a Cabezal | W4: =IFERROR(SUMPRODUCT(--ISNUMBER($W$13:$W$547),--ISNUMBER($X$13:$X$547),--(MOD($X$13:$X$547-$W$13:$W$547+0.5,1)-0.5<-1/1440))/SUMPRODUCT(--ISNUMBER($W$13:$W$547),--ISNUMBER($X$13:$X$547)),0) | X4: % ADELANTADO | AF4: Servicio | AK4: Vacío a Cabezal | BA4: =IFERROR(SUMPRODUCT(--ISNUMBER($BA$13:$BA$547),--ISNUMBER($BB$13:$BB$547),--(MOD($BB$13:$BB$547-$BA$13:$BA$547+0.5,1)-0.5<-1/1440))/SUMPRODUCT(--ISNUMBER($BA$13:$BA$547),--ISNUMBER($BB$13:$BB$547)),0) | BB4: % ADELANTADO | FC4: Diccionario 1 | FD4: 1096 | FE4: D8482685K2PL | FF4: YV3T7U521KA195230 | FG4: Volvo | FH4: B8R | FI4: MARCOPOLO | FJ4: TORINO | FK4: 2019 | FL4: B2PAL | FM4: LOS LIBERTADORES | FN4: Los Liberadores 6450, Lote 4A | FO4: Huechuraba | FP4: B | FS4: 3003 / SFWZ-16| | FT4: SFWZ-16| | FU4: SFWZ-16 | FV4: =VLOOKUP(FU4,FD:FL,9,0) | FZ4: MH | GA4: 0 | GB4: 0.041666667 | GC4: 0.083333333 | GD4: 0.125 | GE4: 0.16666667 | GF4: 0.20833333 | GG4: 0.25 | GH4: 0.29166667 | GI4: 0.33333333 | GJ4: 0.375 | GK4: 0.41666667 | GL4: 0.45833333 | GM4: 0.5 | GN4: 0.54166667 | GO4: 0.58333333 | GP4: 0.625 | GQ4: 0.66666667 | GR4: 0.70833333 | GS4: 0.75 | GT4: 0.79166667 | GU4: 0.83333333 | GV4: 0.875 | GW4: 0.91666667 | GX4: 0.95833333 | HA4: 1 | HE4: U9 | HF4: 105 | HG4: 105 | HH4: 5 | HL4: AlfaU9 | HM4: 105 | HN4: El Retiro | HO4: 805
B5: Sentido | C5: IDA | G5: Vacío a Patio | W5: =IFERROR(SUMPRODUCT(--ISNUMBER($W$13:$W$547),--ISNUMBER($X$13:$X$547),--(MOD($X$13:$X$547-$W$13:$W$547+0.5,1)-0.5>4/1440))/SUMPRODUCT(--ISNUMBER($W$13:$W$547),--ISNUMBER($X$13:$X$547)),0) | X5: % ATRASADO | AF5: Sentido | AG5: REG | AK5: Vacío a Patio | BA5: =IFERROR(SUMPRODUCT(--ISNUMBER($BA$13:$BA$547),--ISNUMBER($BB$13:$BB$547),--(MOD($BB$13:$BB$547-$BA$13:$BA$547+0.5,1)-0.5>4/1440))/SUMPRODUCT(--ISNUMBER($BA$13:$BA$547),--ISNUMBER($BB$13:$BB$547)),0) | BB5: % ATRASADO | FC5: Diccionario 1 | FD5: 1002 | FE5: D8483833K2PL | FF5: YV3T7U520KA195641 | FG5: Volvo | FH5: B8R | FI5: MARCOPOLO | FJ5: TORINO | FK5: 2019 | FL5: B2PAL | FM5: LOS LIBERTADORES | FN5: Los Liberadores 6450, Lote 4A | FO5: Huechuraba | FP5: B | FS5: 3003 / SFWZ-16| | FT5: SFWZ-16| | FU5: SFWZ-16 | FV5: =VLOOKUP(FU5,FD:FL,9,0) | FZ5: LP | GA5: 1 | GB5: 1 | GC5: 1 | GD5: 1 | GE5: 1 | GF5: 1 | GG5: 1 | GH5: 1 | GI5: 1 | GJ5: 1 | GK5: 1 | GL5: 1 | GM5: 1 | GN5: 1 | GO5: 1 | GP5: 1 | GQ5: 1 | GR5: 1 | GS5: 1 | GT5: 1 | GU5: 1 | GV5: 1 | GW5: 1 | GX5: 1 | HA5: 2 | HE5: U9 | HF5: B07 | HG5: B07 | HH5: 8 | HL5: AlfaU9 | HM5: B07 | HN5: Santa Marta | HO5: 807
B6: tipo de día | W6: =SUM(W3:W5) | X6: % TOTAL | AF6: tipo de día | BA6: =SUM(BA3:BA5) | BB6: % TOTAL | FC6: Diccionario 1 | FD6: 1003 | FE6: D8483530K2PL | FF6: YV3T7U522KA195642 | FG6: Volvo | FH6: B8R | FI6: MARCOPOLO | FJ6: TORINO | FK6: 2019 | FL6: B2PAL | FM6: LOS LIBERTADORES | FN6: Los Liberadores 6450, Lote 4A | FO6: Huechuraba | FP6: B | FS6: 3004 / SFWZ-31| | FT6: SFWZ-31| | FU6: SFWZ-31 | FV6: =VLOOKUP(FU6,FD:FL,9,0) | FZ6: B01 | GA6: 28.92 | GB6: 0 | GC6: 0 | GD6: 0 | GE6: 0 | GF6: 8.85 | GG6: 15.76 | GH6: 13.79 | GI6: 14.87 | GJ6: 16.63 | GK6: 16.95 | GL6: 16.38 | GM6: 15.68 | GN6: 15.93 | GO6: 16.02 | GP6: 15.485 | GQ6: 14.685 | GR6: 13.585 | GS6: 14.31 | GT6: 16.51 | GU6: 18.045 | GV6: 19.45 | GW6: 22.085 | GX6: 24.735 | HA6: 3 | HE6: U9 | HF6: B08 | HG6: B08 | HH6: 10 | HL6: AlfaU9 | HM6: B08 | HN6: Santa Marta | HO6: 808
FC7: Diccionario 1 | FD7: 1004 | FE7: D8483789K2PL | FF7: YV3T7U524KA195643 | FG7: Volvo | FH7: B8R | FI7: MARCOPOLO | FJ7: TORINO | FK7: 2019 | FL7: B2PAL | FM7: SAN JOSE | FN7: San José 030 (José Besa 669) | FO7: San Bernardo | FP7: B | FS7: 3004 / SFWZ-31| | FT7: SFWZ-31| | FU7: SFWZ-31 | FV7: =VLOOKUP(FU7,FD:FL,9,0) | FZ7: B03 | GA7: 0 | GB7: 0 | GC7: 0 | GD7: 0 | GE7: 0 | GF7: 17.585 | GG7: 14.575 | GH7: 14.64 | GI7: 15.78 | GJ7: 16.4 | GK7: 16.01 | GL7: 15.555 | GM7: 15.34 | GN7: 15.045 | GO7: 14.625 | GP7: 14.175 | GQ7: 13.545 | GR7: 13.395 | GS7: 15.2 | GT7: 16.955 | GU7: 18.275 | GV7: 19.905 | GW7: 21.615 | GX7: 0 | HA7: 4 | HB7: 1 | HE7: U9 | HF7: B09 | HG7: B09 | HH7: 12 | HL7: AlfaU9 | HM7: B09 | HN7: El Retiro | HO7: 809
FC8: Diccionario 1 | FD8: 1005 | FE8: D8484480K2PL | FF8: YV3T7U524KA195688 | FG8: Volvo | FH8: B8R | FI8: MARCOPOLO | FJ8: TORINO | FK8: 2019 | FL8: B2PAL | FM8: SAN JOSE | FN8: San José 030 (José Besa 669) | FO8: San Bernardo | FP8: B | FS8: 3004 / SFWZ-31| | FT8: SFWZ-31| | FU8: SFWZ-31 | FV8: =VLOOKUP(FU8,FD:FL,9,0) | FZ8: 105 | GA8: 0 | GB8: 0 | GC8: 0 | GD8: 0 | GE8: 0 | GF8: 18.435 | GG8: 15.275 | GH8: 14.62 | GI8: 16.635 | GJ8: 17.05 | GK8: 16.82 | GL8: 16.61 | GM8: 16.31 | GN8: 16.055 | GO8: 15.29 | GP8: 14.71 | GQ8: 13.055 | GR8: 12.495 | GS8: 14.34 | GT8: 16.7 | GU8: 18.44 | GV8: 19.865 | GW8: 21.83 | GX8: 23.995 | HA8: 5 | HB8: 2 | HE8: U9 | HF8: B10 | HG8: B10 | HH8: 13 | HL8: AlfaU9 | HM8: B10 | HN8: Santa Marta | HO8: 810
FC9: Diccionario 1 | FD9: 1006 | FE9: D8484637K2PL | FF9: YV3T7U528KA195712 | FG9: Volvo | FH9: B8R | FI9: MARCOPOLO | FJ9: TORINO | FK9: 2019 | FL9: B2PAL | FM9: SAN JOSE | FN9: San José 030 (José Besa 669) | FO9: San Bernardo | FP9: B | FS9: 3004 / SFWZ-31| | FT9: SFWZ-31| | FU9: SFWZ-31 | FV9: =VLOOKUP(FU9,FD:FL,9,0) | FZ9: 105 | GA9: 0 | GB9: 0 | GC9: 0 | GD9: 0 | GE9: 0 | GF9: 19.51 | GG9: 15.235 | GH9: 14.655 | GI9: 16.62 | GJ9: 17.48 | GK9: 17.01 | GL9: 16.145 | GM9: 15.605 | GN9: 16.08 | GO9: 15.86 | GP9: 15.355 | GQ9: 14.66 | GR9: 13.605 | GS9: 14.395 | GT9: 17.055 | GU9: 18.48 | GV9: 19.235 | GW9: 20.845 | GX9: 22.865 | HA9: 6 | HB9: 3 | HE9: U9 | HF9: 120 | HG9: 120 | HH9: 14 | HL9: AlfaU9 | HM9: 120 | HN9: Condell | HO9: 812
FC10: Diccionario 1 | FD10: 1007 | FE10: D8484676K2PL | FF10: YV3T7U52XKA195713 | FG10: Volvo | FH10: B8R | FI10: MARCOPOLO | FJ10: TORINO | FK10: 2019 | FL10: B2PAL | FM10: LOS LIBERTADORES | FN10: Los Liberadores 6450, Lote 4A | FO10: Huechuraba | FP10: B | FS10: 3004 / SFWZ-31| | FT10: SFWZ-31| | FU10: SFWZ-31 | FV10: =VLOOKUP(FU10,FD:FL,9,0) | FZ10: 105c | GA10: 0 | GB10: 0 | GC10: 0 | GD10: 0 | GE10: 0 | GF10: 10.78 | GG10: 19.005 | GH10: 16.43 | GI10: 18.565 | GJ10: 9.805 | GK10: 0 | GL10: 0 | GM10: 0 | GN10: 0 | GO10: 0 | GP10: 0 | GQ10: 8.115 | GR10: 14.65 | GS10: 15.24 | GT10: 18.095 | GU10: 19.5 | GV10: 0 | GW10: 0 | GX10: 0 | HA10: 7 | HB10: 4 | HE10: U9 | HF10: B13 | HG10: B13 | HH10: 16 | HL10: AlfaU9 | HM10: B13 | HN10: Santa Marta | HO10: 813
BI11: =C4&" "&C5 | BR11: =AG4&" "&MID(AG5,1,3) | FC11: Diccionario 1 | FD11: 1008 | FE11: D8484733K2PL | FF11: YV3T7U526KA195742 | FG11: Volvo | FH11: B8R | FI11: MARCOPOLO | FJ11: TORINO | FK11: 2019 | FL11: B2PAL | FM11: LOS LIBERTADORES | FN11: Los Liberadores 6450, Lote 4A | FO11: Huechuraba | FP11: B | FS11: 3004 / SFWZ-31| | FT11: SFWZ-31| | FU11: SFWZ-31 | FV11: =VLOOKUP(FU11,FD:FL,9,0) | FZ11: B07 | GA11: 0 | GB11: 0 | GC11: 0 | GD11: 0 | GE11: 0 | GF11: 12.58 | GG11: 20.03 | GH11: 17.86 | GI11: 21.28 | GJ11: 23.915 | GK11: 24.295 | GL11: 24.33 | GM11: 24.31 | GN11: 24.125 | GO11: 24.315 | GP11: 23.335 | GQ11: 19.745 | GR11: 15.08 | GS11: 17.465 | GT11: 23.745 | GU11: 27.27 | GV11: 29.185 | GW11: 28.615 | GX11: 0 | HA11: 8 | HB11: 5 | HE11: U9 | HF11: B16 | HG11: B16 | HH11: 17 | HL11: AlfaU9 | HM11: B16 | HN11: Santa Marta | HO11: 816
A12: Periodo | B12: TB Programado | C12: Tipo de Salida | D12: Cumple TB | E12: Bus | F12: Media Hora despacho | G12: ="H Sale Terminal"&""&C3 | H12: Cumple despacho | I12: H. Sale Real | J12: KM PERIODO | K12: KM PROMEDIO | L12: IR_REAL_PROM | M12: IR_PROG_PROM | N12: IR_PROG_DESVEST | O12: IR_REAL_DESVEST | P12: TE_IDEAL | Q12: TE_OBS | R12: TE_OBS_NET | S12: IR_REAL | T12: IR_PROG | U12: ="H llegada Terminal"&""&AG3 | V12: Corta Palo | W12: PUNTO DE CONTROL | X12: SALIDA REAL PUNTO DE CONTROL | Y12: Hora de Llegada Real | Z12: IE | AA12: Causa Perdidas | AB12: observación | AE12: Periodo | AF12: TB Programado | AG12: Tipo de Salida | AH12: Cumple TB | AI12: Bus | AJ12: Media Hora despcaho | AK12: ="H Sale Terminal"&""&AG3 | AL12: Cumple despacho | AM12: H. Sale Real | AN12: KM PERIODO | AO12: KM PROMEDIO | AP12: IR_REAL_PROM | AQ12: IR_PROG_PROM | AR12: IR_PROG_DESVEST | AS12: IR_PROG_DESVEST | AT12: TE_IDEAL | AU12: TE_OBS | AV12: TE_OBS_NET | AW12: IR_REAL | AX12: IR_PROG | AY12: ="H llegada Terminal"&""&C3 | AZ12: Corta Palo | BA12: PUNTO DE CONTROL | BB12: SALIDA REAL PUNTO DE CONTROL | BC12: Hora de Legada Real | BD12: IE | BE12: Causa Perdidas | BF12: observación | BI12: Periodo | BJ12: Teórico | BK12: Real | BL12: ICF-P | BM12: TE Obs | BN12: TE Ideal | BO12: IE | BR12: Periodo | BS12: Teórico | BT12: Real | BU12: ICF-P | BV12: TE Obs | BW12: TE Ideal | BX12: IE | FC12: Diccionario 1 | FD12: 1009 | FE12: D8481621K2PL | FF12: YV3T7U528KA195175 | FG12: Volvo | FH12: B8R | FI12: MARCOPOLO | FJ12: TORINO | FK12: 2019 | FL12: B2PAL | FM12: LOS LIBERTADORES | FN12: Los Liberadores 6450, Lote 4A | FO12: Huechuraba | FP12: B | FS12: 3004 / SFWZ-31| | FT12: SFWZ-31| | FU12: SFWZ-31 | FV12: =VLOOKUP(FU12,FD:FL,9,0) | FZ12: B07y | GA12: 0 | GB12: 0 | GC12: 0 | GD12: 0 | GE12: 0 | GF12: 0 | GG12: 11.345 | GH12: 10.845 | GI12: 0 | GJ12: 0 | GK12: 0 | GL12: 0 | GM12: 0 | GN12: 0 | GO12: 0 | GP12: 0 | GQ12: 0 | GR12: 0 | GS12: 0 | GT12: 0 | GU12: 0 | GV12: 0 | GW12: 0 | GX12: 0 | HA12: 9 | HB12: 6 | HE12: U9 | HF12: B17 | HG12: B17 | HH12: 19 | HL12: AlfaU9 | HM12: B17 | HN12: Condell | HO12: 817
A13: =HOUR(G13)+1 | D13: =IFERROR( IF(AND(OR(Planilla!B13="C",Planilla!B13="c"), VLOOKUP(E13,FD:FP,13,0)="C"), "OK",IF(AND(OR(Planilla!B13="C",Planilla!B13="c"), OR(VLOOKUP(E13,FD:FP,13,0)="B", VLOOKUP(E13,FD:FP,13,0)="A")), "DEFICIT",IF( AND(OR(Planilla!B13="B", Planilla!B13="BPAL"), VLOOKUP(E13,FD:FP,13,0)="B"), "OK",IF(AND(OR(Planilla!B13="B", Planilla!B13="BPAL"), VLOOKUP(E13,FD:FP,13,0)="A"), "DEFICIT",IF(AND(OR(Planilla!B13="B", Planilla!B13="BPAL"), VLOOKUP(E13,FD:FP,13,0)="C"), "SOBREOFERTA",IF(AND(Planilla!B13="A", VLOOKUP(E13,FD:FP,13,0)="A"), "OK",IF( AND(Planilla!B13="A", OR(VLOOKUP(E13,FD:FP,13,0)="B", VLOOKUP(E13,FD:FP,13,0)="C")), "SOBREOFERTA","" ))))))),"") | H13: =IF(I13="","",IF(AND((I13-G13)>=TIME(0,0,0),(I13-G13)<TIME(0,3,0)),"OK",IF(AND((I13-G13)>=TIME(0,3,0),(I13-G13)<TIME(0,5,0)),"RETRASO DE 3-5 MIN",IF(AND((I13-G13)>=TIME(0,5,0),(I13-G13)<TIME(0,10,0)),"RETRASO DE 5-10 MIN",IF((I13-G13)>=TIME(0,10,0),"RETRASO >10 MIN", IF(AND((G13-I13)>=TIME(0,0,0),(G13-I13)<TIME(0,3,0)),"OK",IF((G13-I13)>=TIME(0,3,0),"ADELANTADO"))))))) | J13: =IF(A13<>"",HLOOKUP(VALUE(TEXT(G13,"h:mm:ss")),IF($C$6="Laboral",$FZ$4:$GX$227,IF($C$6="Sábado",$FZ$231:$GX$452,$FZ$456:$GX$656)),VLOOKUP($C$4,$HF$2:$HH$99,3,0)+IF(C$5="Ida",0,1),1),"") | K13: =IF(A14<>A13,AVERAGEIF(A$9:A13,A13,J$9:J13),"") | L13: =IFERROR(IF(A14<>A13,AVERAGEIF(A$9:A13,A13,S$9:S13),""),"") | M13: =IFERROR(IF(A14<>A13,AVERAGEIF(A$9:A13,A13,T$9:T13),""),"") | N13: {=IFERROR(IF(A14<>A13,_xlfn.STDEV.P(IF(A$9:A13=A13,T$9:T13)),""),"")} | O13: {=IFERROR(IF(A14<>A13,_xlfn.STDEV.P(IF(A$9:A13=A13,S$9:S13)),""),"")} | P13: =IFERROR(IF(A13<>A14,MAX((((M13*24*60)/2)*(1+POWER((((N13*24*60) / (M13*24*60) )),2))) + ((M13*24*60 )*-0.1 + (K13*0.015)) +1,(((M13*24*60)/2)*(1+POWER((((N13*24*60) / (M13*24*60 ))),2)))),""),"") | Q13: =IF(AND(O13<>"",L13<>""),IF(A13<>A14,((L13*24*60) / 2 ) * (1 + POWER(((O13*24*60) / (L13*24*60)),2)),""),"") | R13: =IF(Q13<>"",MAX(P13,Q13),"") | S13: =IF(I13<>"H. Sale Real",IF(AND(I14<>"",LEFT(C14,2)<>"Va"),IF(AND(I13<>"",LEFT(C13,2)<>"Va",I13<>"H. Sale Real"),IF(I14-I13<0.208333333333333,I14-I13,""),IF(AND(I12<>"",LEFT(C12,2)<>"Va",I12<>"H. Sale Real"),IF(I14-I12<0.208333333333333,I14-I12,""),IF(AND(I11<>"",LEFT(C11,2)<>"Va",I11<>"H. Sale Real"),IF(I14-I11<0.208333333333333,I14-I11,""),IF(AND(I10<>"",LEFT(C10,2)<>"Va",I10<>"H. Sale Real"),IF(I14-I10<0.208333333333333,I14-I10,""),IF(AND(I9<>"",LEFT(C9,2)<>"Va",I9<>"H. Sale Real"),IF(I14-I9<0.208333333333333,I14-I9,""),""))))),""),"") | T13: =IF(G13<>"H. Sale Real",IF(AND(G14<>"",LEFT(C14,2)<>"Va"),IF(AND(G13<>"",LEFT(C13,2)<>"Va",G13<>"H. Sale Real"),IF(G14-G13<0.208333333333333,G14-G13,""),IF(AND(G12<>"",LEFT(C12,2)<>"Va",G12<>"H. Sale Real"),IF(G14-G12<0.208333333333333,G14-G12,""),IF(AND(G11<>"",LEFT(C11,2)<>"Va",G11<>"H. Sale Real"),IF(G14-G11<0.208333333333333,G14-G11,""),IF(AND(G10<>"",LEFT(C10,2)<>"Va",G10<>"H. Sale Real"),IF(G14-G10<0.208333333333333,G14-G10,""),IF(AND(G9<>"",LEFT(C9,2)<>"Va",G9<>"H. Sale Real"),IF(G14-G9<0.208333333333333,G14-G9,""),""))))),""),"") | Z13: =IF(G13<>"",IF(AND(Z12<>"IE",P13<>0,R13<>""),IF(IFERROR((P13/R13),0) <=1,IFERROR(P13/R13,""),1),""),"") | AE13: =HOUR(AK13)+1 | AL13: =IF(AM13="","",IF(AND((AM13-AK13)>=TIME(0,0,0),(AM13-AK13)<TIME(0,3,0)),"OK",IF(AND((AM13-AK13)>=TIME(0,3,0),(AM13-AK13)<TIME(0,5,0)),"RETRASO DE 3-5 MIN",IF(AND((AM13-AK13)>=TIME(0,5,0),(AM13-AK13)<TIME(0,10,0)),"RETRASO DE 5-10 MIN",IF((AM13-AK13)>=TIME(0,10,0),"RETRASO >10 MIN", IF(AND((AK13-AM13)>=TIME(0,0,0),(AK13-AM13)<TIME(0,3,0)),"OK",IF((AK13-AM13)>=TIME(0,3,0),"ADELANTADO"))))))) | AN13: =IF(AE13<>"",HLOOKUP(VALUE(TEXT(AK13,"h:mm:ss")),IF($C$6="Laboral",$FZ$4:$GX$227,IF($C$6="Sábado",$FZ$231:$GX$452,$FZ$456:$GX$656)),VLOOKUP($C$4,$HF$2:$HH$99,3,0)+IF(AG$5="Ida",0,1),1),"") | AO13: =IF(AE14<>AE13,AVERAGEIF(AE$9:AE13,AE13,AN$9:AN13),"") | AP13: =IFERROR(IF(AE14<>AE13,AVERAGEIF(AE$9:AE13,AE13,AW$9:AW13),""),"") | AQ13: =IFERROR(IF(AE14<>AE13,AVERAGEIF(AE$9:AE13,AE13,AX$9:AX13),""),"") | AR13: {=IFERROR(IF(AE14<>AE13,_xlfn.STDEV.P(IF(AE$9:AE13=AE13,AX$9:AX13)),""),"")} | AS13: {=IFERROR(IF(AE14<>AE13,_xlfn.STDEV.P(IF(AE$9:AE13=AE13,AW$9:AW13)),""),"")} | AT13: =IFERROR(IF(AE13<>AE14,MAX((((AQ13*24*60)/2)*(1+POWER((((AR13*24*60) / (AQ13*24*60) )),2))) + ((AQ13*24*60 )*-0.1 + (AO13*0.015)) +1,(((AQ13*24*60)/2)*(1+POWER((((AR13*24*60) / (AQ13*24*60 ))),2)))),""),"") | AU13: =IF(AND(AS13<>"",AP13<>""),IF(AE13<>AE14,((AP13*24*60) / 2 ) * (1 + POWER(((AS13*24*60) / (AP13*24*60)),2)),""),"") | AV13: =IF(AU13<>"",MAX(AT13,AU13),"") | AW13: =IF(AM13<>"H. Sale Real",IF(AND(AM14<>"",LEFT(AG14,2)<>"Va"),IF(AND(AM13<>"",LEFT(AG13,2)<>"Va",AM13<>"H. Sale Real"),IF(AM14-AM13<0.208333333333333,AM14-AM13,""),IF(AND(AM12<>"",LEFT(AG12,2)<>"Va",AM12<>"H. Sale Real"),IF(AM14-AM12<0.208333333333333,AM14-AM12,""),IF(AND(AM11<>"",LEFT(AG11,2)<>"Va",AM11<>"H. Sale Real"),IF(AM14-AM11<0.208333333333333,AM14-AM11,""),IF(AND(AM10<>"",LEFT(AG10,2)<>"Va",AM10<>"H. Sale Real"),IF(AM14-AM10<0.208333333333333,AM14-AM10,""),IF(AND(AM9<>"",LEFT(AG9,2)<>"Va",AM9<>"H. Sale Real"),IF(AM14-AM9<0.208333333333333,AM14-AM9,""),""))))),""),"") | AX13: =IF(AK13<>"H. Sale Real",IF(AND(AK14<>"",LEFT(AG14,2)<>"Va"),IF(AND(AK13<>"",LEFT(AG13,2)<>"Va",AK13<>"H. Sale Real"),IF(AK14-AK13<0.208333333333333,AK14-AK13,""),IF(AND(AK12<>"",LEFT(AG12,2)<>"Va",AK12<>"H. Sale Real"),IF(AK14-AK12<0.208333333333333,AK14-AK12,""),IF(AND(AK11<>"",LEFT(AG11,2)<>"NC",AK11<>"H. Sale Real"),IF(AK14-AK11<0.208333333333333,AK14-AK11,""),IF(AND(AK10<>"",LEFT(AG10,2)<>"Va",AK10<>"H. Sale Real"),IF(AK14-AK10<0.208333333333333,AK14-AK10,""),IF(AND(AK9<>"",LEFT(AG9,2)<>"Va",AK9<>"H. Sale Real"),IF(AK14-AK9<0.208333333333333,AK14-AK9,""),""))))),""),"") | BD13: =IF(AK13<>"",IF(AND(BD12<>"IE",AT13<>0,AV13<>""),IF(IFERROR((AT13/AV13),0) <=1,IFERROR(AT13/AV13,""),1),""),"") | BI13: 1 | BJ13: =COUNTIFS($A:$A,$BI13,$C:$C,$BI$11) | BK13: =BJ13-COUNTIFS($A:$A,$BI13,$C:$C,$BI$11,$H:$H,"") | BL13: =IFERROR((BK13/BJ13),"") | BM13: =_xlfn.XLOOKUP(BI13,$A:$A,$R:$R,"0",0,-1) | BN13: =_xlfn.XLOOKUP(BI13,$A:$A,$P:$P,"0",0,-1) | BO13: =_xlfn.XLOOKUP(BI13,$A:$A,$Z:$Z,"",0,-1) | BR13: 1 | BS13: =COUNTIFS($AE:$AE,$BR13,$AG:$AG,$BR$11) | BT13: =BS13-COUNTIFS($AE:$AE,$BR13,$AG:$AG,$BR$11,$AL:$AL,"") | BU13: =IFERROR((BT13/BS13),"") | BV13: =_xlfn.XLOOKUP(BR13,$AE:$AE,$AV:$AV,"0",0,-1) | BW13: =_xlfn.XLOOKUP(BR13,$AE:$AE,$AT:$AT,"0",0,-1) | BX13: =_xlfn.XLOOKUP(BR13,$AE:$AE,$BD:$BD,"",0,-1) | FC13: Diccionario 1 | FD13: 1010 | FE13: D8482769K2PL | FF13: YV3T7U522KA195303 | FG13: Volvo | FH13: B8R | FI13: MARCOPOLO | FJ13: TORINO | FK13: 2019 | FL13: B2PAL | FM13: LOS LIBERTADORES | FN13: Los Liberadores 6450, Lote 4A | FO13: Huechuraba | FP13: B | FS13: 3004 / SFWZ-31| | FT13: SFWZ-31| | FU13: SFWZ-31 | FV13: =VLOOKUP(FU13,FD:FL,9,0) | FZ13: B08 | GA13: 14.46 | GB13: 0 | GC13: 0 | GD13: 0 | GE13: 0 | GF13: 9.73 | GG13: 14.47 | GH13: 12.28 | GI13: 14.715 | GJ13: 16.955 | GK13: 17.62 | GL13: 17.205 | GM13: 16.905 | GN13: 16.73 | GO13: 17.195 | GP13: 16.89 | GQ13: 15.54 | GR13: 12.46 | GS13: 13.01 | GT13: 17.045 | GU13: 20.16 | GV13: 22.21 | GW13: 24.05 | GX13: 26.41 | HA13: 10 | HB13: 7 | HE13: U9 | HF13: B18 | HG13: B18 | HH13: 20 | HL13: AlfaU9 | HM13: B18 | HN13: Santa Marta | HO13: 818
A14: =HOUR(G14)+1 | D14: =IFERROR( IF(AND(OR(Planilla!B14="C",Planilla!B14="c"), VLOOKUP(E14,FD:FP,13,0)="C"), "OK",IF(AND(OR(Planilla!B14="C",Planilla!B14="c"), OR(VLOOKUP(E14,FD:FP,13,0)="B", VLOOKUP(E14,FD:FP,13,0)="A")), "DEFICIT",IF( AND(OR(Planilla!B14="B", Planilla!B14="BPAL"), VLOOKUP(E14,FD:FP,13,0)="B"), "OK",IF(AND(OR(Planilla!B14="B", Planilla!B14="BPAL"), VLOOKUP(E14,FD:FP,13,0)="A"), "DEFICIT",IF(AND(OR(Planilla!B14="B", Planilla!B14="BPAL"), VLOOKUP(E14,FD:FP,13,0)="C"), "SOBREOFERTA",IF(AND(Planilla!B14="A", VLOOKUP(E14,FD:FP,13,0)="A"), "OK",IF( AND(Planilla!B14="A", OR(VLOOKUP(E14,FD:FP,13,0)="B", VLOOKUP(E14,FD:FP,13,0)="C")), "SOBREOFERTA","" ))))))),"") | H14: =IF(I14="","",IF(AND((I14-G14)>=TIME(0,0,0),(I14-G14)<TIME(0,3,0)),"OK",IF(AND((I14-G14)>=TIME(0,3,0),(I14-G14)<TIME(0,5,0)),"RETRASO DE 3-5 MIN",IF(AND((I14-G14)>=TIME(0,5,0),(I14-G14)<TIME(0,10,0)),"RETRASO DE 5-10 MIN",IF((I14-G14)>=TIME(0,10,0),"RETRASO >10 MIN", IF(AND((G14-I14)>=TIME(0,0,0),(G14-I14)<TIME(0,3,0)),"OK",IF((G14-I14)>=TIME(0,3,0),"ADELANTADO"))))))) | J14: =IF(A14<>"",HLOOKUP(VALUE(TEXT(G14,"h:mm:ss")),IF($C$6="Laboral",$FZ$4:$GX$227,IF($C$6="Sábado",$FZ$231:$GX$452,$FZ$456:$GX$656)),VLOOKUP($C$4,$HF$2:$HH$99,3,0)+IF(C$5="Ida",0,1),1),"") | K14: =IF(A15<>A14,AVERAGEIF(A$9:A14,A14,J$9:J14),"") | L14: =IFERROR(IF(A15<>A14,AVERAGEIF(A$9:A14,A14,S$9:S14),""),"") | M14: =IFERROR(IF(A15<>A14,AVERAGEIF(A$9:A14,A14,T$9:T14),""),"") | N14: {=IFERROR(IF(A15<>A14,_xlfn.STDEV.P(IF(A$9:A14=A14,T$9:T14)),""),"")} | O14: {=IFERROR(IF(A15<>A14,_xlfn.STDEV.P(IF(A$9:A14=A14,S$9:S14)),""),"")} | P14: =IFERROR(IF(A14<>A15,MAX((((M14*24*60)/2)*(1+POWER((((N14*24*60) / (M14*24*60) )),2))) + ((M14*24*60 )*-0.1 + (K14*0.015)) +1,(((M14*24*60)/2)*(1+POWER((((N14*24*60) / (M14*24*60 ))),2)))),""),"") | Q14: =IF(AND(O14<>"",L14<>""),IF(A14<>A15,((L14*24*60) / 2 ) * (1 + POWER(((O14*24*60) / (L14*24*60)),2)),""),"") | R14: =IF(Q14<>"",MAX(P14,Q14),"") | S14: =IF(I14<>"H. Sale Real",IF(AND(I15<>"",LEFT(C15,2)<>"Va"),IF(AND(I14<>"",LEFT(C14,2)<>"Va",I14<>"H. Sale Real"),IF(I15-I14<0.208333333333333,I15-I14,""),IF(AND(I13<>"",LEFT(C13,2)<>"Va",I13<>"H. Sale Real"),IF(I15-I13<0.208333333333333,I15-I13,""),IF(AND(I12<>"",LEFT(C12,2)<>"Va",I12<>"H. Sale Real"),IF(I15-I12<0.208333333333333,I15-I12,""),IF(AND(I11<>"",LEFT(C11,2)<>"Va",I11<>"H. Sale Real"),IF(I15-I11<0.208333333333333,I15-I11,""),IF(AND(I10<>"",LEFT(C10,2)<>"Va",I10<>"H. Sale Real"),IF(I15-I10<0.208333333333333,I15-I10,""),""))))),""),"") | T14: =IF(G14<>"H. Sale Real",IF(AND(G15<>"",LEFT(C15,2)<>"Va"),IF(AND(G14<>"",LEFT(C14,2)<>"Va",G14<>"H. Sale Real"),IF(G15-G14<0.208333333333333,G15-G14,""),IF(AND(G13<>"",LEFT(C13,2)<>"Va",G13<>"H. Sale Real"),IF(G15-G13<0.208333333333333,G15-G13,""),IF(AND(G12<>"",LEFT(C12,2)<>"Va",G12<>"H. Sale Real"),IF(G15-G12<0.208333333333333,G15-G12,""),IF(AND(G11<>"",LEFT(C11,2)<>"Va",G11<>"H. Sale Real"),IF(G15-G11<0.208333333333333,G15-G11,""),IF(AND(G10<>"",LEFT(C10,2)<>"Va",G10<>"H. Sale Real"),IF(G15-G10<0.208333333333333,G15-G10,""),""))))),""),"") | Z14: =IF(G14<>"",IF(AND(Z13<>"IE",P14<>0,R14<>""),IF(IFERROR((P14/R14),0) <=1,IFERROR(P14/R14,""),1),""),"") | AE14: =HOUR(AK14)+1 | AL14: =IF(AM14="","",IF(AND((AM14-AK14)>=TIME(0,0,0),(AM14-AK14)<TIME(0,3,0)),"OK",IF(AND((AM14-AK14)>=TIME(0,3,0),(AM14-AK14)<TIME(0,5,0)),"RETRASO DE 3-5 MIN",IF(AND((AM14-AK14)>=TIME(0,5,0),(AM14-AK14)<TIME(0,10,0)),"RETRASO DE 5-10 MIN",IF((AM14-AK14)>=TIME(0,10,0),"RETRASO >10 MIN", IF(AND((AK14-AM14)>=TIME(0,0,0),(AK14-AM14)<TIME(0,3,0)),"OK",IF((AK14-AM14)>=TIME(0,3,0),"ADELANTADO"))))))) | AN14: =IF(AE14<>"",HLOOKUP(VALUE(TEXT(AK14,"h:mm:ss")),IF($C$6="Laboral",$FZ$4:$GX$227,IF($C$6="Sábado",$FZ$231:$GX$452,$FZ$456:$GX$656)),VLOOKUP($C$4,$HF$2:$HH$99,3,0)+IF(AG$5="Ida",0,1),1),"") | AO14: =IF(AE15<>AE14,AVERAGEIF(AE$9:AE14,AE14,AN$9:AN14),"") | AP14: =IFERROR(IF(AE15<>AE14,AVERAGEIF(AE$9:AE14,AE14,AW$9:AW14),""),"") | AQ14: =IFERROR(IF(AE15<>AE14,AVERAGEIF(AE$9:AE14,AE14,AX$9:AX14),""),"") | AR14: {=IFERROR(IF(AE15<>AE14,_xlfn.STDEV.P(IF(AE$9:AE14=AE14,AX$9:AX14)),""),"")} | AS14: {=IFERROR(IF(AE15<>AE14,_xlfn.STDEV.P(IF(AE$9:AE14=AE14,AW$9:AW14)),""),"")} | AT14: =IFERROR(IF(AE14<>AE15,MAX((((AQ14*24*60)/2)*(1+POWER((((AR14*24*60) / (AQ14*24*60) )),2))) + ((AQ14*24*60 )*-0.1 + (AO14*0.015)) +1,(((AQ14*24*60)/2)*(1+POWER((((AR14*24*60) / (AQ14*24*60 ))),2)))),""),"") | AU14: =IF(AND(AS14<>"",AP14<>""),IF(AE14<>AE15,((AP14*24*60) / 2 ) * (1 + POWER(((AS14*24*60) / (AP14*24*60)),2)),""),"") | AV14: =IF(AU14<>"",MAX(AT14,AU14),"") | AW14: =IF(AM14<>"H. Sale Real",IF(AND(AM15<>"",LEFT(AG15,2)<>"Va"),IF(AND(AM14<>"",LEFT(AG14,2)<>"Va",AM14<>"H. Sale Real"),IF(AM15-AM14<0.208333333333333,AM15-AM14,""),IF(AND(AM13<>"",LEFT(AG13,2)<>"Va",AM13<>"H. Sale Real"),IF(AM15-AM13<0.208333333333333,AM15-AM13,""),IF(AND(AM12<>"",LEFT(AG12,2)<>"Va",AM12<>"H. Sale Real"),IF(AM15-AM12<0.208333333333333,AM15-AM12,""),IF(AND(AM11<>"",LEFT(AG11,2)<>"Va",AM11<>"H. Sale Real"),IF(AM15-AM11<0.208333333333333,AM15-AM11,""),IF(AND(AM10<>"",LEFT(AG10,2)<>"Va",AM10<>"H. Sale Real"),IF(AM15-AM10<0.208333333333333,AM15-AM10,""),""))))),""),"") | AX14: =IF(AK14<>"H. Sale Real",IF(AND(AK15<>"",LEFT(AG15,2)<>"Va"),IF(AND(AK14<>"",LEFT(AG14,2)<>"Va",AK14<>"H. Sale Real"),IF(AK15-AK14<0.208333333333333,AK15-AK14,""),IF(AND(AK13<>"",LEFT(AG13,2)<>"Va",AK13<>"H. Sale Real"),IF(AK15-AK13<0.208333333333333,AK15-AK13,""),IF(AND(AK12<>"",LEFT(AG12,2)<>"NC",AK12<>"H. Sale Real"),IF(AK15-AK12<0.208333333333333,AK15-AK12,""),IF(AND(AK11<>"",LEFT(AG11,2)<>"Va",AK11<>"H. Sale Real"),IF(AK15-AK11<0.208333333333333,AK15-AK11,""),IF(AND(AK10<>"",LEFT(AG10,2)<>"Va",AK10<>"H. Sale Real"),IF(AK15-AK10<0.208333333333333,AK15-AK10,""),""))))),""),"") | BD14: =IF(AK14<>"",IF(AND(BD13<>"IE",AT14<>0,AV14<>""),IF(IFERROR((AT14/AV14),0) <=1,IFERROR(AT14/AV14,""),1),""),"") | BI14: 2 | BJ14: =COUNTIFS($A:$A,$BI14,$C:$C,$BI$11) | BK14: =BJ14-COUNTIFS($A:$A,$BI14,$C:$C,$BI$11,$H:$H,"") | BL14: =IFERROR((BK14/BJ14),"") | BM14: =_xlfn.XLOOKUP(BI14,$A:$A,$R:$R,"0",0,-1) | BN14: =_xlfn.XLOOKUP(BI14,$A:$A,$P:$P,"0",0,-1) | BO14: =_xlfn.XLOOKUP(BI14,$A:$A,$Z:$Z,"",0,-1) | BR14: 2 | BS14: =COUNTIFS($AE:$AE,$BR14,$AG:$AG,$BR$11) | BT14: =BS14-COUNTIFS($AE:$AE,$BR14,$AG:$AG,$BR$11,$AL:$AL,"") | BU14: =IFERROR((BT14/BS14),"") | BV14: =_xlfn.XLOOKUP(BR14,$AE:$AE,$AV:$AV,"0",0,-1) | BW14: =_xlfn.XLOOKUP(BR14,$AE:$AE,$AT:$AT,"0",0,-1) | BX14: =_xlfn.XLOOKUP(BR14,$AE:$AE,$BD:$BD,"",0,-1) | FC14: Diccionario 1 | FD14: 1011 | FE14: D8478205K2PL | FF14: YV3T7U520KA195140 | FG14: Volvo | FH14: B8R | FI14: MARCOPOLO | FJ14: TORINO | FK14: 2019 | FL14: B2PAL | FM14: LOS LIBERTADORES | FN14: Los Liberadores 6450, Lote 4A | FO14: Huechuraba | FP14: B | FS14: 3005 / SFWZ-39| | FT14: SFWZ-39| | FU14: SFWZ-39 | FV14: =VLOOKUP(FU14,FD:FL,9,0) | FZ14: B08 | GA14: 0 | GB14: 0 | GC14: 0 | GD14: 0 | GE14: 14.545 | GF14: 26.045 | GG14: 18.89 | GH14: 13.08 | GI14: 16.9 | GJ14: 18.97 | GK14: 18.605 | GL14: 18.11 | GM14: 17.29 | GN14: 17.27 | GO14: 17.1 | GP14: 16.02 | GQ14: 15.145 | GR14: 13.705 | GS14: 13.455 | GT14: 16.795 | GU14: 19.67 | GV14: 21.5 | GW14: 23.315 | GX14: 26.9 | HA14: 11 | HB14: 8 | HE14: U9 | HF14: B20 | HG14: B20 | HH14: 24 | HL14: AlfaU9 | HM14: B20 | HN14: El Retiro | HO14: 820
A15: =HOUR(G15)+1 | D15: =IFERROR( IF(AND(OR(Planilla!B15="C",Planilla!B15="c"), VLOOKUP(E15,FD:FP,13,0)="C"), "OK",IF(AND(OR(Planilla!B15="C",Planilla!B15="c"), OR(VLOOKUP(E15,FD:FP,13,0)="B", VLOOKUP(E15,FD:FP,13,0)="A")), "DEFICIT",IF( AND(OR(Planilla!B15="B", Planilla!B15="BPAL"), VLOOKUP(E15,FD:FP,13,0)="B"), "OK",IF(AND(OR(Planilla!B15="B", Planilla!B15="BPAL"), VLOOKUP(E15,FD:FP,13,0)="A"), "DEFICIT",IF(AND(OR(Planilla!B15="B", Planilla!B15="BPAL"), VLOOKUP(E15,FD:FP,13,0)="C"), "SOBREOFERTA",IF(AND(Planilla!B15="A", VLOOKUP(E15,FD:FP,13,0)="A"), "OK",IF( AND(Planilla!B15="A", OR(VLOOKUP(E15,FD:FP,13,0)="B", VLOOKUP(E15,FD:FP,13,0)="C")), "SOBREOFERTA","" ))))))),"") | H15: =IF(I15="","",IF(AND((I15-G15)>=TIME(0,0,0),(I15-G15)<TIME(0,3,0)),"OK",IF(AND((I15-G15)>=TIME(0,3,0),(I15-G15)<TIME(0,5,0)),"RETRASO DE 3-5 MIN",IF(AND((I15-G15)>=TIME(0,5,0),(I15-G15)<TIME(0,10,0)),"RETRASO DE 5-10 MIN",IF((I15-G15)>=TIME(0,10,0),"RETRASO >10 MIN", IF(AND((G15-I15)>=TIME(0,0,0),(G15-I15)<TIME(0,3,0)),"OK",IF((G15-I15)>=TIME(0,3,0),"ADELANTADO"))))))) | J15: =IF(A15<>"",HLOOKUP(VALUE(TEXT(G15,"h:mm:ss")),IF($C$6="Laboral",$FZ$4:$GX$227,IF($C$6="Sábado",$FZ$231:$GX$452,$FZ$456:$GX$656)),VLOOKUP($C$4,$HF$2:$HH$99,3,0)+IF(C$5="Ida",0,1),1),"") | K15: =IF(A16<>A15,AVERAGEIF(A$9:A15,A15,J$9:J15),"") | L15: =IFERROR(IF(A16<>A15,AVERAGEIF(A$9:A15,A15,S$9:S15),""),"") | M15: =IFERROR(IF(A16<>A15,AVERAGEIF(A$9:A15,A15,T$9:T15),""),"") | N15: {=IFERROR(IF(A16<>A15,_xlfn.STDEV.P(IF(A$9:A15=A15,T$9:T15)),""),"")} | O15: {=IFERROR(IF(A16<>A15,_xlfn.STDEV.P(IF(A$9:A15=A15,S$9:S15)),""),"")} | P15: =IFERROR(IF(A15<>A16,MAX((((M15*24*60)/2)*(1+POWER((((N15*24*60) / (M15*24*60) )),2))) + ((M15*24*60 )*-0.1 + (K15*0.015)) +1,(((M15*24*60)/2)*(1+POWER((((N15*24*60) / (M15*24*60 ))),2)))),""),"") | Q15: =IF(AND(O15<>"",L15<>""),IF(A15<>A16,((L15*24*60) / 2 ) * (1 + POWER(((O15*24*60) / (L15*24*60)),2)),""),"") | R15: =IF(Q15<>"",MAX(P15,Q15),"") | S15: =IF(I15<>"H. Sale Real",IF(AND(I16<>"",LEFT(C16,2)<>"Va"),IF(AND(I15<>"",LEFT(C15,2)<>"Va",I15<>"H. Sale Real"),IF(I16-I15<0.208333333333333,I16-I15,""),IF(AND(I14<>"",LEFT(C14,2)<>"Va",I14<>"H. Sale Real"),IF(I16-I14<0.208333333333333,I16-I14,""),IF(AND(I13<>"",LEFT(C13,2)<>"Va",I13<>"H. Sale Real"),IF(I16-I13<0.208333333333333,I16-I13,""),IF(AND(I12<>"",LEFT(C12,2)<>"Va",I12<>"H. Sale Real"),IF(I16-I12<0.208333333333333,I16-I12,""),IF(AND(I11<>"",LEFT(C11,2)<>"Va",I11<>"H. Sale Real"),IF(I16-I11<0.208333333333333,I16-I11,""),""))))),""),"") | T15: =IF(G15<>"H. Sale Real",IF(AND(G16<>"",LEFT(C16,2)<>"Va"),IF(AND(G15<>"",LEFT(C15,2)<>"Va",G15<>"H. Sale Real"),IF(G16-G15<0.208333333333333,G16-G15,""),IF(AND(G14<>"",LEFT(C14,2)<>"Va",G14<>"H. Sale Real"),IF(G16-G14<0.208333333333333,G16-G14,""),IF(AND(G13<>"",LEFT(C13,2)<>"Va",G13<>"H. Sale Real"),IF(G16-G13<0.208333333333333,G16-G13,""),IF(AND(G12<>"",LEFT(C12,2)<>"Va",G12<>"H. Sale Real"),IF(G16-G12<0.208333333333333,G16-G12,""),IF(AND(G11<>"",LEFT(C11,2)<>"Va",G11<>"H. Sale Real"),IF(G16-G11<0.208333333333333,G16-G11,""),""))))),""),"") | Z15: =IF(G15<>"",IF(AND(Z14<>"IE",P15<>0,R15<>""),IF(IFERROR((P15/R15),0) <=1,IFERROR(P15/R15,""),1),""),"") | AE15: =HOUR(AK15)+1 | AL15: =IF(AM15="","",IF(AND((AM15-AK15)>=TIME(0,0,0),(AM15-AK15)<TIME(0,3,0)),"OK",IF(AND((AM15-AK15)>=TIME(0,3,0),(AM15-AK15)<TIME(0,5,0)),"RETRASO DE 3-5 MIN",IF(AND((AM15-AK15)>=TIME(0,5,0),(AM15-AK15)<TIME(0,10,0)),"RETRASO DE 5-10 MIN",IF((AM15-AK15)>=TIME(0,10,0),"RETRASO >10 MIN", IF(AND((AK15-AM15)>=TIME(0,0,0),(AK15-AM15)<TIME(0,3,0)),"OK",IF((AK15-AM15)>=TIME(0,3,0),"ADELANTADO"))))))) | AN15: =IF(AE15<>"",HLOOKUP(VALUE(TEXT(AK15,"h:mm:ss")),IF($C$6="Laboral",$FZ$4:$GX$227,IF($C$6="Sábado",$FZ$231:$GX$452,$FZ$456:$GX$656)),VLOOKUP($C$4,$HF$2:$HH$99,3,0)+IF(AG$5="Ida",0,1),1),"") | AO15: =IF(AE16<>AE15,AVERAGEIF(AE$9:AE15,AE15,AN$9:AN15),"") | AP15: =IFERROR(IF(AE16<>AE15,AVERAGEIF(AE$9:AE15,AE15,AW$9:AW15),""),"") | AQ15: =IFERROR(IF(AE16<>AE15,AVERAGEIF(AE$9:AE15,AE15,AX$9:AX15),""),"") | AR15: {=IFERROR(IF(AE16<>AE15,_xlfn.STDEV.P(IF(AE$9:AE15=AE15,AX$9:AX15)),""),"")} | AS15: {=IFERROR(IF(AE16<>AE15,_xlfn.STDEV.P(IF(AE$9:AE15=AE15,AW$9:AW15)),""),"")} | AT15: =IFERROR(IF(AE15<>AE16,MAX((((AQ15*24*60)/2)*(1+POWER((((AR15*24*60) / (AQ15*24*60) )),2))) + ((AQ15*24*60 )*-0.1 + (AO15*0.015)) +1,(((AQ15*24*60)/2)*(1+POWER((((AR15*24*60) / (AQ15*24*60 ))),2)))),""),"") | AU15: =IF(AND(AS15<>"",AP15<>""),IF(AE15<>AE16,((AP15*24*60) / 2 ) * (1 + POWER(((AS15*24*60) / (AP15*24*60)),2)),""),"") | AV15: =IF(AU15<>"",MAX(AT15,AU15),"") | AW15: =IF(AM15<>"H. Sale Real",IF(AND(AM16<>"",LEFT(AG16,2)<>"Va"),IF(AND(AM15<>"",LEFT(AG15,2)<>"Va",AM15<>"H. Sale Real"),IF(AM16-AM15<0.208333333333333,AM16-AM15,""),IF(AND(AM14<>"",LEFT(AG14,2)<>"Va",AM14<>"H. Sale Real"),IF(AM16-AM14<0.208333333333333,AM16-AM14,""),IF(AND(AM13<>"",LEFT(AG13,2)<>"Va",AM13<>"H. Sale Real"),IF(AM16-AM13<0.208333333333333,AM16-AM13,""),IF(AND(AM12<>"",LEFT(AG12,2)<>"Va",AM12<>"H. Sale Real"),IF(AM16-AM12<0.208333333333333,AM16-AM12,""),IF(AND(AM11<>"",LEFT(AG11,2)<>"Va",AM11<>"H. Sale Real"),IF(AM16-AM11<0.208333333333333,AM16-AM11,""),""))))),""),"") | AX15: =IF(AK15<>"H. Sale Real",IF(AND(AK16<>"",LEFT(AG16,2)<>"Va"),IF(AND(AK15<>"",LEFT(AG15,2)<>"Va",AK15<>"H. Sale Real"),IF(AK16-AK15<0.208333333333333,AK16-AK15,""),IF(AND(AK14<>"",LEFT(AG14,2)<>"Va",AK14<>"H. Sale Real"),IF(AK16-AK14<0.208333333333333,AK16-AK14,""),IF(AND(AK13<>"",LEFT(AG13,2)<>"NC",AK13<>"H. Sale Real"),IF(AK16-AK13<0.208333333333333,AK16-AK13,""),IF(AND(AK12<>"",LEFT(AG12,2)<>"Va",AK12<>"H. Sale Real"),IF(AK16-AK12<0.208333333333333,AK16-AK12,""),IF(AND(AK11<>"",LEFT(AG11,2)<>"Va",AK11<>"H. Sale Real"),IF(AK16-AK11<0.208333333333333,AK16-AK11,""),""))))),""),"") | BD15: =IF(AK15<>"",IF(AND(BD14<>"IE",AT15<>0,AV15<>""),IF(IFERROR((AT15/AV15),0) <=1,IFERROR(AT15/AV15,""),1),""),"") | BI15: 3 | BJ15: =COUNTIFS($A:$A,$BI15,$C:$C,$BI$11) | BK15: =BJ15-COUNTIFS($A:$A,$BI15,$C:$C,$BI$11,$H:$H,"") | BL15: =IFERROR((BK15/BJ15),"") | BM15: =_xlfn.XLOOKUP(BI15,$A:$A,$R:$R,"0",0,-1) | BN15: =_xlfn.XLOOKUP(BI15,$A:$A,$P:$P,"0",0,-1) | BO15: =_xlfn.XLOOKUP(BI15,$A:$A,$Z:$Z,"",0,-1) | BR15: 3 | BS15: =COUNTIFS($AE:$AE,$BR15,$AG:$AG,$BR$11) | BT15: =BS15-COUNTIFS($AE:$AE,$BR15,$AG:$AG,$BR$11,$AL:$AL,"") | BU15: =IFERROR((BT15/BS15),"") | BV15: =_xlfn.XLOOKUP(BR15,$AE:$AE,$AV:$AV,"0",0,-1) | BW15: =_xlfn.XLOOKUP(BR15,$AE:$AE,$AT:$AT,"0",0,-1) | BX15: =_xlfn.XLOOKUP(BR15,$AE:$AE,$BD:$BD,"",0,-1) | FC15: Diccionario 1 | FD15: 1012 | FE15: D8481556K2PL | FF15: YV3T7U521KA195177 | FG15: Volvo | FH15: B8R | FI15: MARCOPOLO | FJ15: TORINO | FK15: 2019 | FL15: B2PAL | FM15: SAN JOSE | FN15: San José 030 (José Besa 669) | FO15: San Bernardo | FP15: B | FS15: 3005 / SFWZ-39| | FT15: SFWZ-39| | FU15: SFWZ-39 | FV15: =VLOOKUP(FU15,FD:FL,9,0) | FZ15: B09 | GA15: 0 | GB15: 0 | GC15: 0 | GD15: 0 | GE15: 13.245 | GF15: 23.725 | GG15: 18.46 | GH15: 17.055 | GI15: 20.3 | GJ15: 21.73 | GK15: 21.455 | GL15: 20.605 | GM15: 19.165 | GN15: 18.745 | GO15: 18.565 | GP15: 17.68 | GQ15: 17.115 | GR15: 16.725 | GS15: 18.5 | GT15: 21.01 | GU15: 23.135 | GV15: 25.075 | GW15: 26.45 | GX15: 0 | HA15: 12 | HB15: 9 | HE15: U9 | HF15: 722 | HG15: 722 | HH15: 25 | HL15: AlfaU9 | HM15: 722 | HN15: Santa Marta | HO15: 822
A16: =HOUR(G16)+1 | D16: =IFERROR( IF(AND(OR(Planilla!B16="C",Planilla!B16="c"), VLOOKUP(E16,FD:FP,13,0)="C"), "OK",IF(AND(OR(Planilla!B16="C",Planilla!B16="c"), OR(VLOOKUP(E16,FD:FP,13,0)="B", VLOOKUP(E16,FD:FP,13,0)="A")), "DEFICIT",IF( AND(OR(Planilla!B16="B", Planilla!B16="BPAL"), VLOOKUP(E16,FD:FP,13,0)="B"), "OK",IF(AND(OR(Planilla!B16="B", Planilla!B16="BPAL"), VLOOKUP(E16,FD:FP,13,0)="A"), "DEFICIT",IF(AND(OR(Planilla!B16="B", Planilla!B16="BPAL"), VLOOKUP(E16,FD:FP,13,0)="C"), "SOBREOFERTA",IF(AND(Planilla!B16="A", VLOOKUP(E16,FD:FP,13,0)="A"), "OK",IF( AND(Planilla!B16="A", OR(VLOOKUP(E16,FD:FP,13,0)="B", VLOOKUP(E16,FD:FP,13,0)="C")), "SOBREOFERTA","" ))))))),"") | H16: =IF(I16="","",IF(AND((I16-G16)>=TIME(0,0,0),(I16-G16)<TIME(0,3,0)),"OK",IF(AND((I16-G16)>=TIME(0,3,0),(I16-G16)<TIME(0,5,0)),"RETRASO DE 3-5 MIN",IF(AND((I16-G16)>=TIME(0,5,0),(I16-G16)<TIME(0,10,0)),"RETRASO DE 5-10 MIN",IF((I16-G16)>=TIME(0,10,0),"RETRASO >10 MIN", IF(AND((G16-I16)>=TIME(0,0,0),(G16-I16)<TIME(0,3,0)),"OK",IF((G16-I16)>=TIME(0,3,0),"ADELANTADO"))))))) | J16: =IF(A16<>"",HLOOKUP(VALUE(TEXT(G16,"h:mm:ss")),IF($C$6="Laboral",$FZ$4:$GX$227,IF($C$6="Sábado",$FZ$231:$GX$452,$FZ$456:$GX$656)),VLOOKUP($C$4,$HF$2:$HH$99,3,0)+IF(C$5="Ida",0,1),1),"") | K16: =IF(A17<>A16,AVERAGEIF(A$9:A16,A16,J$9:J16),"") | L16: =IFERROR(IF(A17<>A16,AVERAGEIF(A$9:A16,A16,S$9:S16),""),"") | M16: =IFERROR(IF(A17<>A16,AVERAGEIF(A$9:A16,A16,T$9:T16),""),"") | N16: {=IFERROR(IF(A17<>A16,_xlfn.STDEV.P(IF(A$9:A16=A16,T$9:T16)),""),"")} | O16: {=IFERROR(IF(A17<>A16,_xlfn.STDEV.P(IF(A$9:A16=A16,S$9:S16)),""),"")} | P16: =IFERROR(IF(A16<>A17,MAX((((M16*24*60)/2)*(1+POWER((((N16*24*60) / (M16*24*60) )),2))) + ((M16*24*60 )*-0.1 + (K16*0.015)) +1,(((M16*24*60)/2)*(1+POWER((((N16*24*60) / (M16*24*60 ))),2)))),""),"") | Q16: =IF(AND(O16<>"",L16<>""),IF(A16<>A17,((L16*24*60) / 2 ) * (1 + POWER(((O16*24*60) / (L16*24*60)),2)),""),"") | R16: =IF(Q16<>"",MAX(P16,Q16),"") | S16: =IF(I16<>"H. Sale Real",IF(AND(I17<>"",LEFT(C17,2)<>"Va"),IF(AND(I16<>"",LEFT(C16,2)<>"Va",I16<>"H. Sale Real"),IF(I17-I16<0.208333333333333,I17-I16,""),IF(AND(I15<>"",LEFT(C15,2)<>"Va",I15<>"H. Sale Real"),IF(I17-I15<0.208333333333333,I17-I15,""),IF(AND(I14<>"",LEFT(C14,2)<>"Va",I14<>"H. Sale Real"),IF(I17-I14<0.208333333333333,I17-I14,""),IF(AND(I13<>"",LEFT(C13,2)<>"Va",I13<>"H. Sale Real"),IF(I17-I13<0.208333333333333,I17-I13,""),IF(AND(I12<>"",LEFT(C12,2)<>"Va",I12<>"H. Sale Real"),IF(I17-I12<0.208333333333333,I17-I12,""),""))))),""),"") | T16: =IF(G16<>"H. Sale Real",IF(AND(G17<>"",LEFT(C17,2)<>"Va"),IF(AND(G16<>"",LEFT(C16,2)<>"Va",G16<>"H. Sale Real"),IF(G17-G16<0.208333333333333,G17-G16,""),IF(AND(G15<>"",LEFT(C15,2)<>"Va",G15<>"H. Sale Real"),IF(G17-G15<0.208333333333333,G17-G15,""),IF(AND(G14<>"",LEFT(C14,2)<>"Va",G14<>"H. Sale Real"),IF(G17-G14<0.208333333333333,G17-G14,""),IF(AND(G13<>"",LEFT(C13,2)<>"Va",G13<>"H. Sale Real"),IF(G17-G13<0.208333333333333,G17-G13,""),IF(AND(G12<>"",LEFT(C12,2)<>"Va",G12<>"H. Sale Real"),IF(G17-G12<0.208333333333333,G17-G12,""),""))))),""),"") | Z16: =IF(G16<>"",IF(AND(Z15<>"IE",P16<>0,R16<>""),IF(IFERROR((P16/R16),0) <=1,IFERROR(P16/R16,""),1),""),"") | AE16: =HOUR(AK16)+1 | AL16: =IF(AM16="","",IF(AND((AM16-AK16)>=TIME(0,0,0),(AM16-AK16)<TIME(0,3,0)),"OK",IF(AND((AM16-AK16)>=TIME(0,3,0),(AM16-AK16)<TIME(0,5,0)),"RETRASO DE 3-5 MIN",IF(AND((AM16-AK16)>=TIME(0,5,0),(AM16-AK16)<TIME(0,10,0)),"RETRASO DE 5-10 MIN",IF((AM16-AK16)>=TIME(0,10,0),"RETRASO >10 MIN", IF(AND((AK16-AM16)>=TIME(0,0,0),(AK16-AM16)<TIME(0,3,0)),"OK",IF((AK16-AM16)>=TIME(0,3,0),"ADELANTADO"))))))) | AN16: =IF(AE16<>"",HLOOKUP(VALUE(TEXT(AK16,"h:mm:ss")),IF($C$6="Laboral",$FZ$4:$GX$227,IF($C$6="Sábado",$FZ$231:$GX$452,$FZ$456:$GX$656)),VLOOKUP($C$4,$HF$2:$HH$99,3,0)+IF(AG$5="Ida",0,1),1),"") | AO16: =IF(AE17<>AE16,AVERAGEIF(AE$9:AE16,AE16,AN$9:AN16),"") | AP16: =IFERROR(IF(AE17<>AE16,AVERAGEIF(AE$9:AE16,AE16,AW$9:AW16),""),"") | AQ16: =IFERROR(IF(AE17<>AE16,AVERAGEIF(AE$9:AE16,AE16,AX$9:AX16),""),"") | AR16: {=IFERROR(IF(AE17<>AE16,_xlfn.STDEV.P(IF(AE$9:AE16=AE16,AX$9:AX16)),""),"")} | AS16: {=IFERROR(IF(AE17<>AE16,_xlfn.STDEV.P(IF(AE$9:AE16=AE16,AW$9:AW16)),""),"")} | AT16: =IFERROR(IF(AE16<>AE17,MAX((((AQ16*24*60)/2)*(1+POWER((((AR16*24*60) / (AQ16*24*60) )),2))) + ((AQ16*24*60 )*-0.1 + (AO16*0.015)) +1,(((AQ16*24*60)/2)*(1+POWER((((AR16*24*60) / (AQ16*24*60 ))),2)))),""),"") | AU16: =IF(AND(AS16<>"",AP16<>""),IF(AE16<>AE17,((AP16*24*60) / 2 ) * (1 + POWER(((AS16*24*60) / (AP16*24*60)),2)),""),"") | AV16: =IF(AU16<>"",MAX(AT16,AU16),"") | AW16: =IF(AM16<>"H. Sale Real",IF(AND(AM17<>"",LEFT(AG17,2)<>"Va"),IF(AND(AM16<>"",LEFT(AG16,2)<>"Va",AM16<>"H. Sale Real"),IF(AM17-AM16<0.208333333333333,AM17-AM16,""),IF(AND(AM15<>"",LEFT(AG15,2)<>"Va",AM15<>"H. Sale Real"),IF(AM17-AM15<0.208333333333333,AM17-AM15,""),IF(AND(AM14<>"",LEFT(AG14,2)<>"Va",AM14<>"H. Sale Real"),IF(AM17-AM14<0.208333333333333,AM17-AM14,""),IF(AND(AM13<>"",LEFT(AG13,2)<>"Va",AM13<>"H. Sale Real"),IF(AM17-AM13<0.208333333333333,AM17-AM13,""),IF(AND(AM12<>"",LEFT(AG12,2)<>"Va",AM12<>"H. Sale Real"),IF(AM17-AM12<0.208333333333333,AM17-AM12,""),""))))),""),"") | AX16: =IF(AK16<>"H. Sale Real",IF(AND(AK17<>"",LEFT(AG17,2)<>"Va"),IF(AND(AK16<>"",LEFT(AG16,2)<>"Va",AK16<>"H. Sale Real"),IF(AK17-AK16<0.208333333333333,AK17-AK16,""),IF(AND(AK15<>"",LEFT(AG15,2)<>"Va",AK15<>"H. Sale Real"),IF(AK17-AK15<0.208333333333333,AK17-AK15,""),IF(AND(AK14<>"",LEFT(AG14,2)<>"NC",AK14<>"H. Sale Real"),IF(AK17-AK14<0.208333333333333,AK17-AK14,""),IF(AND(AK13<>"",LEFT(AG13,2)<>"Va",AK13<>"H. Sale Real"),IF(AK17-AK13<0.208333333333333,AK17-AK13,""),IF(AND(AK12<>"",LEFT(AG12,2)<>"Va",AK12<>"H. Sale Real"),IF(AK17-AK12<0.208333333333333,AK17-AK12,""),""))))),""),"") | BD16: =IF(AK16<>"",IF(AND(BD15<>"IE",AT16<>0,AV16<>""),IF(IFERROR((AT16/AV16),0) <=1,IFERROR(AT16/AV16,""),1),""),"") | BI16: 4 | BJ16: =COUNTIFS($A:$A,$BI16,$C:$C,$BI$11) | BK16: =BJ16-COUNTIFS($A:$A,$BI16,$C:$C,$BI$11,$H:$H,"") | BL16: =IFERROR((BK16/BJ16),"") | BM16: =_xlfn.XLOOKUP(BI16,$A:$A,$R:$R,"0",0,-1) | BN16: =_xlfn.XLOOKUP(BI16,$A:$A,$P:$P,"0",0,-1) | BO16: =_xlfn.XLOOKUP(BI16,$A:$A,$Z:$Z,"",0,-1) | BR16: 4 | BS16: =COUNTIFS($AE:$AE,$BR16,$AG:$AG,$BR$11) | BT16: =BS16-COUNTIFS($AE:$AE,$BR16,$AG:$AG,$BR$11,$AL:$AL,"") | BU16: =IFERROR((BT16/BS16),"") | BV16: =_xlfn.XLOOKUP(BR16,$AE:$AE,$AV:$AV,"0",0,-1) | BW16: =_xlfn.XLOOKUP(BR16,$AE:$AE,$AT:$AT,"0",0,-1) | BX16: =_xlfn.XLOOKUP(BR16,$AE:$AE,$BD:$BD,"",0,-1) | FC16: Diccionario 1 | FD16: 1013 | FE16: D8482482K2PL | FF16: YV3T7U523KA195326 | FG16: Volvo | FH16: B8R | FI16: MARCOPOLO | FJ16: TORINO | FK16: 2019 | FL16: B2PAL | FM16: LOS LIBERTADORES | FN16: Los Liberadores 6450, Lote 4A | FO16: Huechuraba | FP16: B | FS16: 3005 / SFWZ-39| | FT16: SFWZ-39| | FU16: SFWZ-39 | FV16: =VLOOKUP(FU16,FD:FL,9,0) | FZ16: B10 | GA16: 0 | GB16: 0 | GC16: 0 | GD16: 0 | GE16: 0 | GF16: 9.58 | GG16: 15.145 | GH16: 12.605 | GI16: 14.385 | GJ16: 15.19 | GK16: 15.085 | GL16: 14.8 | GM16: 14.43 | GN16: 14.59 | GO16: 14.42 | GP16: 13.86 | GQ16: 12.755 | GR16: 11.79 | GS16: 12.895 | GT16: 14.885 | GU16: 16.585 | GV16: 17.96 | GW16: 20.45 | GX16: 23.575 | HA16: 13 | HB16: 10 | HE16: U9 | HF16: B24 | HG16: B24 | HH16: 27 | HL16: AlfaU9 | HM16: B24 | HN16: Condell | HO16: 824
A17: =HOUR(G17)+1 | D17: =IFERROR( IF(AND(OR(Planilla!B17="C",Planilla!B17="c"), VLOOKUP(E17,FD:FP,13,0)="C"), "OK",IF(AND(OR(Planilla!B17="C",Planilla!B17="c"), OR(VLOOKUP(E17,FD:FP,13,0)="B", VLOOKUP(E17,FD:FP,13,0)="A")), "DEFICIT",IF( AND(OR(Planilla!B17="B", Planilla!B17="BPAL"), VLOOKUP(E17,FD:FP,13,0)="B"), "OK",IF(AND(OR(Planilla!B17="B", Planilla!B17="BPAL"), VLOOKUP(E17,FD:FP,13,0)="A"), "DEFICIT",IF(AND(OR(Planilla!B17="B", Planilla!B17="BPAL"), VLOOKUP(E17,FD:FP,13,0)="C"), "SOBREOFERTA",IF(AND(Planilla!B17="A", VLOOKUP(E17,FD:FP,13,0)="A"), "OK",IF( AND(Planilla!B17="A", OR(VLOOKUP(E17,FD:FP,13,0)="B", VLOOKUP(E17,FD:FP,13,0)="C")), "SOBREOFERTA","" ))))))),"") | H17: =IF(I17="","",IF(AND((I17-G17)>=TIME(0,0,0),(I17-G17)<TIME(0,3,0)),"OK",IF(AND((I17-G17)>=TIME(0,3,0),(I17-G17)<TIME(0,5,0)),"RETRASO DE 3-5 MIN",IF(AND((I17-G17)>=TIME(0,5,0),(I17-G17)<TIME(0,10,0)),"RETRASO DE 5-10 MIN",IF((I17-G17)>=TIME(0,10,0),"RETRASO >10 MIN", IF(AND((G17-I17)>=TIME(0,0,0),(G17-I17)<TIME(0,3,0)),"OK",IF((G17-I17)>=TIME(0,3,0),"ADELANTADO"))))))) | J17: =IF(A17<>"",HLOOKUP(VALUE(TEXT(G17,"h:mm:ss")),IF($C$6="Laboral",$FZ$4:$GX$227,IF($C$6="Sábado",$FZ$231:$GX$452,$FZ$456:$GX$656)),VLOOKUP($C$4,$HF$2:$HH$99,3,0)+IF(C$5="Ida",0,1),1),"") | K17: =IF(A18<>A17,AVERAGEIF(A$9:A17,A17,J$9:J17),"") | L17: =IFERROR(IF(A18<>A17,AVERAGEIF(A$9:A17,A17,S$9:S17),""),"") | M17: =IFERROR(IF(A18<>A17,AVERAGEIF(A$9:A17,A17,T$9:T17),""),"") | N17: {=IFERROR(IF(A18<>A17,_xlfn.STDEV.P(IF(A$9:A17=A17,T$9:T17)),""),"")} | O17: {=IFERROR(IF(A18<>A17,_xlfn.STDEV.P(IF(A$9:A17=A17,S$9:S17)),""),"")} | P17: =IFERROR(IF(A17<>A18,MAX((((M17*24*60)/2)*(1+POWER((((N17*24*60) / (M17*24*60) )),2))) + ((M17*24*60 )*-0.1 + (K17*0.015)) +1,(((M17*24*60)/2)*(1+POWER((((N17*24*60) / (M17*24*60 ))),2)))),""),"") | Q17: =IF(AND(O17<>"",L17<>""),IF(A17<>A18,((L17*24*60) / 2 ) * (1 + POWER(((O17*24*60) / (L17*24*60)),2)),""),"") | R17: =IF(Q17<>"",MAX(P17,Q17),"") | S17: =IF(I17<>"H. Sale Real",IF(AND(I18<>"",LEFT(C18,2)<>"Va"),IF(AND(I17<>"",LEFT(C17,2)<>"Va",I17<>"H. Sale Real"),IF(I18-I17<0.208333333333333,I18-I17,""),IF(AND(I16<>"",LEFT(C16,2)<>"Va",I16<>"H. Sale Real"),IF(I18-I16<0.208333333333333,I18-I16,""),IF(AND(I15<>"",LEFT(C15,2)<>"Va",I15<>"H. Sale Real"),IF(I18-I15<0.208333333333333,I18-I15,""),IF(AND(I14<>"",LEFT(C14,2)<>"Va",I14<>"H. Sale Real"),IF(I18-I14<0.208333333333333,I18-I14,""),IF(AND(I13<>"",LEFT(C13,2)<>"Va",I13<>"H. Sale Real"),IF(I18-I13<0.208333333333333,I18-I13,""),""))))),""),"") | T17: =IF(G17<>"H. Sale Real",IF(AND(G18<>"",LEFT(C18,2)<>"Va"),IF(AND(G17<>"",LEFT(C17,2)<>"Va",G17<>"H. Sale Real"),IF(G18-G17<0.208333333333333,G18-G17,""),IF(AND(G16<>"",LEFT(C16,2)<>"Va",G16<>"H. Sale Real"),IF(G18-G16<0.208333333333333,G18-G16,""),IF(AND(G15<>"",LEFT(C15,2)<>"Va",G15<>"H. Sale Real"),IF(G18-G15<0.208333333333333,G18-G15,""),IF(AND(G14<>"",LEFT(C14,2)<>"Va",G14<>"H. Sale Real"),IF(G18-G14<0.208333333333333,G18-G14,""),IF(AND(G13<>"",LEFT(C13,2)<>"Va",G13<>"H. Sale Real"),IF(G18-G13<0.208333333333333,G18-G13,""),""))))),""),"") | Z17: =IF(G17<>"",IF(AND(Z16<>"IE",P17<>0,R17<>""),IF(IFERROR((P17/R17),0) <=1,IFERROR(P17/R17,""),1),""),"") | AE17: =HOUR(AK17)+1 | AL17: =IF(AM17="","",IF(AND((AM17-AK17)>=TIME(0,0,0),(AM17-AK17)<TIME(0,3,0)),"OK",IF(AND((AM17-AK17)>=TIME(0,3,0),(AM17-AK17)<TIME(0,5,0)),"RETRASO DE 3-5 MIN",IF(AND((AM17-AK17)>=TIME(0,5,0),(AM17-AK17)<TIME(0,10,0)),"RETRASO DE 5-10 MIN",IF((AM17-AK17)>=TIME(0,10,0),"RETRASO >10 MIN", IF(AND((AK17-AM17)>=TIME(0,0,0),(AK17-AM17)<TIME(0,3,0)),"OK",IF((AK17-AM17)>=TIME(0,3,0),"ADELANTADO"))))))) | AN17: =IF(AE17<>"",HLOOKUP(VALUE(TEXT(AK17,"h:mm:ss")),IF($C$6="Laboral",$FZ$4:$GX$227,IF($C$6="Sábado",$FZ$231:$GX$452,$FZ$456:$GX$656)),VLOOKUP($C$4,$HF$2:$HH$99,3,0)+IF(AG$5="Ida",0,1),1),"") | AO17: =IF(AE18<>AE17,AVERAGEIF(AE$9:AE17,AE17,AN$9:AN17),"") | AP17: =IFERROR(IF(AE18<>AE17,AVERAGEIF(AE$9:AE17,AE17,AW$9:AW17),""),"") | AQ17: =IFERROR(IF(AE18<>AE17,AVERAGEIF(AE$9:AE17,AE17,AX$9:AX17),""),"") | AR17: {=IFERROR(IF(AE18<>AE17,_xlfn.STDEV.P(IF(AE$9:AE17=AE17,AX$9:AX17)),""),"")} | AS17: {=IFERROR(IF(AE18<>AE17,_xlfn.STDEV.P(IF(AE$9:AE17=AE17,AW$9:AW17)),""),"")} | AT17: =IFERROR(IF(AE17<>AE18,MAX((((AQ17*24*60)/2)*(1+POWER((((AR17*24*60) / (AQ17*24*60) )),2))) + ((AQ17*24*60 )*-0.1 + (AO17*0.015)) +1,(((AQ17*24*60)/2)*(1+POWER((((AR17*24*60) / (AQ17*24*60 ))),2)))),""),"") | AU17: =IF(AND(AS17<>"",AP17<>""),IF(AE17<>AE18,((AP17*24*60) / 2 ) * (1 + POWER(((AS17*24*60) / (AP17*24*60)),2)),""),"") | AV17: =IF(AU17<>"",MAX(AT17,AU17),"") | AW17: =IF(AM17<>"H. Sale Real",IF(AND(AM18<>"",LEFT(AG18,2)<>"Va"),IF(AND(AM17<>"",LEFT(AG17,2)<>"Va",AM17<>"H. Sale Real"),IF(AM18-AM17<0.208333333333333,AM18-AM17,""),IF(AND(AM16<>"",LEFT(AG16,2)<>"Va",AM16<>"H. Sale Real"),IF(AM18-AM16<0.208333333333333,AM18-AM16,""),IF(AND(AM15<>"",LEFT(AG15,2)<>"Va",AM15<>"H. Sale Real"),IF(AM18-AM15<0.208333333333333,AM18-AM15,""),IF(AND(AM14<>"",LEFT(AG14,2)<>"Va",AM14<>"H. Sale Real"),IF(AM18-AM14<0.208333333333333,AM18-AM14,""),IF(AND(AM13<>"",LEFT(AG13,2)<>"Va",AM13<>"H. Sale Real"),IF(AM18-AM13<0.208333333333333,AM18-AM13,""),""))))),""),"") | AX17: =IF(AK17<>"H. Sale Real",IF(AND(AK18<>"",LEFT(AG18,2)<>"Va"),IF(AND(AK17<>"",LEFT(AG17,2)<>"Va",AK17<>"H. Sale Real"),IF(AK18-AK17<0.208333333333333,AK18-AK17,""),IF(AND(AK16<>"",LEFT(AG16,2)<>"Va",AK16<>"H. Sale Real"),IF(AK18-AK16<0.208333333333333,AK18-AK16,""),IF(AND(AK15<>"",LEFT(AG15,2)<>"NC",AK15<>"H. Sale Real"),IF(AK18-AK15<0.208333333333333,AK18-AK15,""),IF(AND(AK14<>"",LEFT(AG14,2)<>"Va",AK14<>"H. Sale Real"),IF(AK18-AK14<0.208333333333333,AK18-AK14,""),IF(AND(AK13<>"",LEFT(AG13,2)<>"Va",AK13<>"H. Sale Real"),IF(AK18-AK13<0.208333333333333,AK18-AK13,""),""))))),""),"") | BD17: =IF(AK17<>"",IF(AND(BD16<>"IE",AT17<>0,AV17<>""),IF(IFERROR((AT17/AV17),0) <=1,IFERROR(AT17/AV17,""),1),""),"") | BI17: 5 | BJ17: =COUNTIFS($A:$A,$BI17,$C:$C,$BI$11) | BK17: =BJ17-COUNTIFS($A:$A,$BI17,$C:$C,$BI$11,$H:$H,"") | BL17: =IFERROR((BK17/BJ17),"") | BM17: =_xlfn.XLOOKUP(BI17,$A:$A,$R:$R,"0",0,-1) | BN17: =_xlfn.XLOOKUP(BI17,$A:$A,$P:$P,"0",0,-1) | BO17: =_xlfn.XLOOKUP(BI17,$A:$A,$Z:$Z,"",0,-1) | BR17: 5 | BS17: =COUNTIFS($AE:$AE,$BR17,$AG:$AG,$BR$11) | BT17: =BS17-COUNTIFS($AE:$AE,$BR17,$AG:$AG,$BR$11,$AL:$AL,"") | BU17: =IFERROR((BT17/BS17),"") | BV17: =_xlfn.XLOOKUP(BR17,$AE:$AE,$AV:$AV,"0",0,-1) | BW17: =_xlfn.XLOOKUP(BR17,$AE:$AE,$AT:$AT,"0",0,-1) | BX17: =_xlfn.XLOOKUP(BR17,$AE:$AE,$BD:$BD,"",0,-1) | FC17: Diccionario 1 | FD17: 1014 | FE17: D8482478K2PL | FF17: YV3T7U525KA195327 | FG17: Volvo | FH17: B8R | FI17: MARCOPOLO | FJ17: TORINO | FK17: 2019 | FL17: B2PAL | FM17: LOS LIBERTADORES | FN17: Los Liberadores 6450, Lote 4A | FO17: Huechuraba | FP17: B | FS17: 3005 / SFWZ-39| | FT17: SFWZ-39| | FU17: SFWZ-39 | FV17: =VLOOKUP(FU17,FD:FL,9,0) | FZ17: 120 | GA17: 0 | GB17: 0 | GC17: 0 | GD17: 0 | GE17: 27.31 | GF17: 22.005 | GG17: 16.685 | GH17: 14.945 | GI17: 16.83 | GJ17: 17.985 | GK17: 18.065 | GL17: 17.725 | GM17: 17.03 | GN17: 17.105 | GO17: 16.605 | GP17: 15.62 | GQ17: 13.25 | GR17: 11.98 | GS17: 14.1 | GT17: 17.32 | GU17: 19.92 | GV17: 21.765 | GW17: 23.685 | GX17: 25.535 | HA17: 14 | HB17: 11 | HE17: U9 | HF17: B25 | HG17: B25 | HH17: 28 | HL17: AlfaU9 | HM17: B25 | HN17: Santa Marta | HO17: 825
A18: =HOUR(G18)+1 | D18: =IFERROR( IF(AND(OR(Planilla!B18="C",Planilla!B18="c"), VLOOKUP(E18,FD:FP,13,0)="C"), "OK",IF(AND(OR(Planilla!B18="C",Planilla!B18="c"), OR(VLOOKUP(E18,FD:FP,13,0)="B", VLOOKUP(E18,FD:FP,13,0)="A")), "DEFICIT",IF( AND(OR(Planilla!B18="B", Planilla!B18="BPAL"), VLOOKUP(E18,FD:FP,13,0)="B"), "OK",IF(AND(OR(Planilla!B18="B", Planilla!B18="BPAL"), VLOOKUP(E18,FD:FP,13,0)="A"), "DEFICIT",IF(AND(OR(Planilla!B18="B", Planilla!B18="BPAL"), VLOOKUP(E18,FD:FP,13,0)="C"), "SOBREOFERTA",IF(AND(Planilla!B18="A", VLOOKUP(E18,FD:FP,13,0)="A"), "OK",IF( AND(Planilla!B18="A", OR(VLOOKUP(E18,FD:FP,13,0)="B", VLOOKUP(E18,FD:FP,13,0)="C")), "SOBREOFERTA","" ))))))),"") | H18: =IF(I18="","",IF(AND((I18-G18)>=TIME(0,0,0),(I18-G18)<TIME(0,3,0)),"OK",IF(AND((I18-G18)>=TIME(0,3,0),(I18-G18)<TIME(0,5,0)),"RETRASO DE 3-5 MIN",IF(AND((I18-G18)>=TIME(0,5,0),(I18-G18)<TIME(0,10,0)),"RETRASO DE 5-10 MIN",IF((I18-G18)>=TIME(0,10,0),"RETRASO >10 MIN", IF(AND((G18-I18)>=TIME(0,0,0),(G18-I18)<TIME(0,3,0)),"OK",IF((G18-I18)>=TIME(0,3,0),"ADELANTADO"))))))) | J18: =IF(A18<>"",HLOOKUP(VALUE(TEXT(G18,"h:mm:ss")),IF($C$6="Laboral",$FZ$4:$GX$227,IF($C$6="Sábado",$FZ$231:$GX$452,$FZ$456:$GX$656)),VLOOKUP($C$4,$HF$2:$HH$99,3,0)+IF(C$5="Ida",0,1),1),"") | K18: =IF(A19<>A18,AVERAGEIF(A$9:A18,A18,J$9:J18),"") | L18: =IFERROR(IF(A19<>A18,AVERAGEIF(A$9:A18,A18,S$9:S18),""),"") | M18: =IFERROR(IF(A19<>A18,AVERAGEIF(A$9:A18,A18,T$9:T18),""),"") | N18: {=IFERROR(IF(A19<>A18,_xlfn.STDEV.P(IF(A$9:A18=A18,T$9:T18)),""),"")} | O18: {=IFERROR(IF(A19<>A18,_xlfn.STDEV.P(IF(A$9:A18=A18,S$9:S18)),""),"")} | P18: =IFERROR(IF(A18<>A19,MAX((((M18*24*60)/2)*(1+POWER((((N18*24*60) / (M18*24*60) )),2))) + ((M18*24*60 )*-0.1 + (K18*0.015)) +1,(((M18*24*60)/2)*(1+POWER((((N18*24*60) / (M18*24*60 ))),2)))),""),"") | Q18: =IF(AND(O18<>"",L18<>""),IF(A18<>A19,((L18*24*60) / 2 ) * (1 + POWER(((O18*24*60) / (L18*24*60)),2)),""),"") | R18: =IF(Q18<>"",MAX(P18,Q18),"") | S18: =IF(I18<>"H. Sale Real",IF(AND(I19<>"",LEFT(C19,2)<>"Va"),IF(AND(I18<>"",LEFT(C18,2)<>"Va",I18<>"H. Sale Real"),IF(I19-I18<0.208333333333333,I19-I18,""),IF(AND(I17<>"",LEFT(C17,2)<>"Va",I17<>"H. Sale Real"),IF(I19-I17<0.208333333333333,I19-I17,""),IF(AND(I16<>"",LEFT(C16,2)<>"Va",I16<>"H. Sale Real"),IF(I19-I16<0.208333333333333,I19-I16,""),IF(AND(I15<>"",LEFT(C15,2)<>"Va",I15<>"H. Sale Real"),IF(I19-I15<0.208333333333333,I19-I15,""),IF(AND(I14<>"",LEFT(C14,2)<>"Va",I14<>"H. Sale Real"),IF(I19-I14<0.208333333333333,I19-I14,""),""))))),""),"") | T18: =IF(G18<>"H. Sale Real",IF(AND(G19<>"",LEFT(C19,2)<>"Va"),IF(AND(G18<>"",LEFT(C18,2)<>"Va",G18<>"H. Sale Real"),IF(G19-G18<0.208333333333333,G19-G18,""),IF(AND(G17<>"",LEFT(C17,2)<>"Va",G17<>"H. Sale Real"),IF(G19-G17<0.208333333333333,G19-G17,""),IF(AND(G16<>"",LEFT(C16,2)<>"Va",G16<>"H. Sale Real"),IF(G19-G16<0.208333333333333,G19-G16,""),IF(AND(G15<>"",LEFT(C15,2)<>"Va",G15<>"H. Sale Real"),IF(G19-G15<0.208333333333333,G19-G15,""),IF(AND(G14<>"",LEFT(C14,2)<>"Va",G14<>"H. Sale Real"),IF(G19-G14<0.208333333333333,G19-G14,""),""))))),""),"") | Z18: =IF(G18<>"",IF(AND(Z17<>"IE",P18<>0,R18<>""),IF(IFERROR((P18/R18),0) <=1,IFERROR(P18/R18,""),1),""),"") | AE18: =HOUR(AK18)+1 | AL18: =IF(AM18="","",IF(AND((AM18-AK18)>=TIME(0,0,0),(AM18-AK18)<TIME(0,3,0)),"OK",IF(AND((AM18-AK18)>=TIME(0,3,0),(AM18-AK18)<TIME(0,5,0)),"RETRASO DE 3-5 MIN",IF(AND((AM18-AK18)>=TIME(0,5,0),(AM18-AK18)<TIME(0,10,0)),"RETRASO DE 5-10 MIN",IF((AM18-AK18)>=TIME(0,10,0),"RETRASO >10 MIN", IF(AND((AK18-AM18)>=TIME(0,0,0),(AK18-AM18)<TIME(0,3,0)),"OK",IF((AK18-AM18)>=TIME(0,3,0),"ADELANTADO"))))))) | AN18: =IF(AE18<>"",HLOOKUP(VALUE(TEXT(AK18,"h:mm:ss")),IF($C$6="Laboral",$FZ$4:$GX$227,IF($C$6="Sábado",$FZ$231:$GX$452,$FZ$456:$GX$656)),VLOOKUP($C$4,$HF$2:$HH$99,3,0)+IF(AG$5="Ida",0,1),1),"") | AO18: =IF(AE19<>AE18,AVERAGEIF(AE$9:AE18,AE18,AN$9:AN18),"") | AP18: =IFERROR(IF(AE19<>AE18,AVERAGEIF(AE$9:AE18,AE18,AW$9:AW18),""),"") | AQ18: =IFERROR(IF(AE19<>AE18,AVERAGEIF(AE$9:AE18,AE18,AX$9:AX18),""),"") | AR18: {=IFERROR(IF(AE19<>AE18,_xlfn.STDEV.P(IF(AE$9:AE18=AE18,AX$9:AX18)),""),"")} | AS18: {=IFERROR(IF(AE19<>AE18,_xlfn.STDEV.P(IF(AE$9:AE18=AE18,AW$9:AW18)),""),"")} | AT18: =IFERROR(IF(AE18<>AE19,MAX((((AQ18*24*60)/2)*(1+POWER((((AR18*24*60) / (AQ18*24*60) )),2))) + ((AQ18*24*60 )*-0.1 + (AO18*0.015)) +1,(((AQ18*24*60)/2)*(1+POWER((((AR18*24*60) / (AQ18*24*60 ))),2)))),""),"") | AU18: =IF(AND(AS18<>"",AP18<>""),IF(AE18<>AE19,((AP18*24*60) / 2 ) * (1 + POWER(((AS18*24*60) / (AP18*24*60)),2)),""),"") | AV18: =IF(AU18<>"",MAX(AT18,AU18),"") | AW18: =IF(AM18<>"H. Sale Real",IF(AND(AM19<>"",LEFT(AG19,2)<>"Va"),IF(AND(AM18<>"",LEFT(AG18,2)<>"Va",AM18<>"H. Sale Real"),IF(AM19-AM18<0.208333333333333,AM19-AM18,""),IF(AND(AM17<>"",LEFT(AG17,2)<>"Va",AM17<>"H. Sale Real"),IF(AM19-AM17<0.208333333333333,AM19-AM17,""),IF(AND(AM16<>"",LEFT(AG16,2)<>"Va",AM16<>"H. Sale Real"),IF(AM19-AM16<0.208333333333333,AM19-AM16,""),IF(AND(AM15<>"",LEFT(AG15,2)<>"Va",AM15<>"H. Sale Real"),IF(AM19-AM15<0.208333333333333,AM19-AM15,""),IF(AND(AM14<>"",LEFT(AG14,2)<>"Va",AM14<>"H. Sale Real"),IF(AM19-AM14<0.208333333333333,AM19-AM14,""),""))))),""),"") | AX18: =IF(AK18<>"H. Sale Real",IF(AND(AK19<>"",LEFT(AG19,2)<>"Va"),IF(AND(AK18<>"",LEFT(AG18,2)<>"Va",AK18<>"H. Sale Real"),IF(AK19-AK18<0.208333333333333,AK19-AK18,""),IF(AND(AK17<>"",LEFT(AG17,2)<>"Va",AK17<>"H. Sale Real"),IF(AK19-AK17<0.208333333333333,AK19-AK17,""),IF(AND(AK16<>"",LEFT(AG16,2)<>"NC",AK16<>"H. Sale Real"),IF(AK19-AK16<0.208333333333333,AK19-AK16,""),IF(AND(AK15<>"",LEFT(AG15,2)<>"Va",AK15<>"H. Sale Real"),IF(AK19-AK15<0.208333333333333,AK19-AK15,""),IF(AND(AK14<>"",LEFT(AG14,2)<>"Va",AK14<>"H. Sale Real"),IF(AK19-AK14<0.208333333333333,AK19-AK14,""),""))))),""),"") | BD18: =IF(AK18<>"",IF(AND(BD17<>"IE",AT18<>0,AV18<>""),IF(IFERROR((AT18/AV18),0) <=1,IFERROR(AT18/AV18,""),1),""),"") | BI18: 6 | BJ18: =COUNTIFS($A:$A,$BI18,$C:$C,$BI$11) | BK18: =BJ18-COUNTIFS($A:$A,$BI18,$C:$C,$BI$11,$H:$H,"") | BL18: =IFERROR((BK18/BJ18),"") | BM18: =_xlfn.XLOOKUP(BI18,$A:$A,$R:$R,"0",0,-1) | BN18: =_xlfn.XLOOKUP(BI18,$A:$A,$P:$P,"0",0,-1) | BO18: =_xlfn.XLOOKUP(BI18,$A:$A,$Z:$Z,"",0,-1) | BR18: 6 | BS18: =COUNTIFS($AE:$AE,$BR18,$AG:$AG,$BR$11) | BT18: =BS18-COUNTIFS($AE:$AE,$BR18,$AG:$AG,$BR$11,$AL:$AL,"") | BU18: =IFERROR((BT18/BS18),"") | BV18: =_xlfn.XLOOKUP(BR18,$AE:$AE,$AV:$AV,"0",0,-1) | BW18: =_xlfn.XLOOKUP(BR18,$AE:$AE,$AT:$AT,"0",0,-1) | BX18: =_xlfn.XLOOKUP(BR18,$AE:$AE,$BD:$BD,"",0,-1) | FC18: Diccionario 1 | FD18: 1015 | FE18: D8482400K2PL | FF18: YV3T7U527KA195328 | FG18: Volvo | FH18: B8R | FI18: MARCOPOLO | FJ18: TORINO | FK18: 2019 | FL18: B2PAL | FM18: LOS LIBERTADORES | FN18: Los Liberadores 6450, Lote 4A | FO18: Huechuraba | FP18: B | FS18: 3005 / SFWZ-39| | FT18: SFWZ-39| | FU18: SFWZ-39 | FV18: =VLOOKUP(FU18,FD:FL,9,0) | FZ18: 120 | GA18: 28.4 | GB18: 0 | GC18: 0 | GD18: 0 | GE18: 0 | GF18: 9.81 | GG18: 16.66 | GH18: 14.92 | GI18: 16.59 | GJ18: 17.285 | GK18: 17.34 | GL18: 17.32 | GM18: 16.87 | GN18: 16.99 | GO18: 16.855 | GP18: 16.6 | GQ18: 16.175 | GR18: 14.875 | GS18: 15.675 | GT18: 17.97 | GU18: 19.545 | GV18: 20.605 | GW18: 23.055 | GX18: 25.725 | HA18: 15 | HB18: 12 | HE18: U9 | HF18: B26 | HG18: B26 | HH18: 29 | HL18: AlfaU9 | HM18: B26 | HN18: Santa Marta | HO18: 826 | IB18: NO Valida Servicio Sentido Correcto
